Workbook

Sheet Data
A1: Admission_No | B1: Name | C1: Class | D1: State of Origin | E1: Age | F1: LGA | G1: Term | H1: Next Term Begins | I1: Password | J1: Email
A2: 1 | B2: ABBA FIRA ALINGADTHER | C2: SS 2C | D2: Borno | E2: 14 | F2: Jere | G2: 1st | H2: 16th January, 2026 | I2: 1234 | J2: auadams020@gmail.com
A3: 2 | B3: AMINU MUHAMMED AL MUSTAPHA | C3: SS 2C | D3: Borno | E3: 15 | F3: MMC | G3: 1st | H3: 16th January, 2026 | I3: 1234
A4: 3 | B4: AMOS ANJILI STANLEY | C4: SS 2C | D4: Borno | E4: 16 | F4: Gwoza | G4: 1st | H4: 16th January, 2026 | I4: 1234
A5: 4 | B5: BABAKURA ABUBAKAR YUSUF | C5: SS 2C | D5: Borno | E5: 12 | F5: Gwoza | G5: 1st | H5: 16th January, 2026 | I5: 1234
A6: 5 | B6: BUKAR MOHAMMED KADI | C6: SS 2C | D6: Borno | E6: 13 | F6: Gwoza | G6: 1st | H6: 16th January, 2026 | I6: 1234
A7: 6 | B7: BUKAR MUSTAPHA AJI | C7: SS 2C | D7: Borno | E7: 14 | F7: MMC | G7: 1st | H7: 16th January, 2026 | I7: 1234
A8: 7 | B8: GADZAMA IJUDIGAL JOHN | C8: SS 2C | D8: Borno | E8: 15 | F8: Konduga | G8: 1st | H8: 16th January, 2026 | I8: 1234
A9: 8 | B9: IBRAHIM EMMANUEL | C9: SS 2C | D9: Borno | E9: 14 | F9: Chibok | G9: 1st | H9: 16th January, 2026 | I9: 1234
A10: 9 | B10: ISHAKU JOSHUA KWARI | C10: SS 2C | D10: Borno | E10: 14 | F10: Damboa | G10: 1st | H10: 16th January, 2026 | I10: 1234
A11: 10 | B11: PETER SIMON WANDIYAHEL | C11: SS 2C | D11: Adamawa | E11: 15 | F11: Jimeta | G11: 1st | H11: 16th January, 2026 | I11: 1234
A12: 11 | B12: SAMUEL JOHN ABBAS | C12: SS 2C | D12: Yobe | E12: 15 | F12: Fika | G12: 1st | H12: 16th January, 2026 | I12: 1234
A13: 12 | B13: SHETTIMA AHMED MOHAMMED | C13: SS 2C | D13: Adamawa | E13: 15 | F13: Ganye | G13: 1st | H13: 16th January, 2026 | I13: 1234
A14: 13 | B14: SHUIABU FARUK UMAR | C14: SS 2C | D14: Borno | E14: 15 | F14: Mafa | G14: 1st | H14: 16th January, 2026 | I14: 1234
... A22: 21 | B22: ABEDNEGO JOSEPH JANICE | C22: SS 2C | D22: Yobe | E22: 15 | F22: Gulani | G22: 1st | H22: 16th January, 2026 | I22: 1234
A23: 22 | B23: ABUBAKAR FATIMA | C23: SS 2C | G23: 1st | H23: 16th January, 2026 | I23: 1234
A24: 23 | B24: ADAMU KAHDIJA ALIYU | C24: SS 2C | D24: Borno | E24: 14 | F24: Gwoza | G24: 1st | H24: 16th January, 2026 | I24: 1234
A25: 24 | B25: AHMED KHADIJA SHETTIMA | C25: SS 2C | D25: Borno | E25: 15 | F25: Hawul | G25: 1st | H25: 16th January, 2026 | I25: 1234
A26: 25 | B26: BABAGONI FATIMA SHETTIMA | C26: SS 2C | D26: Borno | E26: 15 | F26: Biu | G26: 1st | H26: 16th January, 2026 | I26: 1234
A27: 26 | B27: BASHIR FATIMA | C27: SS 2C | D27: Borno | E27: 14 | F27: Hawul | G27: 1st | H27: 16th January, 2026 | I27: 1234
A28: 27 | B28: BELLO AMINA ABDULLAHI | C28: SS 2C | D28: Borno | E28: 13 | F28: Bama | G28: 1st | H28: 16th January, 2026 | I28: 1234
A29: 28 | B29: BUKAR MARYARM UMAR | C29: SS 2C | D29: Borno | E29: 15 | F29: Dikwa | G29: 1st | H29: 16th January, 2026 | I29: 1234
A30: 29 | B30: DALA FATIMA AHMED | C30: SS 2C | D30: Borno | E30: 15 | F30: Gwoza | G30: 1st | H30: 16th January, 2026 | I30: 1234
A31: 30 | B31: DAUDA MARYAM UMMI | C31: SS 2C | D31: Borno | E31: 13 | F31: Jere | G31: 1st | H31: 16th January, 2026 | I31: 1234
A32: 31 | B32: DULOMI ZAINAB | C32: SS 2C | D32: Borno | E32: 14 | F32: Hong | G32: 1st | H32: 16th January, 2026 | I32: 1234
A33: 32 | B33: GADAU FATIMA ALI | C33: SS 2C | D33: Borno | E33: 14 | F33: Askira Uba | G33: 1st | H33: 16th January, 2026 | I33: 1234
A34: 33 | B34: HUSSANI HADIZA MUSA | C34: SS 2C | D34: Borno | E34: 14 | F34: Dikwa | G34: 1st | H34: 16th January, 2026 | I34: 1234
A35: 34 | B35: HUSSANI ZAINAB A | C35: SS 2C | D35: Borno | E35: 15 | F35: Bama | G35: 1st | H35: 16th January, 2026 | I35: 1234
... A52: 51 | B52: Deborah Adeola Showole | C52: SS 2C | D52: Lagos | E52: 14 | F52: Island | G52: 1st | H52: 16th January, 2026 | I52: 1234
A53: 52 | B53: Shuabu Ayuba | C53: SS 2C | G53: 1st | H53: 16th January, 2026 | I53: 1234
A54: 53 | B54: Mohammed yakubu Abbagana | C54: SS 2C | G54: 1st | H54: 16th January, 2026 | I54: 1234
A55: 54 | C55: SS 2C | G55: 1st
A56: 55

Sheet Comments
A1: Admission_No | B1: Comments | C1: Position of authourity
A2: 1 | B2: Calm and obedient | C2: Nil
A3: 2 | B3: Calm and obedient | C3: Nil
A4: 3 | B4: Calm and obedient | C4: Nil
A5: 4 | B5: Calm and obedient | C5: Nil
A6: 5 | B6: Calm and obedient | C6: Nil
A7: 6 | B7: Calm and obedient | C7: Nil
A8: 7 | B8: Calm and obedient | C8: Nil
A9: 8 | B9: Calm and obedient | C9: Nil
A10: 9 | B10: Calm and obedient | C10: Nil
A11: 10 | B11: Calm and obedient | C11: Nil
A12: 11 | B12: Calm and obedient | C12: Nil
A13: 12 | B13: Calm and obedient | C13: Nil
... A54: 53 | B54: Calm and obedient | C54: Nil
A55: 54
A56: 55

Sheet Behaviour
A1: Admission_No | B1: Puntuality | C1: Attendance in class | D1: Neatness | E1: Politeness | F1: Honesty | G1: Attentiveness | H1: Obedience | I1: Self Control
A2: 1 | B2: 4 | C2: 5 | D2: 4 | E2: 4 | F2: 4 | G2: 4 | H2: 4 | I2: 4
A3: 2 | B3: 4 | C3: 4 | D3: 4 | E3: 4 | F3: 3 | G3: 4 | H3: 4 | I3: 4
A4: 3 | B4: 3 | C4: 3 | D4: 4 | E4: 4 | F4: 4 | G4: 4 | H4: 4 | I4: 4
A5: 4 | B5: 4 | C5: 5 | D5: 4 | E5: 4 | F5: 4 | G5: 4 | H5: 4 | I5: 5
A6: 5 | B6: 4 | C6: 5 | D6: 4 | E6: 4 | F6: 4 | G6: 4 | H6: 4 | I6: 4
A7: 6 | B7: 4 | C7: 5 | D7: 3 | E7: 4 | F7: 4 | G7: 4 | H7: 4 | I7: 3
A8: 7 | B8: 3 | C8: 3 | D8: 4 | E8: 4 | F8: 4 | G8: 4 | H8: 4 | I8: 4
A9: 8 | B9: 3 | C9: 3 | D9: 4 | E9: 4 | F9: 4 | G9: 4 | H9: 4 | I9: 4
A10: 9 | B10: 4 | C10: 3 | D10: 4 | E10: 4 | F10: 4 | G10: 4 | H10: 4 | I10: 4
A11: 10 | B11: 4 | C11: 5 | D11: 3 | E11: 3 | F11: 2 | G11: 4 | H11: 2 | I11: 4
A12: 11 | B12: 4 | C12: 4 | D12: 4 | E12: 4 | F12: 3 | G12: 4 | H12: 4 | I12: 4
A13: 12 | B13: 4 | C13: 4 | D13: 4 | E13: 4 | F13: 4 | G13: 4 | H13: 3 | I13: 4
... A55: 54 | B55: 4 | C55: 5 | D55: 3 | E55: 3 | F55: 2 | G55: 4 | H55: 2 | I55: 4
A56: 55

Sheet Skills
A1: Admission_No | B1: Handwriting | C1: Musical Skill | D1: Craft | E1: Games | F1: Fluency
A2: 1 | B2: 4 | C2: 4 | D2: 4 | E2: 4 | F2: 4
A3: 2 | B3: 3 | C3: 3 | D3: 3 | E3: 4 | F3: 4
A4: 3 | B4: 3 | C4: 4 | D4: 3 | E4: 4 | F4: 4
A5: 4 | B5: 4 | C5: 3 | D5: 4 | E5: 3 | F5: 3
A6: 5 | B6: 3 | C6: 3 | D6: 3 | E6: 3 | F6: 3
A7: 6 | B7: 3 | C7: 4 | D7: 4 | E7: 4 | F7: 4
A8: 7 | B8: 4 | C8: 3 | D8: 3 | E8: 3 | F8: 4
A9: 8 | B9: 4 | C9: 3 | D9: 4 | E9: 4 | F9: 3
A10: 9 | B10: 3 | C10: 3 | D10: 3 | E10: 5 | F10: 3
A11: 10 | B11: 4 | C11: 4 | D11: 3 | E11: 3 | F11: 3
A12: 11 | B12: 3 | C12: 3 | D12: 3 | E12: 4 | F12: 3
A13: 12 | B13: 4 | C13: 4 | D13: 4 | E13: 5 | F13: 4
... A55: 54 | B55: 4 | C55: 3 | D55: 3 | E55: 5 | F55: 3
A56: 55

Sheet Scoresheet
C1: English Language | O1: Literature in English | AA1: MATHEMATICS | AM1: Physics | AY1: CHEMISTRY | BK1: BIOLOGY | BW1: ECONOMICS | CI1: HISTORY | CU1: CRK | DG1: AGRIC SCIENCE | DS1: GEOGRAPHY | EE1: COMMERCE | EQ1: FINE ART | FC1: ACCOUINTING | FO1: TECHNICAL DRAWING | GA1: GOVERNMENT | GM1: FURTHER MATHS | GY1: HAUSA | HK1: FOOD & NUTRITION | HW1: COMPUTER SCIENCE | II1: FRENCH | IU1: CIVIC EDUCATION | JG1: DATA PROCESSING | JS1: I.R.K.
B2: Admission_No | C2: Names | D2: 1st C. A. | E2: 2st C. A. | F2: 3st C. A. | G2: 4st C. A. | H2: Total C. A. | I2: Exam | J2: Total | K2: Position | L2: Grade | M2: Teacher's Comment | O2: Names | P2: 1st C. A. | Q2: 2st C. A. | R2: 3st C. A. | S2: 4st C. A. | T2: Total C. A. | U2: Exam | V2: Total | W2: Position | X2: Grade | Y2: Teacher's Comment | AA2: Names | AB2: 1st C. A. | AC2: 2st C. A. | AD2: 3st C. A. | AE2: 4st C. A. | AF2: Total C. A. | AG2: Exam | AH2: Total | AI2: Position | AJ2: Grade | AK2: Teacher's Comment | AM2: Names | AN2: 1st C. A. | AO2: 2st C. A. | AP2: 3st C. A. | AQ2: 4st C. A. | AR2: Total C. A. | AS2: Exam | AT2: Total | AU2: Position | AV2: Grade | AW2: Teacher's Comment | AY2: Names | AZ2: 1st C. A. | BA2: 2st C. A. | BB2: 3st C. A. | BC2: 4st C. A. | BD2: Total C. A. | BE2: Exam | BF2: Total | BG2: Position | BH2: Grade | BI2: Teacher's Comment | BK2: Names | BL2: 1st C. A. | BM2: 2st C. A. | BN2: 3st C. A. | BO2: 4st C. A. | BP2: Total C. A. | BQ2: Exam | BR2: Total | BS2: Position | BT2: Grade | BU2: Teacher's Comment | BW2: Names | BX2: 1st C. A. | BY2: 2st C. A. | BZ2: 3st C. A. | CA2: 4st C. A. | CB2: Total C. A. | CC2: Exam | CD2: Total | CE2: Position | CF2: Grade | CG2: Teacher's Comment | CI2: Names | CJ2: 1st C. A. | CK2: 2st C. A. | CL2: 3st C. A. | CM2: 4st C. A. | CN2: Total C. A. | CO2: Exam | CP2: Total | CQ2: Position | CR2: Grade | CS2: Teacher's Comment | CU2: Names | CV2: 1st C. A. | CW2: 2st C. A. | CX2: 3st C. A. | CY2: 4st C. A. | CZ2: Total C. A. | DA2: Exam | DB2: Total | DC2: Position | DD2: Grade | DE2: Teacher's Comment | DG2: Names | DH2: 1st C. A. | DI2: 2st C. A. | DJ2: 3st C. A. | DK2: 4st C. A. | DL2: Total C. A. | DM2: Exam | DN2: Total | DO2: Position | DP2: Grade | DQ2: Teacher's Comment | DS2: Names | DT2: 1st C. A. | DU2: 2st C. A. | DV2: 3st C. A. | DW2: 4st C. A. | DX2: Total C. A. | DY2: Exam | DZ2: Total | EA2: Position | EB2: Grade | EC2: Teacher's Comment | EE2: Names | EF2: 1st C. A. | EG2: 2st C. A. | EH2: 3st C. A. | EI2: 4st C. A. | EJ2: Total C. A. | EK2: Exam | EL2: Total | EM2: Position | EN2: Grade | EO2: Teacher's Comment | EQ2: Names | ER2: 1st C. A. | ES2: 2st C. A. | ET2: 3st C. A. | EU2: 4st C. A. | EV2: Total C. A. | EW2: Exam | EX2: Total | EY2: Position | EZ2: Grade | FA2: Teacher's Comment | FC2: Names | FD2: 1st C. A. | FE2: 2st C. A. | FF2: 3st C. A. | FG2: 4st C. A. | FH2: Total C. A. | FI2: Exam | FJ2: Total | FK2: Position | FL2: Grade | FM2: Teacher's Comment | FO2: Names | FP2: 1st C. A. | FQ2: 2st C. A. | FR2: 3st C. A. | FS2: 4st C. A. | FT2: Total C. A. | FU2: Exam | FV2: Total | FW2: Position | FX2: Grade | FY2: Teacher's Comment | GA2: Names | GB2: 1st C. A. | GC2: 2st C. A. | GD2: 3st C. A. | GE2: 4st C. A. | GF2: Total C. A. | GG2: Exam | GH2: Total | GI2: Position | GJ2: Grade | GK2: Teacher's Comment | GM2: Names | GN2: 1st C. A. | GO2: 2st C. A. | GP2: 3st C. A. | GQ2: 4st C. A. | GR2: Total C. A. | GS2: Exam | GT2: Total | GU2: Position | GV2: Grade | GW2: Teacher's Comment | GY2: Names | GZ2: 1st C. A. | HA2: 2st C. A. | HB2: 3st C. A. | HC2: 4st C. A. | HD2: Total C. A. | HE2: Exam | HF2: Total | HG2: Position | HH2: Grade | HI2: Teacher's Comment | HK2: Names | HL2: 1st C. A. | HM2: 2st C. A. | HN2: 3st C. A. | HO2: 4st C. A. | HP2: Total C. A. | HQ2: Exam | HR2: Total | HS2: Position | HT2: Grade | HU2: Teacher's Comment | HW2: Names | HX2: 1st C. A. | HY2: 2st C. A. | HZ2: 3st C. A. | IA2: 4st C. A. | IB2: Total C. A. | IC2: Exam | ID2: Total | IE2: Position | IF2: Grade | IG2: Teacher's Comment | II2: Names | IJ2: 1st C. A. | IK2: 2st C. A. | IL2: 3st C. A. | IM2: 4st C. A. | IN2: Total C. A. | IO2: Exam | IP2: Total | IQ2: Position | IR2: Grade | IS2: Teacher's Comment | IU2: Names | IV2: 1st C. A. | IW2: 2st C. A. | IX2: 3st C. A. | IY2: 4st C. A. | IZ2: Total C. A. | JA2: Exam | JB2: Total | JC2: Position | JD2: Grade | JE2: Teacher's Comment | JG2: Names | JH2: 1st C. A. | JI2: 2st C. A. | JJ2: 3st C. A. | JK2: 4st C. A. | JL2: Total C. A. | JM2: Exam | JN2: Total | JO2: Position | JP2: Grade | JQ2: Teacher's Comment | JS2: Names | JT2: 1st C. A. | JU2: 2st C. A. | JV2: 3st C. A. | JW2: 4st C. A. | JX2: Total C. A. | JY2: Exam | JZ2: Total | KA2: Position | KB2: Grade | KC2: Teacher's Comment
A3: 1 | B3: 1 | C3: =Data!B2 -> ABBA FIRA ALINGADTHER | D3: 7 | E3: 8 | F3: 8 | G3: 8 | H3: =SUM(D3:G3) -> 31 | I3: 27 | J3: =H3+I3 -> 58 | K3: =IF(J3<10,"",RANK(J3,J$3:J$52)) -> 21 | L3: =IF(J3>=75,"A1",IF(J3>=70,"B2",IF(J3>=65,"B3",IF(J3>=60,"C4",IF(J3>=55,"C5",IF(J3>=50,"C6",IF(J3>=45,"D7",IF(J3>=40,"E8",IF(J3>=6,"F",IF(J3<5,"")))))))))) -> C5 | M3: =IF(J3>=75,"Excellent",IF(J3>=70,"V.Good",IF(J3>=65,"Good",IF(J3>=60,"Credit",IF(J3>=55,"Credit",IF(J3>=50,"Credit",IF(J3>=45,"Pass",IF(J3>=40,"Pass",IF(J3>=6,"Fail",IF(J3<5,"")))))))))) -> Credit | N3: 1 | O3: =Data!B2 -> ABBA FIRA ALINGADTHER | T3: =SUM(P3:S3) -> 0 | V3: =T3+U3 -> 0 | W3: =IF(V3<10,"",RANK(V3,V$3:V$52)) | X3: =IF(V3>=75,"A1",IF(V3>=70,"B2",IF(V3>=65,"B3",IF(V3>=60,"C4",IF(V3>=55,"C5",IF(V3>=50,"C6",IF(V3>=45,"D7",IF(V3>=40,"E8",IF(V3>=6,"F",IF(V3<5,"")))))))))) | Y3: =IF(V3>=75,"Excellent",IF(V3>=70,"V.Good",IF(V3>=65,"Good",IF(V3>=60,"Credit",IF(V3>=55,"Credit",IF(V3>=50,"Credit",IF(V3>=45,"Pass",IF(V3>=40,"Pass",IF(V3>=6,"Fail",IF(V3<5,"")))))))))) | Z3: 1 | AA3: =Data!B2 -> ABBA FIRA ALINGADTHER | AB3: 7 | AC3: 8 | AD3: 8 | AE3: 8 | AF3: =SUM(AB3:AE3) -> 31 | AG3: 27 | AH3: =AF3+AG3 -> 58 | AI3: =IF(AH3<10,"",RANK(AH3,AH$3:AH$52)) -> 21 | AJ3: =IF(AH3>=75,"A1",IF(AH3>=70,"B2",IF(AH3>=65,"B3",IF(AH3>=60,"C4",IF(AH3>=55,"C5",IF(AH3>=50,"C6",IF(AH3>=45,"D7",IF(AH3>=40,"E8",IF(AH3>=6,"F",IF(AH3<5,"")))))))))) -> C5 | AK3: =IF(AH3>=75,"Excellent",IF(AH3>=70,"V.Good",IF(AH3>=65,"Good",IF(AH3>=60,"Credit",IF(AH3>=55,"Credit",IF(AH3>=50,"Credit",IF(AH3>=45,"Pass",IF(AH3>=40,"Pass",IF(AH3>=6,"Fail",IF(AH3<5,"")))))))))) -> Credit | AL3: 1 | AM3: =Data!B2 -> ABBA FIRA ALINGADTHER | AN3: 7 | AO3: 8 | AP3: 8 | AQ3: 8 | AR3: =SUM(AN3:AQ3) -> 31 | AS3: 27 | AT3: =AR3+AS3 -> 58 | AU3: =IF(AT3<10,"",RANK(AT3,AT$3:AT$52)) -> 21 | AV3: =IF(AT3>=75,"A1",IF(AT3>=70,"B2",IF(AT3>=65,"B3",IF(AT3>=60,"C4",IF(AT3>=55,"C5",IF(AT3>=50,"C6",IF(AT3>=45,"D7",IF(AT3>=40,"E8",IF(AT3>=6,"F",IF(AT3<5,"")))))))))) -> C5 | AW3: =IF(AT3>=75,"Excellent",IF(AT3>=70,"V.Good",IF(AT3>=65,"Good",IF(AT3>=60,"Credit",IF(AT3>=55,"Credit",IF(AT3>=50,"Credit",IF(AT3>=45,"Pass",IF(AT3>=40,"Pass",IF(AT3>=6,"Fail",IF(AT3<5,"")))))))))) -> Credit | AX3: 1 | AY3: =Data!B2 -> ABBA FIRA ALINGADTHER | AZ3: 7 | BA3: 8 | BB3: 8 | BC3: 8 | BD3: =SUM(AZ3:BC3) -> 31 | BE3: 27 | BF3: =BD3+BE3 -> 58 | BG3: =IF(BF3<10,"",RANK(BF3,BF$3:BF$52)) -> 21 | BH3: =IF(BF3>=75,"A1",IF(BF3>=70,"B2",IF(BF3>=65,"B3",IF(BF3>=60,"C4",IF(BF3>=55,"C5",IF(BF3>=50,"C6",IF(BF3>=45,"D7",IF(BF3>=40,"E8",IF(BF3>=6,"F",IF(BF3<5,"")))))))))) -> C5 | BI3: =IF(BF3>=75,"Excellent",IF(BF3>=70,"V.Good",IF(BF3>=65,"Good",IF(BF3>=60,"Credit",IF(BF3>=55,"Credit",IF(BF3>=50,"Credit",IF(BF3>=45,"Pass",IF(BF3>=40,"Pass",IF(BF3>=6,"Fail",IF(BF3<5,"")))))))))) -> Credit | BJ3: 1 | BK3: =Data!B2 -> ABBA FIRA ALINGADTHER | BL3: 7 | BM3: 8 | BN3: 8 | BO3: 8 | BP3: =SUM(BL3:BO3) -> 31 | BQ3: 27 | BR3: =BP3+BQ3 -> 58 | BS3: =IF(BR3<10,"",RANK(BR3,BR$3:BR$52)) -> 21 | BT3: =IF(BR3>=75,"A1",IF(BR3>=70,"B2",IF(BR3>=65,"B3",IF(BR3>=60,"C4",IF(BR3>=55,"C5",IF(BR3>=50,"C6",IF(BR3>=45,"D7",IF(BR3>=40,"E8",IF(BR3>=6,"F",IF(BR3<5,"")))))))))) -> C5 | BU3: =IF(BR3>=75,"Excellent",IF(BR3>=70,"V.Good",IF(BR3>=65,"Good",IF(BR3>=60,"Credit",IF(BR3>=55,"Credit",IF(BR3>=50,"Credit",IF(BR3>=45,"Pass",IF(BR3>=40,"Pass",IF(BR3>=6,"Fail",IF(BR3<5,"")))))))))) -> Credit | BV3: 1 | BW3: =Data!B2 -> ABBA FIRA ALINGADTHER | BX3: 7 | BY3: 8 | BZ3: 8 | CA3: 8 | CB3: =SUM(BX3:CA3) -> 31 | CC3: 27 | CD3: =CB3+CC3 -> 58 | CE3: =IF(CD3<10,"",RANK(CD3,CD$3:CD$52)) -> 21 | CF3: =IF(CD3>=75,"A1",IF(CD3>=70,"B2",IF(CD3>=65,"B3",IF(CD3>=60,"C4",IF(CD3>=55,"C5",IF(CD3>=50,"C6",IF(CD3>=45,"D7",IF(CD3>=40,"E8",IF(CD3>=6,"F",IF(CD3<5,"")))))))))) -> C5 | CG3: =IF(CD3>=75,"Excellent",IF(CD3>=70,"V.Good",IF(CD3>=65,"Good",IF(CD3>=60,"Credit",IF(CD3>=55,"Credit",IF(CD3>=50,"Credit",IF(CD3>=45,"Pass",IF(CD3>=40,"Pass",IF(CD3>=6,"Fail",IF(CD3<5,"")))))))))) -> Credit | CH3: 1 | CI3: =Data!B2 -> ABBA FIRA ALINGADTHER | CN3: =SUM(CJ3:CM3) -> 0 | CP3: =CN3+CO3 -> 0 | CQ3: =IF(CP3<10,"",RANK(CP3,CP$3:CP$52)) | CR3: =IF(CP3>=75,"A1",IF(CP3>=70,"B2",IF(CP3>=65,"B3",IF(CP3>=60,"C4",IF(CP3>=55,"C5",IF(CP3>=50,"C6",IF(CP3>=45,"D7",IF(CP3>=40,"E8",IF(CP3>=6,"F",IF(CP3<5,"")))))))))) | CS3: =IF(CP3>=75,"Excellent",IF(CP3>=70,"V.Good",IF(CP3>=65,"Good",IF(CP3>=60,"Credit",IF(CP3>=55,"Credit",IF(CP3>=50,"Credit",IF(CP3>=45,"Pass",IF(CP3>=40,"Pass",IF(CP3>=6,"Fail",IF(CP3<5,"")))))))))) | CT3: 1 | CU3: =Data!B2 -> ABBA FIRA ALINGADTHER | CZ3: =SUM(CV3:CY3) -> 0 | DB3: =CZ3+DA3 -> 0 | DC3: =IF(DB3<10,"",RANK(DB3,DB$3:DB$52)) | DD3: =IF(DB3>=75,"A1",IF(DB3>=70,"B2",IF(DB3>=65,"B3",IF(DB3>=60,"C4",IF(DB3>=55,"C5",IF(DB3>=50,"C6",IF(DB3>=45,"D7",IF(DB3>=40,"E8",IF(DB3>=6,"F",IF(DB3<5,"")))))))))) | DE3: =IF(DB3>=75,"Excellent",IF(DB3>=70,"V.Good",IF(DB3>=65,"Good",IF(DB3>=60,"Credit",IF(DB3>=55,"Credit",IF(DB3>=50,"Credit",IF(DB3>=45,"Pass",IF(DB3>=40,"Pass",IF(DB3>=6,"Fail",IF(DB3<5,"")))))))))) | DF3: 1 | DG3: =Data!B2 -> ABBA FIRA ALINGADTHER | DH3: 7 | DI3: 3 | DJ3: 2 | DK3: 5 | DL3: =SUM(DH3:DK3) -> 17 | DM3: 19 | DN3: =DL3+DM3 -> 36 | DO3: =IF(DN3<10,"",RANK(DN3,DN$3:DN$52)) -> 6 | DP3: =IF(DN3>=75,"A1",IF(DN3>=70,"B2",IF(DN3>=65,"B3",IF(DN3>=60,"C4",IF(DN3>=55,"C5",IF(DN3>=50,"C6",IF(DN3>=45,"D7",IF(DN3>=40,"E8",IF(DN3>=6,"F",IF(DN3<5,"")))))))))) -> F | DQ3: =IF(DN3>=75,"Excellent",IF(DN3>=70,"V.Good",IF(DN3>=65,"Good",IF(DN3>=60,"Credit",IF(DN3>=55,"Credit",IF(DN3>=50,"Credit",IF(DN3>=45,"Pass",IF(DN3>=40,"Pass",IF(DN3>=6,"Fail",IF(DN3<5,"")))))))))) -> Fail | DR3: 1 | DS3: =Data!B2 -> ABBA FIRA ALINGADTHER | DX3: =SUM(DT3:DW3) -> 0 | DZ3: =DX3+DY3 -> 0 | EA3: =IF(DZ3<10,"",RANK(DZ3,DZ$3:DZ$52)) | EB3: =IF(DZ3>=75,"A1",IF(DZ3>=70,"B2",IF(DZ3>=65,"B3",IF(DZ3>=60,"C4",IF(DZ3>=55,"C5",IF(DZ3>=50,"C6",IF(DZ3>=45,"D7",IF(DZ3>=40,"E8",IF(DZ3>=6,"F",IF(DZ3<5,"")))))))))) | EC3: =IF(DZ3>=75,"Excellent",IF(DZ3>=70,"V.Good",IF(DZ3>=65,"Good",IF(DZ3>=60,"Credit",IF(DZ3>=55,"Credit",IF(DZ3>=50,"Credit",IF(DZ3>=45,"Pass",IF(DZ3>=40,"Pass",IF(DZ3>=6,"Fail",IF(DZ3<5,"")))))))))) | ED3: 1 | EE3: =Data!B2 -> ABBA FIRA ALINGADTHER | EJ3: =SUM(EF3:EI3) -> 0 | EL3: =EJ3+EK3 -> 0 | EM3: =IF(EL3<10,"",RANK(EL3,EL$3:EL$52)) | EN3: =IF(EL3>=75,"A1",IF(EL3>=70,"B2",IF(EL3>=65,"B3",IF(EL3>=60,"C4",IF(EL3>=55,"C5",IF(EL3>=50,"C6",IF(EL3>=45,"D7",IF(EL3>=40,"E8",IF(EL3>=6,"F",IF(EL3<5,"")))))))))) | EO3: =IF(EL3>=75,"Excellent",IF(EL3>=70,"V.Good",IF(EL3>=65,"Good",IF(EL3>=60,"Credit",IF(EL3>=55,"Credit",IF(EL3>=50,"Credit",IF(EL3>=45,"Pass",IF(EL3>=40,"Pass",IF(EL3>=6,"Fail",IF(EL3<5,"")))))))))) | EP3: 1 | EQ3: =Data!B2 -> ABBA FIRA ALINGADTHER | EV3: =SUM(ER3:EU3) -> 0 | EX3: =EV3+EW3 -> 0 | EY3: =IF(EX3<10,"",RANK(EX3,EX$3:EX$52)) | EZ3: =IF(EX3>=75,"A1",IF(EX3>=70,"B2",IF(EX3>=65,"B3",IF(EX3>=60,"C4",IF(EX3>=55,"C5",IF(EX3>=50,"C6",IF(EX3>=45,"D7",IF(EX3>=40,"E8",IF(EX3>=6,"F",IF(EX3<5,"")))))))))) | FA3: =IF(EX3>=75,"Excellent",IF(EX3>=70,"V.Good",IF(EX3>=65,"Good",IF(EX3>=60,"Credit",IF(EX3>=55,"Credit",IF(EX3>=50,"Credit",IF(EX3>=45,"Pass",IF(EX3>=40,"Pass",IF(EX3>=6,"Fail",IF(EX3<5,"")))))))))) | FB3: 1 | FC3: =Data!B2 -> ABBA FIRA ALINGADTHER | FH3: =SUM(FD3:FG3) -> 0 | FJ3: =FH3+FI3 -> 0 | FK3: =IF(FJ3<10,"",RANK(FJ3,FJ$3:FJ$52)) | FL3: =IF(FJ3>=75,"A",IF(FJ3>=70,"B2",IF(FJ3>=50,"C",IF(FJ3>=45,"D",IF(FJ3>=40,"E",IF(FJ3>=6,"F",IF(FJ3<5,""))))))) | FM3: =IF(FJ3>=75,"Excellent",IF(FJ3>=70,"V.Good",IF(FJ3>=65,"Good",IF(FJ3>=60,"Credit",IF(FJ3>=55,"Credit",IF(FJ3>=50,"Credit",IF(FJ3>=45,"Pass",IF(FJ3>=40,"Pass",IF(FJ3>=6,"Fail",IF(FJ3<5,"")))))))))) | FN3: 1 | FO3: =Data!B2 -> ABBA FIRA ALINGADTHER | FT3: =SUM(FP3:FS3) -> 0 | FV3: =FT3+FU3 -> 0 | FW3: =IF(FV3<10,"",RANK(FV3,FV$3:FV$52)) | FX3: =IF(FV3>=75,"A",IF(FV3>=70,"B2",IF(FV3>=50,"C",IF(FV3>=45,"D",IF(FV3>=40,"E",IF(FV3>=6,"F",IF(FV3<5,""))))))) | FY3: =IF(FV3>=75,"Excellent",IF(FV3>=70,"V.Good",IF(FV3>=65,"Good",IF(FV3>=60,"Credit",IF(FV3>=55,"Credit",IF(FV3>=50,"Credit",IF(FV3>=45,"Pass",IF(FV3>=40,"Pass",IF(FV3>=6,"Fail",IF(FV3<5,"")))))))))) | FZ3: 1 | GA3: =Data!B2 -> ABBA FIRA ALINGADTHER | GF3: =SUM(GB3:GE3) -> 0 | GH3: =GF3+GG3 -> 0 | GI3: =IF(GH3<10,"",RANK(GH3,GH$3:GH$52)) | GJ3: =IF(GH3>=75,"A",IF(GH3>=70,"B2",IF(GH3>=50,"C",IF(GH3>=45,"D",IF(GH3>=40,"E",IF(GH3>=6,"F",IF(GH3<5,""))))))) | GK3: =IF(GH3>=75,"Excellent",IF(GH3>=70,"V.Good",IF(GH3>=65,"Good",IF(GH3>=60,"Credit",IF(GH3>=55,"Credit",IF(GH3>=50,"Credit",IF(GH3>=45,"Pass",IF(GH3>=40,"Pass",IF(GH3>=6,"Fail",IF(GH3<5,"")))))))))) | GL3: 1 | GM3: =Data!B2 -> ABBA FIRA ALINGADTHER | GR3: =SUM(GN3:GQ3) -> 0 | GT3: =GR3+GS3 -> 0 | GU3: =IF(GT3<10,"",RANK(GT3,GT$3:GT$52)) | GV3: =IF(GT3>=75,"A",IF(GT3>=70,"B2",IF(GT3>=50,"C",IF(GT3>=45,"D",IF(GT3>=40,"E",IF(GT3>=6,"F",IF(GT3<5,""))))))) | GW3: =IF(GT3>=75,"Excellent",IF(GT3>=70,"V.Good",IF(GT3>=65,"Good",IF(GT3>=60,"Credit",IF(GT3>=55,"Credit",IF(GT3>=50,"Credit",IF(GT3>=45,"Pass",IF(GT3>=40,"Pass",IF(GT3>=6,"Fail",IF(GT3<5,"")))))))))) | GX3: 1 | GY3: =Data!B2 -> ABBA FIRA ALINGADTHER | HD3: =SUM(GZ3:HC3) -> 0 | HF3: =HD3+HE3 -> 0 | HG3: =IF(HF3<10,"",RANK(HF3,HF$3:HF$52)) | HH3: =IF(HF3>=75,"A",IF(HF3>=70,"B2",IF(HF3>=50,"C",IF(HF3>=45,"D",IF(HF3>=40,"E",IF(HF3>=6,"F",IF(HF3<5,""))))))) | HI3: =IF(HF3>=75,"Excellent",IF(HF3>=70,"V.Good",IF(HF3>=65,"Good",IF(HF3>=60,"Credit",IF(HF3>=55,"Credit",IF(HF3>=50,"Credit",IF(HF3>=45,"Pass",IF(HF3>=40,"Pass",IF(HF3>=6,"Fail",IF(HF3<5,"")))))))))) | HJ3: 1 | HK3: =Data!B2 -> ABBA FIRA ALINGADTHER | HP3: =SUM(HL3:HO3) -> 0 | HR3: =HP3+HQ3 -> 0 | HS3: =IF(HR3<10,"",RANK(HR3,HR$3:HR$52)) | HT3: =IF(HR3>=75,"A",IF(HR3>=70,"B2",IF(HR3>=50,"C",IF(HR3>=45,"D",IF(HR3>=40,"E",IF(HR3>=6,"F",IF(HR3<5,""))))))) | HU3: =IF(HR3>=75,"Excellent",IF(HR3>=70,"V.Good",IF(HR3>=65,"Good",IF(HR3>=60,"Credit",IF(HR3>=55,"Credit",IF(HR3>=50,"Credit",IF(HR3>=45,"Pass",IF(HR3>=40,"Pass",IF(HR3>=6,"Fail",IF(HR3<5,"")))))))))) | HV3: 1 | HW3: =Data!B2 -> ABBA FIRA ALINGADTHER | IB3: =SUM(HX3:IA3) -> 0 | ID3: =IB3+IC3 -> 0 | IE3: =IF(ID3<10,"",RANK(ID3,ID$3:ID$52)) | IF3: =IF(ID3>=75,"A",IF(ID3>=70,"B2",IF(ID3>=50,"C",IF(ID3>=45,"D",IF(ID3>=40,"E",IF(ID3>=6,"F",IF(ID3<5,""))))))) | IG3: =IF(ID3>=75,"Excellent",IF(ID3>=70,"V.Good",IF(ID3>=65,"Good",IF(ID3>=60,"Credit",IF(ID3>=55,"Credit",IF(ID3>=50,"Credit",IF(ID3>=45,"Pass",IF(ID3>=40,"Pass",IF(ID3>=6,"Fail",IF(ID3<5,"")))))))))) | IH3: 1 | II3: =Data!B2 -> ABBA FIRA ALINGADTHER | IN3: =SUM(IJ3:IM3) -> 0 | IP3: =IN3+IO3 -> 0 | IQ3: =IF(IP3<10,"",RANK(IP3,IP$3:IP$52)) | IR3: =IF(IP3>=75,"A",IF(IP3>=70,"B2",IF(IP3>=50,"C",IF(IP3>=45,"D",IF(IP3>=40,"E",IF(IP3>=6,"F",IF(IP3<5,""))))))) | IS3: =IF(IP3>=75,"Excellent",IF(IP3>=70,"V.Good",IF(IP3>=65,"Good",IF(IP3>=60,"Credit",IF(IP3>=55,"Credit",IF(IP3>=50,"Credit",IF(IP3>=45,"Pass",IF(IP3>=40,"Pass",IF(IP3>=6,"Fail",IF(IP3<5,"")))))))))) | IT3: 1 | IU3: =II3 -> ABBA FIRA ALINGADTHER | IZ3: =SUM(IV3:IY3) -> 0 | JB3: =IZ3+JA3 -> 0 | JC3: =IF(JB3<10,"",RANK(JB3,JB$3:JB$52)) | JD3: =IF(JB3>=75,"A",IF(JB3>=70,"B2",IF(JB3>=50,"C",IF(JB3>=45,"D",IF(JB3>=40,"E",IF(JB3>=6,"F",IF(JB3<5,""))))))) | JE3: =IF(JB3>=75,"Excellent",IF(JB3>=70,"V.Good",IF(JB3>=65,"Good",IF(JB3>=60,"Credit",IF(JB3>=55,"Credit",IF(JB3>=50,"Credit",IF(JB3>=45,"Pass",IF(JB3>=40,"Pass",IF(JB3>=6,"Fail",IF(JB3<5,"")))))))))) | JF3: 1 | JG3: =IU3 -> ABBA FIRA ALINGADTHER | JL3: =SUM(JH3:JK3) -> 0 | JN3: =JL3+JM3 -> 0 | JO3: =IF(JN3<10,"",RANK(JN3,JN$3:JN$52)) | JP3: =IF(JN3>=75,"A",IF(JN3>=70,"B2",IF(JN3>=50,"C",IF(JN3>=45,"D",IF(JN3>=40,"E",IF(JN3>=6,"F",IF(JN3<5,""))))))) | JQ3: =IF(JN3>=75,"Excellent",IF(JN3>=70,"V.Good",IF(JN3>=65,"Good",IF(JN3>=60,"Credit",IF(JN3>=55,"Credit",IF(JN3>=50,"Credit",IF(JN3>=45,"Pass",IF(JN3>=40,"Pass",IF(JN3>=6,"Fail",IF(JN3<5,"")))))))))) | JR3: 1 | JS3: =JG3 -> ABBA FIRA ALINGADTHER | JX3: =SUM(JT3:JW3) -> 0 | JZ3: =JX3+JY3 -> 0 | KA3: =IF(JZ3<10,"",RANK(JZ3,JZ$3:JZ$52)) | KB3: =IF(JZ3>=75,"A",IF(JZ3>=70,"B2",IF(JZ3>=50,"C",IF(JZ3>=45,"D",IF(JZ3>=40,"E",IF(JZ3>=6,"F",IF(JZ3<5,""))))))) | KC3: =IF(JZ3>=75,"Excellent",IF(JZ3>=70,"V.Good",IF(JZ3>=65,"Good",IF(JZ3>=60,"Credit",IF(JZ3>=55,"Credit",IF(JZ3>=50,"Credit",IF(JZ3>=45,"Pass",IF(JZ3>=40,"Pass",IF(JZ3>=6,"Fail",IF(JZ3<5,""))))))))))
A4: 2 | B4: 2 | C4: =Data!B3 -> AMINU MUHAMMED AL MUSTAPHA | D4: 6 | E4: 7 | F4: 8 | G4: 6 | H4: =SUM(D4:G4) -> 27 | I4: 19 | J4: =H4+I4 -> 46 | K4: =IF(J4<10,"",RANK(J4,J$3:J$52)) -> 40 | L4: =IF(J4>=75,"A1",IF(J4>=70,"B2",IF(J4>=65,"B3",IF(J4>=60,"C4",IF(J4>=55,"C5",IF(J4>=50,"C6",IF(J4>=45,"D7",IF(J4>=40,"E8",IF(J4>=6,"F",IF(J4<5,"")))))))))) -> D7 | M4: =IF(J4>=75,"Excellent",IF(J4>=70,"V.Good",IF(J4>=65,"Good",IF(J4>=60,"Credit",IF(J4>=55,"Credit",IF(J4>=50,"Credit",IF(J4>=45,"Pass",IF(J4>=40,"Pass",IF(J4>=6,"Fail",IF(J4<5,"")))))))))) -> Pass | N4: 2 | O4: =Data!B3 -> AMINU MUHAMMED AL MUSTAPHA | T4: =SUM(P4:S4) -> 0 | V4: =T4+U4 -> 0 | W4: =IF(V4<10,"",RANK(V4,V$3:V$52)) | X4: =IF(V4>=75,"A1",IF(V4>=70,"B2",IF(V4>=65,"B3",IF(V4>=60,"C4",IF(V4>=55,"C5",IF(V4>=50,"C6",IF(V4>=45,"D7",IF(V4>=40,"E8",IF(V4>=6,"F",IF(V4<5,"")))))))))) | Y4: =IF(V4>=75,"Excellent",IF(V4>=70,"V.Good",IF(V4>=65,"Good",IF(V4>=60,"Credit",IF(V4>=55,"Credit",IF(V4>=50,"Credit",IF(V4>=45,"Pass",IF(V4>=40,"Pass",IF(V4>=6,"Fail",IF(V4<5,"")))))))))) | Z4: 2 | AA4: =Data!B3 -> AMINU MUHAMMED AL MUSTAPHA | AB4: 6 | AC4: 7 | AD4: 8 | AE4: 6 | AF4: =SUM(AB4:AE4) -> 27 | AG4: 19 | AH4: =AF4+AG4 -> 46 | AI4: =IF(AH4<10,"",RANK(AH4,AH$3:AH$52)) -> 40 | AJ4: =IF(AH4>=75,"A1",IF(AH4>=70,"B2",IF(AH4>=65,"B3",IF(AH4>=60,"C4",IF(AH4>=55,"C5",IF(AH4>=50,"C6",IF(AH4>=45,"D7",IF(AH4>=40,"E8",IF(AH4>=6,"F",IF(AH4<5,"")))))))))) -> D7 | AK4: =IF(AH4>=75,"Excellent",IF(AH4>=70,"V.Good",IF(AH4>=65,"Good",IF(AH4>=60,"Credit",IF(AH4>=55,"Credit",IF(AH4>=50,"Credit",IF(AH4>=45,"Pass",IF(AH4>=40,"Pass",IF(AH4>=6,"Fail",IF(AH4<5,"")))))))))) -> Pass | AL4: 2 | AM4: =Data!B3 -> AMINU MUHAMMED AL MUSTAPHA | AN4: 6 | AO4: 7 | AP4: 8 | AQ4: 6 | AR4: =SUM(AN4:AQ4) -> 27 | AS4: 19 | AT4: =AR4+AS4 -> 46 | AU4: =IF(AT4<10,"",RANK(AT4,AT$3:AT$52)) -> 40 | AV4: =IF(AT4>=75,"A1",IF(AT4>=70,"B2",IF(AT4>=65,"B3",IF(AT4>=60,"C4",IF(AT4>=55,"C5",IF(AT4>=50,"C6",IF(AT4>=45,"D7",IF(AT4>=40,"E8",IF(AT4>=6,"F",IF(AT4<5,"")))))))))) -> D7 | AW4: =IF(AT4>=75,"Excellent",IF(AT4>=70,"V.Good",IF(AT4>=65,"Good",IF(AT4>=60,"Credit",IF(AT4>=55,"Credit",IF(AT4>=50,"Credit",IF(AT4>=45,"Pass",IF(AT4>=40,"Pass",IF(AT4>=6,"Fail",IF(AT4<5,"")))))))))) -> Pass | AX4: 2 | AY4: =Data!B3 -> AMINU MUHAMMED AL MUSTAPHA | AZ4: 6 | BA4: 7 | BB4: 8 | BC4: 6 | BD4: =SUM(AZ4:BC4) -> 27 | BE4: 19 | BF4: =BD4+BE4 -> 46 | BG4: =IF(BF4<10,"",RANK(BF4,BF$3:BF$52)) -> 40 | BH4: =IF(BF4>=75,"A1",IF(BF4>=70,"B2",IF(BF4>=65,"B3",IF(BF4>=60,"C4",IF(BF4>=55,"C5",IF(BF4>=50,"C6",IF(BF4>=45,"D7",IF(BF4>=40,"E8",IF(BF4>=6,"F",IF(BF4<5,"")))))))))) -> D7 | BI4: =IF(BF4>=75,"Excellent",IF(BF4>=70,"V.Good",IF(BF4>=65,"Good",IF(BF4>=60,"Credit",IF(BF4>=55,"Credit",IF(BF4>=50,"Credit",IF(BF4>=45,"Pass",IF(BF4>=40,"Pass",IF(BF4>=6,"Fail",IF(BF4<5,"")))))))))) -> Pass | BJ4: 2 | BK4: =Data!B3 -> AMINU MUHAMMED AL MUSTAPHA | BL4: 6 | BM4: 7 | BN4: 8 | BO4: 6 | BP4: =SUM(BL4:BO4) -> 27 | BQ4: 19 | BR4: =BP4+BQ4 -> 46 | BS4: =IF(BR4<10,"",RANK(BR4,BR$3:BR$52)) -> 40 | BT4: =IF(BR4>=75,"A1",IF(BR4>=70,"B2",IF(BR4>=65,"B3",IF(BR4>=60,"C4",IF(BR4>=55,"C5",IF(BR4>=50,"C6",IF(BR4>=45,"D7",IF(BR4>=40,"E8",IF(BR4>=6,"F",IF(BR4<5,"")))))))))) -> D7 | BU4: =IF(BR4>=75,"Excellent",IF(BR4>=70,"V.Good",IF(BR4>=65,"Good",IF(BR4>=60,"Credit",IF(BR4>=55,"Credit",IF(BR4>=50,"Credit",IF(BR4>=45,"Pass",IF(BR4>=40,"Pass",IF(BR4>=6,"Fail",IF(BR4<5,"")))))))))) -> Pass | BV4: 2 | BW4: =Data!B3 -> AMINU MUHAMMED AL MUSTAPHA | BX4: 6 | BY4: 7 | BZ4: 8 | CA4: 6 | CB4: =SUM(BX4:CA4) -> 27 | CC4: 19 | CD4: =CB4+CC4 -> 46 | CE4: =IF(CD4<10,"",RANK(CD4,CD$3:CD$52)) -> 40 | CF4: =IF(CD4>=75,"A1",IF(CD4>=70,"B2",IF(CD4>=65,"B3",IF(CD4>=60,"C4",IF(CD4>=55,"C5",IF(CD4>=50,"C6",IF(CD4>=45,"D7",IF(CD4>=40,"E8",IF(CD4>=6,"F",IF(CD4<5,"")))))))))) -> D7 | CG4: =IF(CD4>=75,"Excellent",IF(CD4>=70,"V.Good",IF(CD4>=65,"Good",IF(CD4>=60,"Credit",IF(CD4>=55,"Credit",IF(CD4>=50,"Credit",IF(CD4>=45,"Pass",IF(CD4>=40,"Pass",IF(CD4>=6,"Fail",IF(CD4<5,"")))))))))) -> Pass | CH4: 2 | CI4: =Data!B3 -> AMINU MUHAMMED AL MUSTAPHA | CN4: =SUM(CJ4:CM4) -> 0 | CP4: =CN4+CO4 -> 0 | CQ4: =IF(CP4<10,"",RANK(CP4,CP$3:CP$52)) | CR4: =IF(CP4>=75,"A1",IF(CP4>=70,"B2",IF(CP4>=65,"B3",IF(CP4>=60,"C4",IF(CP4>=55,"C5",IF(CP4>=50,"C6",IF(CP4>=45,"D7",IF(CP4>=40,"E8",IF(CP4>=6,"F",IF(CP4<5,"")))))))))) | CS4: =IF(CP4>=75,"Excellent",IF(CP4>=70,"V.Good",IF(CP4>=65,"Good",IF(CP4>=60,"Credit",IF(CP4>=55,"Credit",IF(CP4>=50,"Credit",IF(CP4>=45,"Pass",IF(CP4>=40,"Pass",IF(CP4>=6,"Fail",IF(CP4<5,"")))))))))) | CT4: 2 | CU4: =Data!B3 -> AMINU MUHAMMED AL MUSTAPHA | CZ4: =SUM(CV4:CY4) -> 0 | DB4: =CZ4+DA4 -> 0 | DC4: =IF(DB4<10,"",RANK(DB4,DB$3:DB$52)) | DD4: =IF(DB4>=75,"A1",IF(DB4>=70,"B2",IF(DB4>=65,"B3",IF(DB4>=60,"C4",IF(DB4>=55,"C5",IF(DB4>=50,"C6",IF(DB4>=45,"D7",IF(DB4>=40,"E8",IF(DB4>=6,"F",IF(DB4<5,"")))))))))) | DE4: =IF(DB4>=75,"Excellent",IF(DB4>=70,"V.Good",IF(DB4>=65,"Good",IF(DB4>=60,"Credit",IF(DB4>=55,"Credit",IF(DB4>=50,"Credit",IF(DB4>=45,"Pass",IF(DB4>=40,"Pass",IF(DB4>=6,"Fail",IF(DB4<5,"")))))))))) | DF4: 2 | DG4: =Data!B3 -> AMINU MUHAMMED AL MUSTAPHA | DL4: =SUM(DH4:DK4) -> 0 | DN4: =DL4+DM4 -> 0 | DO4: =IF(DN4<10,"",RANK(DN4,DN$3:DN$52)) | DP4: =IF(DN4>=75,"A1",IF(DN4>=70,"B2",IF(DN4>=65,"B3",IF(DN4>=60,"C4",IF(DN4>=55,"C5",IF(DN4>=50,"C6",IF(DN4>=45,"D7",IF(DN4>=40,"E8",IF(DN4>=6,"F",IF(DN4<5,"")))))))))) | DQ4: =IF(DN4>=75,"Excellent",IF(DN4>=70,"V.Good",IF(DN4>=65,"Good",IF(DN4>=60,"Credit",IF(DN4>=55,"Credit",IF(DN4>=50,"Credit",IF(DN4>=45,"Pass",IF(DN4>=40,"Pass",IF(DN4>=6,"Fail",IF(DN4<5,"")))))))))) | DR4: 2 | DS4: =Data!B3 -> AMINU MUHAMMED AL MUSTAPHA | DX4: =SUM(DT4:DW4) -> 0 | DZ4: =DX4+DY4 -> 0 | EA4: =IF(DZ4<10,"",RANK(DZ4,DZ$3:DZ$52)) | EB4: =IF(DZ4>=75,"A1",IF(DZ4>=70,"B2",IF(DZ4>=65,"B3",IF(DZ4>=60,"C4",IF(DZ4>=55,"C5",IF(DZ4>=50,"C6",IF(DZ4>=45,"D7",IF(DZ4>=40,"E8",IF(DZ4>=6,"F",IF(DZ4<5,"")))))))))) | EC4: =IF(DZ4>=75,"Excellent",IF(DZ4>=70,"V.Good",IF(DZ4>=65,"Good",IF(DZ4>=60,"Credit",IF(DZ4>=55,"Credit",IF(DZ4>=50,"Credit",IF(DZ4>=45,"Pass",IF(DZ4>=40,"Pass",IF(DZ4>=6,"Fail",IF(DZ4<5,"")))))))))) | ED4: 2 | EE4: =Data!B3 -> AMINU MUHAMMED AL MUSTAPHA | EJ4: =SUM(EF4:EI4) -> 0 | EL4: =EJ4+EK4 -> 0 | EM4: =IF(EL4<10,"",RANK(EL4,EL$3:EL$52)) | EN4: =IF(EL4>=75,"A1",IF(EL4>=70,"B2",IF(EL4>=65,"B3",IF(EL4>=60,"C4",IF(EL4>=55,"C5",IF(EL4>=50,"C6",IF(EL4>=45,"D7",IF(EL4>=40,"E8",IF(EL4>=6,"F",IF(EL4<5,"")))))))))) | EO4: =IF(EL4>=75,"Excellent",IF(EL4>=70,"V.Good",IF(EL4>=65,"Good",IF(EL4>=60,"Credit",IF(EL4>=55,"Credit",IF(EL4>=50,"Credit",IF(EL4>=45,"Pass",IF(EL4>=40,"Pass",IF(EL4>=6,"Fail",IF(EL4<5,"")))))))))) | EP4: 2 | EQ4: =Data!B3 -> AMINU MUHAMMED AL MUSTAPHA | EV4: =SUM(ER4:EU4) -> 0 | EX4: =EV4+EW4 -> 0 | EY4: =IF(EX4<10,"",RANK(EX4,EX$3:EX$52)) | EZ4: =IF(EX4>=75,"A1",IF(EX4>=70,"B2",IF(EX4>=65,"B3",IF(EX4>=60,"C4",IF(EX4>=55,"C5",IF(EX4>=50,"C6",IF(EX4>=45,"D7",IF(EX4>=40,"E8",IF(EX4>=6,"F",IF(EX4<5,"")))))))))) | FA4: =IF(EX4>=75,"Excellent",IF(EX4>=70,"V.Good",IF(EX4>=65,"Good",IF(EX4>=60,"Credit",IF(EX4>=55,"Credit",IF(EX4>=50,"Credit",IF(EX4>=45,"Pass",IF(EX4>=40,"Pass",IF(EX4>=6,"Fail",IF(EX4<5,"")))))))))) | FB4: 2 | FC4: =Data!B3 -> AMINU MUHAMMED AL MUSTAPHA | FH4: =SUM(FD4:FG4) -> 0 | FJ4: =FH4+FI4 -> 0 | FK4: =IF(FJ4<10,"",RANK(FJ4,FJ$3:FJ$52)) | FL4: =IF(FJ4>=75,"A",IF(FJ4>=70,"B2",IF(FJ4>=50,"C",IF(FJ4>=45,"D",IF(FJ4>=40,"E",IF(FJ4>=6,"F",IF(FJ4<5,""))))))) | FM4: =IF(FJ4>=75,"Excellent",IF(FJ4>=70,"V.Good",IF(FJ4>=65,"Good",IF(FJ4>=60,"Credit",IF(FJ4>=55,"Credit",IF(FJ4>=50,"Credit",IF(FJ4>=45,"Pass",IF(FJ4>=40,"Pass",IF(FJ4>=6,"Fail",IF(FJ4<5,"")))))))))) | FN4: 2 | FO4: =Data!B3 -> AMINU MUHAMMED AL MUSTAPHA | FT4: =SUM(FP4:FS4) -> 0 | FV4: =FT4+FU4 -> 0 | FW4: =IF(FV4<10,"",RANK(FV4,FV$3:FV$52)) | FX4: =IF(FV4>=75,"A",IF(FV4>=70,"B2",IF(FV4>=50,"C",IF(FV4>=45,"D",IF(FV4>=40,"E",IF(FV4>=6,"F",IF(FV4<5,""))))))) | FY4: =IF(FV4>=75,"Excellent",IF(FV4>=70,"V.Good",IF(FV4>=65,"Good",IF(FV4>=60,"Credit",IF(FV4>=55,"Credit",IF(FV4>=50,"Credit",IF(FV4>=45,"Pass",IF(FV4>=40,"Pass",IF(FV4>=6,"Fail",IF(FV4<5,"")))))))))) | FZ4: 2 | GA4: =Data!B3 -> AMINU MUHAMMED AL MUSTAPHA | GF4: =SUM(GB4:GE4) -> 0 | GH4: =GF4+GG4 -> 0 | GI4: =IF(GH4<10,"",RANK(GH4,GH$3:GH$52)) | GJ4: =IF(GH4>=75,"A",IF(GH4>=70,"B2",IF(GH4>=50,"C",IF(GH4>=45,"D",IF(GH4>=40,"E",IF(GH4>=6,"F",IF(GH4<5,""))))))) | GK4: =IF(GH4>=75,"Excellent",IF(GH4>=70,"V.Good",IF(GH4>=65,"Good",IF(GH4>=60,"Credit",IF(GH4>=55,"Credit",IF(GH4>=50,"Credit",IF(GH4>=45,"Pass",IF(GH4>=40,"Pass",IF(GH4>=6,"Fail",IF(GH4<5,"")))))))))) | GL4: 2 | GM4: =Data!B3 -> AMINU MUHAMMED AL MUSTAPHA | GR4: =SUM(GN4:GQ4) -> 0 | GT4: =GR4+GS4 -> 0 | GU4: =IF(GT4<10,"",RANK(GT4,GT$3:GT$52)) | GV4: =IF(GT4>=75,"A",IF(GT4>=70,"B2",IF(GT4>=50,"C",IF(GT4>=45,"D",IF(GT4>=40,"E",IF(GT4>=6,"F",IF(GT4<5,""))))))) | GW4: =IF(GT4>=75,"Excellent",IF(GT4>=70,"V.Good",IF(GT4>=65,"Good",IF(GT4>=60,"Credit",IF(GT4>=55,"Credit",IF(GT4>=50,"Credit",IF(GT4>=45,"Pass",IF(GT4>=40,"Pass",IF(GT4>=6,"Fail",IF(GT4<5,"")))))))))) | GX4: 2 | GY4: =Data!B3 -> AMINU MUHAMMED AL MUSTAPHA | HD4: =SUM(GZ4:HC4) -> 0 | HF4: =HD4+HE4 -> 0 | HG4: =IF(HF4<10,"",RANK(HF4,HF$3:HF$52)) | HH4: =IF(HF4>=75,"A",IF(HF4>=70,"B2",IF(HF4>=50,"C",IF(HF4>=45,"D",IF(HF4>=40,"E",IF(HF4>=6,"F",IF(HF4<5,""))))))) | HI4: =IF(HF4>=75,"Excellent",IF(HF4>=70,"V.Good",IF(HF4>=65,"Good",IF(HF4>=60,"Credit",IF(HF4>=55,"Credit",IF(HF4>=50,"Credit",IF(HF4>=45,"Pass",IF(HF4>=40,"Pass",IF(HF4>=6,"Fail",IF(HF4<5,"")))))))))) | HJ4: 2 | HK4: =Data!B3 -> AMINU MUHAMMED AL MUSTAPHA | HP4: =SUM(HL4:HO4) -> 0 | HR4: =HP4+HQ4 -> 0 | HS4: =IF(HR4<10,"",RANK(HR4,HR$3:HR$52)) | HT4: =IF(HR4>=75,"A",IF(HR4>=70,"B2",IF(HR4>=50,"C",IF(HR4>=45,"D",IF(HR4>=40,"E",IF(HR4>=6,"F",IF(HR4<5,""))))))) | HU4: =IF(HR4>=75,"Excellent",IF(HR4>=70,"V.Good",IF(HR4>=65,"Good",IF(HR4>=60,"Credit",IF(HR4>=55,"Credit",IF(HR4>=50,"Credit",IF(HR4>=45,"Pass",IF(HR4>=40,"Pass",IF(HR4>=6,"Fail",IF(HR4<5,"")))))))))) | HV4: 2 | HW4: =Data!B3 -> AMINU MUHAMMED AL MUSTAPHA | IB4: =SUM(HX4:IA4) -> 0 | ID4: =IB4+IC4 -> 0 | IE4: =IF(ID4<10,"",RANK(ID4,ID$3:ID$52)) | IF4: =IF(ID4>=75,"A",IF(ID4>=70,"B2",IF(ID4>=50,"C",IF(ID4>=45,"D",IF(ID4>=40,"E",IF(ID4>=6,"F",IF(ID4<5,""))))))) | IG4: =IF(ID4>=75,"Excellent",IF(ID4>=70,"V.Good",IF(ID4>=65,"Good",IF(ID4>=60,"Credit",IF(ID4>=55,"Credit",IF(ID4>=50,"Credit",IF(ID4>=45,"Pass",IF(ID4>=40,"Pass",IF(ID4>=6,"Fail",IF(ID4<5,"")))))))))) | IH4: 2 | II4: =Data!B3 -> AMINU MUHAMMED AL MUSTAPHA | IN4: =SUM(IJ4:IM4) -> 0 | IP4: =IN4+IO4 -> 0 | IQ4: =IF(IP4<10,"",RANK(IP4,IP$3:IP$52)) | IR4: =IF(IP4>=75,"A",IF(IP4>=70,"B2",IF(IP4>=50,"C",IF(IP4>=45,"D",IF(IP4>=40,"E",IF(IP4>=6,"F",IF(IP4<5,""))))))) | IS4: =IF(IP4>=75,"Excellent",IF(IP4>=70,"V.Good",IF(IP4>=65,"Good",IF(IP4>=60,"Credit",IF(IP4>=55,"Credit",IF(IP4>=50,"Credit",IF(IP4>=45,"Pass",IF(IP4>=40,"Pass",IF(IP4>=6,"Fail",IF(IP4<5,"")))))))))) | IT4: 2 | IU4: =II4 -> AMINU MUHAMMED AL MUSTAPHA | IZ4: =SUM(IV4:IY4) -> 0 | JB4: =IZ4+JA4 -> 0 | JC4: =IF(JB4<10,"",RANK(JB4,JB$3:JB$52)) | JD4: =IF(JB4>=75,"A",IF(JB4>=70,"B2",IF(JB4>=50,"C",IF(JB4>=45,"D",IF(JB4>=40,"E",IF(JB4>=6,"F",IF(JB4<5,""))))))) | JE4: =IF(JB4>=75,"Excellent",IF(JB4>=70,"V.Good",IF(JB4>=65,"Good",IF(JB4>=60,"Credit",IF(JB4>=55,"Credit",IF(JB4>=50,"Credit",IF(JB4>=45,"Pass",IF(JB4>=40,"Pass",IF(JB4>=6,"Fail",IF(JB4<5,"")))))))))) | JF4: 2 | JG4: =IU4 -> AMINU MUHAMMED AL MUSTAPHA | JL4: =SUM(JH4:JK4) -> 0 | JN4: =JL4+JM4 -> 0 | JO4: =IF(JN4<10,"",RANK(JN4,JN$3:JN$52)) | JP4: =IF(JN4>=75,"A",IF(JN4>=70,"B2",IF(JN4>=50,"C",IF(JN4>=45,"D",IF(JN4>=40,"E",IF(JN4>=6,"F",IF(JN4<5,""))))))) | JQ4: =IF(JN4>=75,"Excellent",IF(JN4>=70,"V.Good",IF(JN4>=65,"Good",IF(JN4>=60,"Credit",IF(JN4>=55,"Credit",IF(JN4>=50,"Credit",IF(JN4>=45,"Pass",IF(JN4>=40,"Pass",IF(JN4>=6,"Fail",IF(JN4<5,"")))))))))) | JR4: 2 | JS4: =JG4 -> AMINU MUHAMMED AL MUSTAPHA | JX4: =SUM(JT4:JW4) -> 0 | JZ4: =JX4+JY4 -> 0 | KA4: =IF(JZ4<10,"",RANK(JZ4,JZ$3:JZ$52)) | KB4: =IF(JZ4>=75,"A",IF(JZ4>=70,"B2",IF(JZ4>=50,"C",IF(JZ4>=45,"D",IF(JZ4>=40,"E",IF(JZ4>=6,"F",IF(JZ4<5,""))))))) | KC4: =IF(JZ4>=75,"Excellent",IF(JZ4>=70,"V.Good",IF(JZ4>=65,"Good",IF(JZ4>=60,"Credit",IF(JZ4>=55,"Credit",IF(JZ4>=50,"Credit",IF(JZ4>=45,"Pass",IF(JZ4>=40,"Pass",IF(JZ4>=6,"Fail",IF(JZ4<5,""))))))))))
A5: 3 | B5: 3 | C5: =Data!B4 -> AMOS ANJILI STANLEY | D5: 2 | E5: 4 | F5: 6 | G5: 8 | H5: =SUM(D5:G5) -> 20 | I5: 21 | J5: =H5+I5 -> 41 | K5: =IF(J5<10,"",RANK(J5,J$3:J$52)) -> 44 | L5: =IF(J5>=75,"A1",IF(J5>=70,"B2",IF(J5>=65,"B3",IF(J5>=60,"C4",IF(J5>=55,"C5",IF(J5>=50,"C6",IF(J5>=45,"D7",IF(J5>=40,"E8",IF(J5>=6,"F",IF(J5<5,"")))))))))) -> E8 | M5: =IF(J5>=75,"Excellent",IF(J5>=70,"V.Good",IF(J5>=65,"Good",IF(J5>=60,"Credit",IF(J5>=55,"Credit",IF(J5>=50,"Credit",IF(J5>=45,"Pass",IF(J5>=40,"Pass",IF(J5>=6,"Fail",IF(J5<5,"")))))))))) -> Pass | N5: 3 | O5: =Data!B4 -> AMOS ANJILI STANLEY | T5: =SUM(P5:S5) -> 0 | V5: =T5+U5 -> 0 | W5: =IF(V5<10,"",RANK(V5,V$3:V$52)) | X5: =IF(V5>=75,"A1",IF(V5>=70,"B2",IF(V5>=65,"B3",IF(V5>=60,"C4",IF(V5>=55,"C5",IF(V5>=50,"C6",IF(V5>=45,"D7",IF(V5>=40,"E8",IF(V5>=6,"F",IF(V5<5,"")))))))))) | Y5: =IF(V5>=75,"Excellent",IF(V5>=70,"V.Good",IF(V5>=65,"Good",IF(V5>=60,"Credit",IF(V5>=55,"Credit",IF(V5>=50,"Credit",IF(V5>=45,"Pass",IF(V5>=40,"Pass",IF(V5>=6,"Fail",IF(V5<5,"")))))))))) | Z5: 3 | AA5: =Data!B4 -> AMOS ANJILI STANLEY | AB5: 2 | AC5: 4 | AD5: 6 | AE5: 8 | AF5: =SUM(AB5:AE5) -> 20 | AG5: 21 | AH5: =AF5+AG5 -> 41 | AI5: =IF(AH5<10,"",RANK(AH5,AH$3:AH$52)) -> 44 | AJ5: =IF(AH5>=75,"A1",IF(AH5>=70,"B2",IF(AH5>=65,"B3",IF(AH5>=60,"C4",IF(AH5>=55,"C5",IF(AH5>=50,"C6",IF(AH5>=45,"D7",IF(AH5>=40,"E8",IF(AH5>=6,"F",IF(AH5<5,"")))))))))) -> E8 | AK5: =IF(AH5>=75,"Excellent",IF(AH5>=70,"V.Good",IF(AH5>=65,"Good",IF(AH5>=60,"Credit",IF(AH5>=55,"Credit",IF(AH5>=50,"Credit",IF(AH5>=45,"Pass",IF(AH5>=40,"Pass",IF(AH5>=6,"Fail",IF(AH5<5,"")))))))))) -> Pass | AL5: 3 | AM5: =Data!B4 -> AMOS ANJILI STANLEY | AN5: 2 | AO5: 4 | AP5: 6 | AQ5: 8 | AR5: =SUM(AN5:AQ5) -> 20 | AS5: 21 | AT5: =AR5+AS5 -> 41 | AU5: =IF(AT5<10,"",RANK(AT5,AT$3:AT$52)) -> 44 | AV5: =IF(AT5>=75,"A1",IF(AT5>=70,"B2",IF(AT5>=65,"B3",IF(AT5>=60,"C4",IF(AT5>=55,"C5",IF(AT5>=50,"C6",IF(AT5>=45,"D7",IF(AT5>=40,"E8",IF(AT5>=6,"F",IF(AT5<5,"")))))))))) -> E8 | AW5: =IF(AT5>=75,"Excellent",IF(AT5>=70,"V.Good",IF(AT5>=65,"Good",IF(AT5>=60,"Credit",IF(AT5>=55,"Credit",IF(AT5>=50,"Credit",IF(AT5>=45,"Pass",IF(AT5>=40,"Pass",IF(AT5>=6,"Fail",IF(AT5<5,"")))))))))) -> Pass | AX5: 3 | AY5: =Data!B4 -> AMOS ANJILI STANLEY | AZ5: 2 | BA5: 4 | BB5: 6 | BC5: 8 | BD5: =SUM(AZ5:BC5) -> 20 | BE5: 21 | BF5: =BD5+BE5 -> 41 | BG5: =IF(BF5<10,"",RANK(BF5,BF$3:BF$52)) -> 44 | BH5: =IF(BF5>=75,"A1",IF(BF5>=70,"B2",IF(BF5>=65,"B3",IF(BF5>=60,"C4",IF(BF5>=55,"C5",IF(BF5>=50,"C6",IF(BF5>=45,"D7",IF(BF5>=40,"E8",IF(BF5>=6,"F",IF(BF5<5,"")))))))))) -> E8 | BI5: =IF(BF5>=75,"Excellent",IF(BF5>=70,"V.Good",IF(BF5>=65,"Good",IF(BF5>=60,"Credit",IF(BF5>=55,"Credit",IF(BF5>=50,"Credit",IF(BF5>=45,"Pass",IF(BF5>=40,"Pass",IF(BF5>=6,"Fail",IF(BF5<5,"")))))))))) -> Pass | BJ5: 3 | BK5: =Data!B4 -> AMOS ANJILI STANLEY | BL5: 2 | BM5: 4 | BN5: 6 | BO5: 8 | BP5: =SUM(BL5:BO5) -> 20 | BQ5: 21 | BR5: =BP5+BQ5 -> 41 | BS5: =IF(BR5<10,"",RANK(BR5,BR$3:BR$52)) -> 44 | BT5: =IF(BR5>=75,"A1",IF(BR5>=70,"B2",IF(BR5>=65,"B3",IF(BR5>=60,"C4",IF(BR5>=55,"C5",IF(BR5>=50,"C6",IF(BR5>=45,"D7",IF(BR5>=40,"E8",IF(BR5>=6,"F",IF(BR5<5,"")))))))))) -> E8 | BU5: =IF(BR5>=75,"Excellent",IF(BR5>=70,"V.Good",IF(BR5>=65,"Good",IF(BR5>=60,"Credit",IF(BR5>=55,"Credit",IF(BR5>=50,"Credit",IF(BR5>=45,"Pass",IF(BR5>=40,"Pass",IF(BR5>=6,"Fail",IF(BR5<5,"")))))))))) -> Pass | BV5: 3 | BW5: =Data!B4 -> AMOS ANJILI STANLEY | BX5: 2 | BY5: 4 | BZ5: 6 | CA5: 8 | CB5: =SUM(BX5:CA5) -> 20 | CC5: 21 | CD5: =CB5+CC5 -> 41 | CE5: =IF(CD5<10,"",RANK(CD5,CD$3:CD$52)) -> 44 | CF5: =IF(CD5>=75,"A1",IF(CD5>=70,"B2",IF(CD5>=65,"B3",IF(CD5>=60,"C4",IF(CD5>=55,"C5",IF(CD5>=50,"C6",IF(CD5>=45,"D7",IF(CD5>=40,"E8",IF(CD5>=6,"F",IF(CD5<5,"")))))))))) -> E8 | CG5: =IF(CD5>=75,"Excellent",IF(CD5>=70,"V.Good",IF(CD5>=65,"Good",IF(CD5>=60,"Credit",IF(CD5>=55,"Credit",IF(CD5>=50,"Credit",IF(CD5>=45,"Pass",IF(CD5>=40,"Pass",IF(CD5>=6,"Fail",IF(CD5<5,"")))))))))) -> Pass | CH5: 3 | CI5: =Data!B4 -> AMOS ANJILI STANLEY | CN5: =SUM(CJ5:CM5) -> 0 | CP5: =CN5+CO5 -> 0 | CQ5: =IF(CP5<10,"",RANK(CP5,CP$3:CP$52)) | CR5: =IF(CP5>=75,"A1",IF(CP5>=70,"B2",IF(CP5>=65,"B3",IF(CP5>=60,"C4",IF(CP5>=55,"C5",IF(CP5>=50,"C6",IF(CP5>=45,"D7",IF(CP5>=40,"E8",IF(CP5>=6,"F",IF(CP5<5,"")))))))))) | CS5: =IF(CP5>=75,"Excellent",IF(CP5>=70,"V.Good",IF(CP5>=65,"Good",IF(CP5>=60,"Credit",IF(CP5>=55,"Credit",IF(CP5>=50,"Credit",IF(CP5>=45,"Pass",IF(CP5>=40,"Pass",IF(CP5>=6,"Fail",IF(CP5<5,"")))))))))) | CT5: 3 | CU5: =Data!B4 -> AMOS ANJILI STANLEY | CZ5: =SUM(CV5:CY5) -> 0 | DB5: =CZ5+DA5 -> 0 | DC5: =IF(DB5<10,"",RANK(DB5,DB$3:DB$52)) | DD5: =IF(DB5>=75,"A1",IF(DB5>=70,"B2",IF(DB5>=65,"B3",IF(DB5>=60,"C4",IF(DB5>=55,"C5",IF(DB5>=50,"C6",IF(DB5>=45,"D7",IF(DB5>=40,"E8",IF(DB5>=6,"F",IF(DB5<5,"")))))))))) | DE5: =IF(DB5>=75,"Excellent",IF(DB5>=70,"V.Good",IF(DB5>=65,"Good",IF(DB5>=60,"Credit",IF(DB5>=55,"Credit",IF(DB5>=50,"Credit",IF(DB5>=45,"Pass",IF(DB5>=40,"Pass",IF(DB5>=6,"Fail",IF(DB5<5,"")))))))))) | DF5: 3 | DG5: =Data!B4 -> AMOS ANJILI STANLEY | DL5: =SUM(DH5:DK5) -> 0 | DN5: =DL5+DM5 -> 0 | DO5: =IF(DN5<10,"",RANK(DN5,DN$3:DN$52)) | DP5: =IF(DN5>=75,"A1",IF(DN5>=70,"B2",IF(DN5>=65,"B3",IF(DN5>=60,"C4",IF(DN5>=55,"C5",IF(DN5>=50,"C6",IF(DN5>=45,"D7",IF(DN5>=40,"E8",IF(DN5>=6,"F",IF(DN5<5,"")))))))))) | DQ5: =IF(DN5>=75,"Excellent",IF(DN5>=70,"V.Good",IF(DN5>=65,"Good",IF(DN5>=60,"Credit",IF(DN5>=55,"Credit",IF(DN5>=50,"Credit",IF(DN5>=45,"Pass",IF(DN5>=40,"Pass",IF(DN5>=6,"Fail",IF(DN5<5,"")))))))))) | DR5: 3 | DS5: =Data!B4 -> AMOS ANJILI STANLEY | DX5: =SUM(DT5:DW5) -> 0 | DZ5: =DX5+DY5 -> 0 | EA5: =IF(DZ5<10,"",RANK(DZ5,DZ$3:DZ$52)) | EB5: =IF(DZ5>=75,"A1",IF(DZ5>=70,"B2",IF(DZ5>=65,"B3",IF(DZ5>=60,"C4",IF(DZ5>=55,"C5",IF(DZ5>=50,"C6",IF(DZ5>=45,"D7",IF(DZ5>=40,"E8",IF(DZ5>=6,"F",IF(DZ5<5,"")))))))))) | EC5: =IF(DZ5>=75,"Excellent",IF(DZ5>=70,"V.Good",IF(DZ5>=65,"Good",IF(DZ5>=60,"Credit",IF(DZ5>=55,"Credit",IF(DZ5>=50,"Credit",IF(DZ5>=45,"Pass",IF(DZ5>=40,"Pass",IF(DZ5>=6,"Fail",IF(DZ5<5,"")))))))))) | ED5: 3 | EE5: =Data!B4 -> AMOS ANJILI STANLEY | EJ5: =SUM(EF5:EI5) -> 0 | EL5: =EJ5+EK5 -> 0 | EM5: =IF(EL5<10,"",RANK(EL5,EL$3:EL$52)) | EN5: =IF(EL5>=75,"A1",IF(EL5>=70,"B2",IF(EL5>=65,"B3",IF(EL5>=60,"C4",IF(EL5>=55,"C5",IF(EL5>=50,"C6",IF(EL5>=45,"D7",IF(EL5>=40,"E8",IF(EL5>=6,"F",IF(EL5<5,"")))))))))) | EO5: =IF(EL5>=75,"Excellent",IF(EL5>=70,"V.Good",IF(EL5>=65,"Good",IF(EL5>=60,"Credit",IF(EL5>=55,"Credit",IF(EL5>=50,"Credit",IF(EL5>=45,"Pass",IF(EL5>=40,"Pass",IF(EL5>=6,"Fail",IF(EL5<5,"")))))))))) | EP5: 3 | EQ5: =Data!B4 -> AMOS ANJILI STANLEY | EV5: =SUM(ER5:EU5) -> 0 | EX5: =EV5+EW5 -> 0 | EY5: =IF(EX5<10,"",RANK(EX5,EX$3:EX$52)) | EZ5: =IF(EX5>=75,"A1",IF(EX5>=70,"B2",IF(EX5>=65,"B3",IF(EX5>=60,"C4",IF(EX5>=55,"C5",IF(EX5>=50,"C6",IF(EX5>=45,"D7",IF(EX5>=40,"E8",IF(EX5>=6,"F",IF(EX5<5,"")))))))))) | FA5: =IF(EX5>=75,"Excellent",IF(EX5>=70,"V.Good",IF(EX5>=65,"Good",IF(EX5>=60,"Credit",IF(EX5>=55,"Credit",IF(EX5>=50,"Credit",IF(EX5>=45,"Pass",IF(EX5>=40,"Pass",IF(EX5>=6,"Fail",IF(EX5<5,"")))))))))) | FB5: 3 | FC5: =Data!B4 -> AMOS ANJILI STANLEY | FH5: =SUM(FD5:FG5) -> 0 | FJ5: =FH5+FI5 -> 0 | FK5: =IF(FJ5<10,"",RANK(FJ5,FJ$3:FJ$52)) | FL5: =IF(FJ5>=75,"A",IF(FJ5>=70,"B2",IF(FJ5>=50,"C",IF(FJ5>=45,"D",IF(FJ5>=40,"E",IF(FJ5>=6,"F",IF(FJ5<5,""))))))) | FM5: =IF(FJ5>=75,"Excellent",IF(FJ5>=70,"V.Good",IF(FJ5>=65,"Good",IF(FJ5>=60,"Credit",IF(FJ5>=55,"Credit",IF(FJ5>=50,"Credit",IF(FJ5>=45,"Pass",IF(FJ5>=40,"Pass",IF(FJ5>=6,"Fail",IF(FJ5<5,"")))))))))) | FN5: 3 | FO5: =Data!B4 -> AMOS ANJILI STANLEY | FT5: =SUM(FP5:FS5) -> 0 | FV5: =FT5+FU5 -> 0 | FW5: =IF(FV5<10,"",RANK(FV5,FV$3:FV$52)) | FX5: =IF(FV5>=75,"A",IF(FV5>=70,"B2",IF(FV5>=50,"C",IF(FV5>=45,"D",IF(FV5>=40,"E",IF(FV5>=6,"F",IF(FV5<5,""))))))) | FY5: =IF(FV5>=75,"Excellent",IF(FV5>=70,"V.Good",IF(FV5>=65,"Good",IF(FV5>=60,"Credit",IF(FV5>=55,"Credit",IF(FV5>=50,"Credit",IF(FV5>=45,"Pass",IF(FV5>=40,"Pass",IF(FV5>=6,"Fail",IF(FV5<5,"")))))))))) | FZ5: 3 | GA5: =Data!B4 -> AMOS ANJILI STANLEY | GF5: =SUM(GB5:GE5) -> 0 | GH5: =GF5+GG5 -> 0 | GI5: =IF(GH5<10,"",RANK(GH5,GH$3:GH$52)) | GJ5: =IF(GH5>=75,"A",IF(GH5>=70,"B2",IF(GH5>=50,"C",IF(GH5>=45,"D",IF(GH5>=40,"E",IF(GH5>=6,"F",IF(GH5<5,""))))))) | GK5: =IF(GH5>=75,"Excellent",IF(GH5>=70,"V.Good",IF(GH5>=65,"Good",IF(GH5>=60,"Credit",IF(GH5>=55,"Credit",IF(GH5>=50,"Credit",IF(GH5>=45,"Pass",IF(GH5>=40,"Pass",IF(GH5>=6,"Fail",IF(GH5<5,"")))))))))) | GL5: 3 | GM5: =Data!B4 -> AMOS ANJILI STANLEY | GR5: =SUM(GN5:GQ5) -> 0 | GT5: =GR5+GS5 -> 0 | GU5: =IF(GT5<10,"",RANK(GT5,GT$3:GT$52)) | GV5: =IF(GT5>=75,"A",IF(GT5>=70,"B2",IF(GT5>=50,"C",IF(GT5>=45,"D",IF(GT5>=40,"E",IF(GT5>=6,"F",IF(GT5<5,""))))))) | GW5: =IF(GT5>=75,"Excellent",IF(GT5>=70,"V.Good",IF(GT5>=65,"Good",IF(GT5>=60,"Credit",IF(GT5>=55,"Credit",IF(GT5>=50,"Credit",IF(GT5>=45,"Pass",IF(GT5>=40,"Pass",IF(GT5>=6,"Fail",IF(GT5<5,"")))))))))) | GX5: 3 | GY5: =Data!B4 -> AMOS ANJILI STANLEY | HD5: =SUM(GZ5:HC5) -> 0 | HF5: =HD5+HE5 -> 0 | HG5: =IF(HF5<10,"",RANK(HF5,HF$3:HF$52)) | HH5: =IF(HF5>=75,"A",IF(HF5>=70,"B2",IF(HF5>=50,"C",IF(HF5>=45,"D",IF(HF5>=40,"E",IF(HF5>=6,"F",IF(HF5<5,""))))))) | HI5: =IF(HF5>=75,"Excellent",IF(HF5>=70,"V.Good",IF(HF5>=65,"Good",IF(HF5>=60,"Credit",IF(HF5>=55,"Credit",IF(HF5>=50,"Credit",IF(HF5>=45,"Pass",IF(HF5>=40,"Pass",IF(HF5>=6,"Fail",IF(HF5<5,"")))))))))) | HJ5: 3 | HK5: =Data!B4 -> AMOS ANJILI STANLEY | HP5: =SUM(HL5:HO5) -> 0 | HR5: =HP5+HQ5 -> 0 | HS5: =IF(HR5<10,"",RANK(HR5,HR$3:HR$52)) | HT5: =IF(HR5>=75,"A",IF(HR5>=70,"B2",IF(HR5>=50,"C",IF(HR5>=45,"D",IF(HR5>=40,"E",IF(HR5>=6,"F",IF(HR5<5,""))))))) | HU5: =IF(HR5>=75,"Excellent",IF(HR5>=70,"V.Good",IF(HR5>=65,"Good",IF(HR5>=60,"Credit",IF(HR5>=55,"Credit",IF(HR5>=50,"Credit",IF(HR5>=45,"Pass",IF(HR5>=40,"Pass",IF(HR5>=6,"Fail",IF(HR5<5,"")))))))))) | HV5: 3 | HW5: =Data!B4 -> AMOS ANJILI STANLEY | IB5: =SUM(HX5:IA5) -> 0 | ID5: =IB5+IC5 -> 0 | IE5: =IF(ID5<10,"",RANK(ID5,ID$3:ID$52)) | IF5: =IF(ID5>=75,"A",IF(ID5>=70,"B2",IF(ID5>=50,"C",IF(ID5>=45,"D",IF(ID5>=40,"E",IF(ID5>=6,"F",IF(ID5<5,""))))))) | IG5: =IF(ID5>=75,"Excellent",IF(ID5>=70,"V.Good",IF(ID5>=65,"Good",IF(ID5>=60,"Credit",IF(ID5>=55,"Credit",IF(ID5>=50,"Credit",IF(ID5>=45,"Pass",IF(ID5>=40,"Pass",IF(ID5>=6,"Fail",IF(ID5<5,"")))))))))) | IH5: 3 | II5: =Data!B4 -> AMOS ANJILI STANLEY | IN5: =SUM(IJ5:IM5) -> 0 | IP5: =IN5+IO5 -> 0 | IQ5: =IF(IP5<10,"",RANK(IP5,IP$3:IP$52)) | IR5: =IF(IP5>=75,"A",IF(IP5>=70,"B2",IF(IP5>=50,"C",IF(IP5>=45,"D",IF(IP5>=40,"E",IF(IP5>=6,"F",IF(IP5<5,""))))))) | IS5: =IF(IP5>=75,"Excellent",IF(IP5>=70,"V.Good",IF(IP5>=65,"Good",IF(IP5>=60,"Credit",IF(IP5>=55,"Credit",IF(IP5>=50,"Credit",IF(IP5>=45,"Pass",IF(IP5>=40,"Pass",IF(IP5>=6,"Fail",IF(IP5<5,"")))))))))) | IT5: 3 | IU5: =II5 -> AMOS ANJILI STANLEY | IZ5: =SUM(IV5:IY5) -> 0 | JB5: =IZ5+JA5 -> 0 | JC5: =IF(JB5<10,"",RANK(JB5,JB$3:JB$52)) | JD5: =IF(JB5>=75,"A",IF(JB5>=70,"B2",IF(JB5>=50,"C",IF(JB5>=45,"D",IF(JB5>=40,"E",IF(JB5>=6,"F",IF(JB5<5,""))))))) | JE5: =IF(JB5>=75,"Excellent",IF(JB5>=70,"V.Good",IF(JB5>=65,"Good",IF(JB5>=60,"Credit",IF(JB5>=55,"Credit",IF(JB5>=50,"Credit",IF(JB5>=45,"Pass",IF(JB5>=40,"Pass",IF(JB5>=6,"Fail",IF(JB5<5,"")))))))))) | JF5: 3 | JG5: =IU5 -> AMOS ANJILI STANLEY | JL5: =SUM(JH5:JK5) -> 0 | JN5: =JL5+JM5 -> 0 | JO5: =IF(JN5<10,"",RANK(JN5,JN$3:JN$52)) | JP5: =IF(JN5>=75,"A",IF(JN5>=70,"B2",IF(JN5>=50,"C",IF(JN5>=45,"D",IF(JN5>=40,"E",IF(JN5>=6,"F",IF(JN5<5,""))))))) | JQ5: =IF(JN5>=75,"Excellent",IF(JN5>=70,"V.Good",IF(JN5>=65,"Good",IF(JN5>=60,"Credit",IF(JN5>=55,"Credit",IF(JN5>=50,"Credit",IF(JN5>=45,"Pass",IF(JN5>=40,"Pass",IF(JN5>=6,"Fail",IF(JN5<5,"")))))))))) | JR5: 3 | JS5: =JG5 -> AMOS ANJILI STANLEY | JX5: =SUM(JT5:JW5) -> 0 | JZ5: =JX5+JY5 -> 0 | KA5: =IF(JZ5<10,"",RANK(JZ5,JZ$3:JZ$52)) | KB5: =IF(JZ5>=75,"A",IF(JZ5>=70,"B2",IF(JZ5>=50,"C",IF(JZ5>=45,"D",IF(JZ5>=40,"E",IF(JZ5>=6,"F",IF(JZ5<5,""))))))) | KC5: =IF(JZ5>=75,"Excellent",IF(JZ5>=70,"V.Good",IF(JZ5>=65,"Good",IF(JZ5>=60,"Credit",IF(JZ5>=55,"Credit",IF(JZ5>=50,"Credit",IF(JZ5>=45,"Pass",IF(JZ5>=40,"Pass",IF(JZ5>=6,"Fail",IF(JZ5<5,""))))))))))
