Workbook

Sheet Data
A1: Admission_No | B1: Name | C1: Class | D1: State of Origin | E1: Age | F1: LGA | G1: Term | H1: Next Term Begins | I1: Password | J1: Email
A2: 1 | B2: ALI AHMED ASHEMI | C2: SS 1F | G2: 1 st | H2: 16th January, 2026 | I2: 1234 | J2: adamusman781@gmail.com
A3: 2 | B3: ALHAJI MUSTAPHA ABUBAKAR | C3: SS 1F | G3: 1 st | H3: 16th January, 2026 | I3: 1234 | J3: adamusman781@gmail.com
A4: 3 | B4: ALI MUHAMMED UMAR | C4: SS 1F | G4: 1 st | H4: 16th January, 2026 | I4: 1234 | J4: adamusman781@gmail.com
A5: 4 | B5: ADAM UMAR LAMINU | C5: SS 1F | G5: 1 st | H5: 16th January, 2026 | I5: 1234 | J5: adamusman781@gmail.com
A6: 5 | B6: ABUBAKAR UMAR | C6: SS 1F | G6: 1 st | H6: 16th January, 2026 | I6: 1234 | J6: adamusman781@gmail.com
A7: 6 | B7: BABAGANA ISA ABBA | C7: SS 1F | G7: 1 st | H7: 16th January, 2026 | I7: 1234 | J7: adamusman781@gmail.com
A8: 7 | B8: BABASHEHU ABDULLAHI | C8: SS 1F | G8: 1 st | H8: 16th January, 2026 | I8: 1234 | J8: adamusman781@gmail.com
A9: 8 | B9: BUKAR MUHAMMED GAMBO | C9: SS 1F | G9: 1 st | H9: 16th January, 2026 | I9: 1234 | J9: adamusman781@gmail.com
A10: 9 | B10: ELKANAH DANIEL KAIGAMA | C10: SS 1F | G10: 1 st | H10: 16th January, 2026 | I10: 1234 | J10: adamusman781@gmail.com
A11: 10 | B11: GANA ABUBAKAR ALHAJ | C11: SS 1F | G11: 1 st | H11: 16th January, 2026 | I11: 1234 | J11: adamusman781@gmail.com
A12: 11 | B12: IBRAHIM HASSAN HELMA | C12: SS 1F | G12: 1 st | H12: 16th January, 2026 | I12: 1234 | J12: adamusman781@gmail.com
A13: 12 | B13: MODUYE ALI | C13: SS 1F | G13: 1 st | H13: 16th January, 2026 | I13: 1234 | J13: adamusman781@gmail.com
... A24: 23 | B24: WIZIRI UMAR KINIDI | C24: SS 1F | G24: 1 st | H24: 16th January, 2026 | I24: 1234 | J24: adamusman781@gmail.com
A25: 24 | C25: SS 1F | G25: 1 st | H25: 16th January, 2026 | I25: 1234 | J25: adamusman781@gmail.com
A26: 25 | C26: SS 1F | G26: 1 st | H26: 16th January, 2026 | I26: 1234 | J26: adamusman781@gmail.com
A27: 26 | C27: SS 1F | G27: 1 st | H27: 16th January, 2026 | I27: 1234 | J27: adamusman781@gmail.com
A28: 27 | C28: SS 1F | G28: 1 st | H28: 16th January, 2026 | I28: 1234 | J28: adamusman781@gmail.com
A29: 28 | C29: SS 1F | G29: 1 st | H29: 16th January, 2026 | I29: 1234 | J29: adamusman781@gmail.com
A30: 29 | B30: ALI AALIYA SHEHU | C30: SS 1F | G30: 1 st | H30: 16th January, 2026 | I30: 1234 | J30: adamusman781@gmail.com
A31: 30 | B31: AUDU FATIMA ADO | C31: SS 1F | G31: 1 st | H31: 16th January, 2026 | I31: 1234 | J31: adamusman781@gmail.com
A32: 31 | B32: ABBA FATIMA KYARI | C32: SS 1F | G32: 1 st | H32: 16th January, 2026 | I32: 1234 | J32: adamusman781@gmail.com
A33: 32 | B33: AHMED FATIMA JIME | C33: SS 1F | G33: 1 st | H33: 16th January, 2026 | I33: 1234 | J33: adamusman781@gmail.com
A34: 33 | B34: ADAMU HASAT ISAH | C34: SS 1F | G34: 1 st | H34: 16th January, 2026 | I34: 1234 | J34: adamusman781@gmail.com
A35: 34 | B35: BABAGANA AISHA ARFO | C35: SS 1F | G35: 1 st | H35: 16th January, 2026 | I35: 1234 | J35: adamusman781@gmail.com
A36: 35 | B36: BABA AMINA ZANNAH | C36: SS 1F | G36: 1 st | H36: 16th January, 2026 | I36: 1234 | J36: adamusman781@gmail.com
A37: 36 | B37: BUKAR FATIMAH ALLAU | C37: SS 1F | G37: 1 st | H37: 16th January, 2026 | I37: 1234 | J37: adamusman781@gmail.com
A38: 37 | B38: BABAGANA FATIMA KARUMI | C38: SS 1F | G38: 1 st | H38: 16th January, 2026 | I38: 1234 | J38: adamusman781@gmail.com
A39: 38 | B39: HARUNA RUTH AFFIKU | C39: SS 1F | G39: 1 st | H39: 16th January, 2026 | I39: 1234 | J39: adamusman781@gmail.com
A40: 39 | B40: HABILA ROSE | C40: SS 1F | G40: 1 st | H40: 16th January, 2026 | I40: 1234 | J40: adamusman781@gmail.com
A41: 40 | B41: IBRAHIM HADIZA ABUBAKAR | C41: SS 1F | G41: 1 st | H41: 16th January, 2026 | I41: 1234 | J41: adamusman781@gmail.com
... A48: 47 | B48: TAHA AMINA | C48: SS 1F | G48: 1 st | H48: 16th January, 2026 | I48: 1234 | J48: adamusman781@gmail.com
A49: 48 | B49: UMAR ZAINAB ZARMA | C49: SS 1F | G49: 1 st | H49: 16th January, 2026 | I49: 1234
A50: 49 | B50: ZANNA ZARA MUSTAPHA | C50: SS 1F | G50: 1 st | H50: 16th January, 2026 | I50: 1234
A51: 50 | B51: ZUBAIRU KHADIJA H ALIN | C51: SS 1F | G51: 1 st | H51: 16th January, 2026 | I51: 1234
C52: SS 1F | G52: 1 st
C53: SS 1F | G53: 1 st
C54: SS 1F | G54: 1 st
C55: SS 1F | G55: 1 st

Sheet T  Score
B1: Ruby Springfield College 1st Term Scoresheet
B2: SUBJECT | C2: Class SS 1A | H2: Teacher
A3: S/N | B3: Names | C3: 1st C. A. | D3: 2st C. A. | E3: 3st C. A. | F3: 4st C. A. | G3: Total C. A. | H3: Exam | I3: Total | J3: Position | K3: Grade | L3: Teacher's Comment
A4: 1 | B4: =Data!B2 -> ALI AHMED ASHEMI | G4: =SUM(C4:F4) -> 0 | I4: =G4+H4 -> 0 | J4: =IF(I4<10,"",RANK(I4,I$4:I$53)) | K4: =IF(I4>=75,"A",IF(I4>=70,"B2",IF(I4>=50,"C",IF(I4>=45,"D",IF(I4>=40,"E",IF(I4>=6,"F",IF(I4<5,""))))))) | L4: =IF(I4>=75,"Excellent",IF(I4>=70,"V.Good",IF(I4>=65,"Good",IF(I4>=60,"Credit",IF(I4>=55,"Credit",IF(I4>=50,"Credit",IF(I4>=45,"Pass",IF(I4>=40,"Pass",IF(I4>=6,"Fail",IF(I4<5,""))))))))))
A5: 2 | B5: =Data!B3 -> ALHAJI MUSTAPHA ABUBAKAR | G5: =SUM(C5:F5) -> 0 | I5: =G5+H5 -> 0 | J5: =IF(I5<10,"",RANK(I5,I$4:I$53)) | K5: =IF(I5>=75,"A",IF(I5>=70,"B2",IF(I5>=50,"C",IF(I5>=45,"D",IF(I5>=40,"E",IF(I5>=6,"F",IF(I5<5,""))))))) | L5: =IF(I5>=75,"Excellent",IF(I5>=70,"V.Good",IF(I5>=65,"Good",IF(I5>=60,"Credit",IF(I5>=55,"Credit",IF(I5>=50,"Credit",IF(I5>=45,"Pass",IF(I5>=40,"Pass",IF(I5>=6,"Fail",IF(I5<5,""))))))))))
A6: 3 | B6: =Data!B4 -> ALI MUHAMMED UMAR | G6: =SUM(C6:F6) -> 0 | I6: =G6+H6 -> 0 | J6: =IF(I6<10,"",RANK(I6,I$4:I$53)) | K6: =IF(I6>=75,"A",IF(I6>=70,"B2",IF(I6>=50,"C",IF(I6>=45,"D",IF(I6>=40,"E",IF(I6>=6,"F",IF(I6<5,""))))))) | L6: =IF(I6>=75,"Excellent",IF(I6>=70,"V.Good",IF(I6>=65,"Good",IF(I6>=60,"Credit",IF(I6>=55,"Credit",IF(I6>=50,"Credit",IF(I6>=45,"Pass",IF(I6>=40,"Pass",IF(I6>=6,"Fail",IF(I6<5,""))))))))))
A7: 4 | B7: =Data!B5 -> ADAM UMAR LAMINU | G7: =SUM(C7:F7) -> 0 | I7: =G7+H7 -> 0 | J7: =IF(I7<10,"",RANK(I7,I$4:I$53)) | K7: =IF(I7>=75,"A",IF(I7>=70,"B2",IF(I7>=50,"C",IF(I7>=45,"D",IF(I7>=40,"E",IF(I7>=6,"F",IF(I7<5,""))))))) | L7: =IF(I7>=75,"Excellent",IF(I7>=70,"V.Good",IF(I7>=65,"Good",IF(I7>=60,"Credit",IF(I7>=55,"Credit",IF(I7>=50,"Credit",IF(I7>=45,"Pass",IF(I7>=40,"Pass",IF(I7>=6,"Fail",IF(I7<5,""))))))))))
A8: 5 | B8: =Data!B6 -> ABUBAKAR UMAR | G8: =SUM(C8:F8) -> 0 | I8: =G8+H8 -> 0 | J8: =IF(I8<10,"",RANK(I8,I$4:I$53)) | K8: =IF(I8>=75,"A",IF(I8>=70,"B2",IF(I8>=50,"C",IF(I8>=45,"D",IF(I8>=40,"E",IF(I8>=6,"F",IF(I8<5,""))))))) | L8: =IF(I8>=75,"Excellent",IF(I8>=70,"V.Good",IF(I8>=65,"Good",IF(I8>=60,"Credit",IF(I8>=55,"Credit",IF(I8>=50,"Credit",IF(I8>=45,"Pass",IF(I8>=40,"Pass",IF(I8>=6,"Fail",IF(I8<5,""))))))))))
A9: 6 | B9: =Data!B7 -> BABAGANA ISA ABBA | G9: =SUM(C9:F9) -> 0 | I9: =G9+H9 -> 0 | J9: =IF(I9<10,"",RANK(I9,I$4:I$53)) | K9: =IF(I9>=75,"A",IF(I9>=70,"B2",IF(I9>=50,"C",IF(I9>=45,"D",IF(I9>=40,"E",IF(I9>=6,"F",IF(I9<5,""))))))) | L9: =IF(I9>=75,"Excellent",IF(I9>=70,"V.Good",IF(I9>=65,"Good",IF(I9>=60,"Credit",IF(I9>=55,"Credit",IF(I9>=50,"Credit",IF(I9>=45,"Pass",IF(I9>=40,"Pass",IF(I9>=6,"Fail",IF(I9<5,""))))))))))
A10: 7 | B10: =Data!B8 -> BABASHEHU ABDULLAHI | G10: =SUM(C10:F10) -> 0 | I10: =G10+H10 -> 0 | J10: =IF(I10<10,"",RANK(I10,I$4:I$53)) | K10: =IF(I10>=75,"A",IF(I10>=70,"B2",IF(I10>=50,"C",IF(I10>=45,"D",IF(I10>=40,"E",IF(I10>=6,"F",IF(I10<5,""))))))) | L10: =IF(I10>=75,"Excellent",IF(I10>=70,"V.Good",IF(I10>=65,"Good",IF(I10>=60,"Credit",IF(I10>=55,"Credit",IF(I10>=50,"Credit",IF(I10>=45,"Pass",IF(I10>=40,"Pass",IF(I10>=6,"Fail",IF(I10<5,""))))))))))
A11: 8 | B11: =Data!B9 -> BUKAR MUHAMMED GAMBO | G11: =SUM(C11:F11) -> 0 | I11: =G11+H11 -> 0 | J11: =IF(I11<10,"",RANK(I11,I$4:I$53)) | K11: =IF(I11>=75,"A",IF(I11>=70,"B2",IF(I11>=50,"C",IF(I11>=45,"D",IF(I11>=40,"E",IF(I11>=6,"F",IF(I11<5,""))))))) | L11: =IF(I11>=75,"Excellent",IF(I11>=70,"V.Good",IF(I11>=65,"Good",IF(I11>=60,"Credit",IF(I11>=55,"Credit",IF(I11>=50,"Credit",IF(I11>=45,"Pass",IF(I11>=40,"Pass",IF(I11>=6,"Fail",IF(I11<5,""))))))))))
A12: 9 | B12: =Data!B10 -> ELKANAH DANIEL KAIGAMA | G12: =SUM(C12:F12) -> 0 | I12: =G12+H12 -> 0 | J12: =IF(I12<10,"",RANK(I12,I$4:I$53)) | K12: =IF(I12>=75,"A",IF(I12>=70,"B2",IF(I12>=50,"C",IF(I12>=45,"D",IF(I12>=40,"E",IF(I12>=6,"F",IF(I12<5,""))))))) | L12: =IF(I12>=75,"Excellent",IF(I12>=70,"V.Good",IF(I12>=65,"Good",IF(I12>=60,"Credit",IF(I12>=55,"Credit",IF(I12>=50,"Credit",IF(I12>=45,"Pass",IF(I12>=40,"Pass",IF(I12>=6,"Fail",IF(I12<5,""))))))))))
A13: 10 | B13: =Data!B11 -> GANA ABUBAKAR ALHAJ | G13: =SUM(C13:F13) -> 0 | I13: =G13+H13 -> 0 | J13: =IF(I13<10,"",RANK(I13,I$4:I$53)) | K13: =IF(I13>=75,"A",IF(I13>=70,"B2",IF(I13>=50,"C",IF(I13>=45,"D",IF(I13>=40,"E",IF(I13>=6,"F",IF(I13<5,""))))))) | L13: =IF(I13>=75,"Excellent",IF(I13>=70,"V.Good",IF(I13>=65,"Good",IF(I13>=60,"Credit",IF(I13>=55,"Credit",IF(I13>=50,"Credit",IF(I13>=45,"Pass",IF(I13>=40,"Pass",IF(I13>=6,"Fail",IF(I13<5,""))))))))))
A14: 11 | B14: =Data!B12 -> IBRAHIM HASSAN HELMA | G14: =SUM(C14:F14) -> 0 | I14: =G14+H14 -> 0 | J14: =IF(I14<10,"",RANK(I14,I$4:I$53)) | K14: =IF(I14>=75,"A",IF(I14>=70,"B2",IF(I14>=50,"C",IF(I14>=45,"D",IF(I14>=40,"E",IF(I14>=6,"F",IF(I14<5,""))))))) | L14: =IF(I14>=75,"Excellent",IF(I14>=70,"V.Good",IF(I14>=65,"Good",IF(I14>=60,"Credit",IF(I14>=55,"Credit",IF(I14>=50,"Credit",IF(I14>=45,"Pass",IF(I14>=40,"Pass",IF(I14>=6,"Fail",IF(I14<5,""))))))))))
A15: 12 | B15: =Data!B13 -> MODUYE ALI | G15: =SUM(C15:F15) -> 0 | I15: =G15+H15 -> 0 | J15: =IF(I15<10,"",RANK(I15,I$4:I$53)) | K15: =IF(I15>=75,"A",IF(I15>=70,"B2",IF(I15>=50,"C",IF(I15>=45,"D",IF(I15>=40,"E",IF(I15>=6,"F",IF(I15<5,""))))))) | L15: =IF(I15>=75,"Excellent",IF(I15>=70,"V.Good",IF(I15>=65,"Good",IF(I15>=60,"Credit",IF(I15>=55,"Credit",IF(I15>=50,"Credit",IF(I15>=45,"Pass",IF(I15>=40,"Pass",IF(I15>=6,"Fail",IF(I15<5,""))))))))))
... A53: 50 | B53: =Data!B51 -> ZUBAIRU KHADIJA H ALIN | G53: =SUM(C53:F53) -> 0 | I53: =G53+H53 -> 0 | J53: =IF(I53<10,"",RANK(I53,I$4:I$53)) | K53: =IF(I53>=75,"A",IF(I53>=70,"B2",IF(I53>=50,"C",IF(I53>=45,"D",IF(I53>=40,"E",IF(I53>=6,"F",IF(I53<5,""))))))) | L53: =IF(I53>=75,"Excellent",IF(I53>=70,"V.Good",IF(I53>=65,"Good",IF(I53>=60,"Credit",IF(I53>=55,"Credit",IF(I53>=50,"Credit",IF(I53>=45,"Pass",IF(I53>=40,"Pass",IF(I53>=6,"Fail",IF(I53<5,""))))))))))

Sheet Comments
A1: Admission_No | B1: Comments | C1: Position of authourity
A2: 1 | B2: Calm and obedient | C2: Nil
A3: 2 | B3: Calm and obedient | C3: Nil
A4: 3 | B4: Calm and obedient | C4: Nil
A5: 4 | B5: Calm and obedient | C5: Nil
A6: 5 | B6: Calm and obedient | C6: Nil
A7: 6 | B7: Calm and obedient | C7: Nil
A8: 7 | B8: Calm and obedient | C8: Nil
A9: 8 | B9: Calm and obedient | C9: Nil
A10: 9 | B10: Calm and obedient | C10: Nil
A11: 10 | B11: Calm and obedient | C11: Nil
A12: 11 | B12: Calm and obedient | C12: Nil
A13: 12 | B13: Relates well with classmates | C13: Nil
... A51: 50 | B51: Relates well with classmates | C51: Nil

Sheet Behaviour
A1: Admission_No | B1: Puntuality | C1: Attendance in class | D1: Neatness | E1: Politeness | F1: Honesty | G1: Attentiveness | H1: Obedience | I1: Self Control
A2: 1 | B2: 4 | C2: 5 | D2: 4 | E2: 4 | F2: 4 | G2: 4 | H2: 4 | I2: 4
A3: 2 | B3: 4 | C3: 4 | D3: 4 | E3: 4 | F3: 3 | G3: 4 | H3: 4 | I3: 4
A4: 3 | B4: 3 | C4: 3 | D4: 4 | E4: 4 | F4: 4 | G4: 4 | H4: 4 | I4: 4
A5: 4 | B5: 4 | C5: 5 | D5: 4 | E5: 4 | F5: 4 | G5: 4 | H5: 4 | I5: 5
A6: 5 | B6: 4 | C6: 5 | D6: 4 | E6: 4 | F6: 4 | G6: 4 | H6: 4 | I6: 4
A7: 6 | B7: 4 | C7: 5 | D7: 3 | E7: 4 | F7: 4 | G7: 4 | H7: 4 | I7: 3
A8: 7 | B8: 3 | C8: 3 | D8: 4 | E8: 4 | F8: 4 | G8: 4 | H8: 4 | I8: 4
A9: 8 | B9: 3 | C9: 3 | D9: 4 | E9: 4 | F9: 4 | G9: 4 | H9: 4 | I9: 4
A10: 9 | B10: 4 | C10: 3 | D10: 4 | E10: 4 | F10: 4 | G10: 4 | H10: 4 | I10: 4
A11: 10 | B11: 4 | C11: 5 | D11: 3 | E11: 3 | F11: 2 | G11: 4 | H11: 2 | I11: 4
A12: 11 | B12: 4 | C12: 4 | D12: 4 | E12: 4 | F12: 3 | G12: 4 | H12: 4 | I12: 4
A13: 12 | B13: 4 | C13: 4 | D13: 4 | E13: 4 | F13: 4 | G13: 4 | H13: 3 | I13: 4
... A51: 50 | B51: 4 | C51: 5 | D51: 3 | E51: 3 | F51: 2 | G51: 4 | H51: 2 | I51: 4
B52: 4 | C52: 5 | D52: 3 | E52: 3 | F52: 2 | G52: 4 | H52: 2 | I52: 4
B53: 4 | C53: 5 | D53: 3 | E53: 3 | F53: 2 | G53: 4 | H53: 2 | I53: 4
B54: 4 | C54: 5 | D54: 3 | E54: 3 | F54: 2 | G54: 4 | H54: 2 | I54: 4

Sheet Skills
A1: Admission_No | B1: Handwriting | C1: Musical Skill | D1: Craft | E1: Games | F1: Fluency
A2: 1 | B2: 4 | C2: 4 | D2: 4 | E2: 4 | F2: 4
A3: 2 | B3: 3 | C3: 3 | D3: 3 | E3: 4 | F3: 4
A4: 3 | B4: 3 | C4: 4 | D4: 3 | E4: 4 | F4: 4
A5: 4 | B5: 4 | C5: 3 | D5: 4 | E5: 3 | F5: 3
A6: 5 | B6: 3 | C6: 3 | D6: 3 | E6: 3 | F6: 3
A7: 6 | B7: 3 | C7: 4 | D7: 4 | E7: 4 | F7: 4
A8: 7 | B8: 4 | C8: 3 | D8: 3 | E8: 3 | F8: 4
A9: 8 | B9: 4 | C9: 3 | D9: 4 | E9: 4 | F9: 3
A10: 9 | B10: 3 | C10: 3 | D10: 3 | E10: 5 | F10: 3
A11: 10 | B11: 4 | C11: 4 | D11: 3 | E11: 3 | F11: 3
A12: 11 | B12: 3 | C12: 3 | D12: 3 | E12: 4 | F12: 3
A13: 12 | B13: 4 | C13: 4 | D13: 4 | E13: 5 | F13: 4
... A51: 50 | B51: 4 | C51: 3 | D51: 3 | E51: 5 | F51: 3

Sheet Scoresheet
A1: 1 | B1: 2 | C1: 3 | D1: 4 | E1: 5 | F1: 6 | G1: 7 | H1: 8 | I1: 9 | J1: 11 | O1: 1 | P1: 2 | Q1: 3 | R1: 4 | S1: 5 | T1: 6 | U1: 7 | V1: 8 | W1: 9 | Z1: 2 | AA1: 3 | AB1: 4 | AC1: 5 | AD1: 6 | AE1: 7 | AF1: 8 | AG1: 9 | AH1: 11 | AL1: 2 | AM1: 3 | AN1: 4 | AO1: 5 | AP1: 6 | AQ1: 7 | AR1: 8 | AS1: 9 | AT1: 11 | AX1: 2 | AZ1: 4 | BA1: 5 | BB1: 6 | BC1: 7 | BD1: 8 | BE1: 9 | BF1: 11 | BJ1: 2 | BK1: 3 | BL1: 4 | BM1: 5 | BN1: 6 | BO1: 7 | BP1: 8 | BQ1: 9 | BR1: 11 | BV1: 2 | BW1: 3 | BX1: 4 | BY1: 5 | BZ1: 6 | CA1: 7 | CB1: 8 | CC1: 9 | CD1: 11 | CH1: 2 | CI1: 3 | CJ1: 4 | CK1: 5 | CL1: 6 | CM1: 7 | CN1: 8 | CO1: 9 | CP1: 11 | CT1: 2 | CU1: 3 | CV1: 4 | CW1: 5 | CX1: 6 | CY1: 7 | CZ1: 8 | DA1: 9 | DB1: 11 | DF1: 2 | DG1: 3 | DH1: 4 | DI1: 5 | DJ1: 6 | DK1: 7 | DL1: 8 | DM1: 9 | DN1: 11 | DR1: 2 | DS1: 3 | DT1: 4 | DU1: 5 | DV1: 6 | DW1: 7 | DX1: 8 | DY1: 9 | DZ1: 11 | ED1: 2 | EE1: 3 | EF1: 4 | EG1: 5 | EH1: 6 | EI1: 7 | EJ1: 8 | EK1: 9 | EL1: 11 | EP1: 2 | EQ1: 3 | ER1: 4 | ES1: 5 | ET1: 6 | EU1: 7 | EV1: 8 | EW1: 9 | EX1: 11 | FB1: 2 | FC1: 3 | FD1: 4 | FE1: 5 | FF1: 6 | FG1: 7 | FH1: 8 | FI1: 9 | FJ1: 11 | FN1: 2 | FO1: 3 | FP1: 4 | FQ1: 5 | FR1: 6 | FS1: 7 | FT1: 8 | FU1: 9 | FV1: 11 | FZ1: 2 | GA1: 3 | GB1: 4 | GC1: 5 | GD1: 6 | GE1: 7 | GF1: 8 | GG1: 9 | GH1: 11 | GL1: 2 | GM1: 3 | GN1: 4 | GO1: 5 | GP1: 6 | GQ1: 7 | GR1: 8 | GS1: 9 | GT1: 11 | GX1: 2 | GY1: 3 | GZ1: 4 | HA1: 5 | HB1: 6 | HC1: 7 | HD1: 8 | HE1: 9 | HF1: 11 | HJ1: 2 | HK1: 3 | HL1: 4 | HM1: 5 | HN1: 6 | HO1: 7 | HP1: 8 | HQ1: 9 | HR1: 11 | HV1: 2 | HW1: 3 | HX1: 4 | HY1: 5 | HZ1: 6 | IA1: 7 | IB1: 8 | IC1: 9
B2: English Language | N2: Literature in English | Z2: MATHEMATICS | AL2: Physics | AX2: CHEMISTRY | BJ2: BIOLOGY | BV2: ECONOMICS | CH2: HISTORY | CT2: CRK | DF2: AGRIC SCIENCE | DR2: GEOGRAPHY | ED2: COMMERCE | EP2: FINE ART | FB2: ACCOUINTING | FN2: TECHNICAL DRAWING | FZ2: GOVERNMENT | GL2: FURTHER MATHS | GX2: HAUSA | HJ2: FOOD & NUTRITION | HV2: COMPUTER SCIENCE | IH2: FRENCH | IT2: CIVIC EDUCATION | JF2: DATA PROCESSING | JR2: I.R.K.
A3: Admission_No | B3: Names | C3: 1st C. A. | D3: 2st C. A. | E3: 3st C. A. | F3: 4st C. A. | G3: Total C. A. | H3: Exam | I3: Total | J3: Position | K3: Grade | L3: Teacher's Comment | N3: Names | O3: 1st C. A. | P3: 2st C. A. | Q3: 3st C. A. | R3: 4st C. A. | S3: Total C. A. | T3: Exam | U3: Total | V3: Position | W3: Grade | X3: Teacher's Comment | Z3: Names | AA3: 1st C. A. | AB3: 2st C. A. | AC3: 3st C. A. | AD3: 4st C. A. | AE3: Total C. A. | AF3: Exam | AG3: Total | AH3: Position | AI3: Grade | AJ3: Teacher's Comment | AL3: Names | AM3: 1st C. A. | AN3: 2st C. A. | AO3: 3st C. A. | AP3: 4st C. A. | AQ3: Total C. A. | AR3: Exam | AS3: Total | AT3: Position | AU3: Grade | AV3: Teacher's Comment | AX3: Names | AY3: 1st C. A. | AZ3: 2st C. A. | BA3: 3st C. A. | BB3: 4st C. A. | BC3: Total C. A. | BD3: Exam | BE3: Total | BF3: Position | BG3: Grade | BH3: Teacher's Comment | BJ3: Names | BK3: 1st C. A. | BL3: 2st C. A. | BM3: 3st C. A. | BN3: 4st C. A. | BO3: Total C. A. | BP3: Exam | BQ3: Total | BR3: Position | BS3: Grade | BT3: Teacher's Comment | BV3: Names | BW3: 1st C. A. | BX3: 2st C. A. | BY3: 3st C. A. | BZ3: 4st C. A. | CA3: Total C. A. | CB3: Exam | CC3: Total | CD3: Position | CE3: Grade | CF3: Teacher's Comment | CH3: Names | CI3: 1st C. A. | CJ3: 2st C. A. | CK3: 3st C. A. | CL3: 4st C. A. | CM3: Total C. A. | CN3: Exam | CO3: Total | CP3: Position | CQ3: Grade | CR3: Teacher's Comment | CT3: Names | CU3: 1st C. A. | CV3: 2st C. A. | CW3: 3st C. A. | CX3: 4st C. A. | CY3: Total C. A. | CZ3: Exam | DA3: Total | DB3: Position | DC3: Grade | DD3: Teacher's Comment | DF3: Names | DG3: 1st C. A. | DH3: 2st C. A. | DI3: 3st C. A. | DJ3: 4st C. A. | DK3: Total C. A. | DL3: Exam | DM3: Total | DN3: Position | DO3: Grade | DP3: Teacher's Comment | DR3: Names | DS3: 1st C. A. | DT3: 2st C. A. | DU3: 3st C. A. | DV3: 4st C. A. | DW3: Total C. A. | DX3: Exam | DY3: Total | DZ3: Position | EA3: Grade | EB3: Teacher's Comment | ED3: Names | EE3: 1st C. A. | EF3: 2st C. A. | EG3: 3st C. A. | EH3: 4st C. A. | EI3: Total C. A. | EJ3: Exam | EK3: Total | EL3: Position | EM3: Grade | EN3: Teacher's Comment | EP3: Names | EQ3: 1st C. A. | ER3: 2st C. A. | ES3: 3st C. A. | ET3: 4st C. A. | EU3: Total C. A. | EV3: Exam | EW3: Total | EX3: Position | EY3: Grade | EZ3: Teacher's Comment | FB3: Names | FC3: 1st C. A. | FD3: 2st C. A. | FE3: 3st C. A. | FF3: 4st C. A. | FG3: Total C. A. | FH3: Exam | FI3: Total | FJ3: Position | FK3: Grade | FL3: Teacher's Comment | FN3: Names | FO3: 1st C. A. | FP3: 2st C. A. | FQ3: 3st C. A. | FR3: 4st C. A. | FS3: Total C. A. | FT3: Exam | FU3: Total | FV3: Position | FW3: Grade | FX3: Teacher's Comment | FZ3: Names | GA3: 1st C. A. | GB3: 2st C. A. | GC3: 3st C. A. | GD3: 4st C. A. | GE3: Total C. A. | GF3: Exam | GG3: Total | GH3: Position | GI3: Grade | GJ3: Teacher's Comment | GL3: Names | GM3: 1st C. A. | GN3: 2st C. A. | GO3: 3st C. A. | GP3: 4st C. A. | GQ3: Total C. A. | GR3: Exam | GS3: Total | GT3: Position | GU3: Grade | GV3: Teacher's Comment | GX3: Names | GY3: 1st C. A. | GZ3: 2st C. A. | HA3: 3st C. A. | HB3: 4st C. A. | HC3: Total C. A. | HD3: Exam | HE3: Total | HF3: Position | HG3: Grade | HH3: Teacher's Comment | HJ3: Names | HK3: 1st C. A. | HL3: 2st C. A. | HM3: 3st C. A. | HN3: 4st C. A. | HO3: Total C. A. | HP3: Exam | HQ3: Total | HR3: Position | HS3: Grade | HT3: Teacher's Comment | HV3: Names | HW3: 1st C. A. | HX3: 2st C. A. | HY3: 3st C. A. | HZ3: 4st C. A. | IA3: Total C. A. | IB3: Exam | IC3: Total | ID3: Position | IE3: Grade | IF3: Teacher's Comment | IH3: Names | II3: 1st C. A. | IJ3: 2st C. A. | IK3: 3st C. A. | IL3: 4st C. A. | IM3: Total C. A. | IN3: Exam | IO3: Total | IP3: Position | IQ3: Grade | IR3: Teacher's Comment | IT3: Names | IU3: 1st C. A. | IV3: 2st C. A. | IW3: 3st C. A. | IX3: 4st C. A. | IY3: Total C. A. | IZ3: Exam | JA3: Total | JB3: Position | JC3: Grade | JD3: Teacher's Comment | JF3: Names | JG3: 1st C. A. | JH3: 2st C. A. | JI3: 3st C. A. | JJ3: 4st C. A. | JK3: Total C. A. | JL3: Exam | JM3: Total | JN3: Position | JO3: Grade | JP3: Teacher's Comment | JR3: Names | JS3: 1st C. A. | JT3: 2st C. A. | JU3: 3st C. A. | JV3: 4st C. A. | JW3: Total C. A. | JX3: Exam | JY3: Total | JZ3: Position | KA3: Grade | KB3: Teacher's Comment
A4: 1 | B4: =Data!B2 -> ALI AHMED ASHEMI | C4: 6 | D4: 4 | E4: 1 | F4: 5 | G4: =SUM(C4:F4) -> 16 | H4: 27 | I4: =G4+H4 -> 43 | J4: =IF(I4<10,"",RANK(I4,I$4:I$57)) -> 15 | K4: =IF(I4>=75,"A1",IF(I4>=70,"B2",IF(I4>=65,"B3",IF(I4>=60,"C4",IF(I4>=55,"C5",IF(I4>=50,"C6",IF(I4>=45,"D7",IF(I4>=40,"E8",IF(I4>=6,"F",IF(I4<5,"")))))))))) -> E8 | L4: =IF(I4>=75,"Excellent",IF(I4>=70,"V.Good",IF(I4>=65,"Good",IF(I4>=60,"Credit",IF(I4>=55,"Credit",IF(I4>=50,"Credit",IF(I4>=45,"Pass",IF(I4>=40,"Pass",IF(I4>=6,"Fail",IF(I4<5,"")))))))))) -> Pass | M4: 1 | N4: =Data!B2 -> ALI AHMED ASHEMI | O4: 6 | P4: 4 | Q4: 1 | R4: 5 | S4: =SUM(O4:R4) -> 16 | T4: 27 | U4: =S4+T4 -> 43 | V4: =IF(U4<10,"",RANK(U4,U$4:U$57)) -> 11 | W4: =IF(U4>=75,"A1",IF(U4>=70,"B2",IF(U4>=65,"B3",IF(U4>=60,"C4",IF(U4>=55,"C5",IF(U4>=50,"C6",IF(U4>=45,"D7",IF(U4>=40,"E8",IF(U4>=6,"F",IF(U4<5,"")))))))))) -> E8 | X4: =IF(U4>=75,"Excellent",IF(U4>=70,"V.Good",IF(U4>=65,"Good",IF(U4>=60,"Credit",IF(U4>=55,"Credit",IF(U4>=50,"Credit",IF(U4>=45,"Pass",IF(U4>=40,"Pass",IF(U4>=6,"Fail",IF(U4<5,"")))))))))) -> Pass | Y4: 1 | Z4: =Data!B2 -> ALI AHMED ASHEMI | AA4: 6 | AB4: 4 | AC4: 1 | AD4: 5 | AE4: =SUM(AA4:AD4) -> 16 | AF4: 42 | AG4: =AE4+AF4 -> 58 | AH4: =IF(AG4<10,"",RANK(AG4,AG$4:AG$57)) -> 19 | AI4: =IF(AG4>=75,"A1",IF(AG4>=70,"B2",IF(AG4>=65,"B3",IF(AG4>=60,"C4",IF(AG4>=55,"C5",IF(AG4>=50,"C6",IF(AG4>=45,"D7",IF(AG4>=40,"E8",IF(AG4>=6,"F",IF(AG4<5,"")))))))))) -> C5 | AJ4: =IF(AG4>=75,"Excellent",IF(AG4>=70,"V.Good",IF(AG4>=65,"Good",IF(AG4>=60,"Credit",IF(AG4>=55,"Credit",IF(AG4>=50,"Credit",IF(AG4>=45,"Pass",IF(AG4>=40,"Pass",IF(AG4>=6,"Fail",IF(AG4<5,"")))))))))) -> Credit | AK4: 1 | AL4: =Data!B2 -> ALI AHMED ASHEMI | AQ4: =SUM(AM4:AP4) -> 0 | AS4: =AQ4+AR4 -> 0 | AT4: =IF(AS4<10,"",RANK(AS4,AS$4:AS$57)) | AU4: =IF(AS4>=75,"A1",IF(AS4>=70,"B2",IF(AS4>=65,"B3",IF(AS4>=60,"C4",IF(AS4>=55,"C5",IF(AS4>=50,"C6",IF(AS4>=45,"D7",IF(AS4>=40,"E8",IF(AS4>=6,"F",IF(AS4<5,"")))))))))) | AV4: =IF(AS4>=75,"Excellent",IF(AS4>=70,"V.Good",IF(AS4>=65,"Good",IF(AS4>=60,"Credit",IF(AS4>=55,"Credit",IF(AS4>=50,"Credit",IF(AS4>=45,"Pass",IF(AS4>=40,"Pass",IF(AS4>=6,"Fail",IF(AS4<5,"")))))))))) | AW4: 1 | AX4: =Data!B2 -> ALI AHMED ASHEMI | BC4: =SUM(AY4:BB4) -> 0 | BE4: =BC4+BD4 -> 0 | BF4: =IF(BE4<10,"",RANK(BE4,BE$4:BE$57)) | BG4: =IF(BE4>=75,"A1",IF(BE4>=70,"B2",IF(BE4>=65,"B3",IF(BE4>=60,"C4",IF(BE4>=55,"C5",IF(BE4>=50,"C6",IF(BE4>=45,"D7",IF(BE4>=40,"E8",IF(BE4>=6,"F",IF(BE4<5,"")))))))))) | BH4: =IF(BE4>=75,"Excellent",IF(BE4>=70,"V.Good",IF(BE4>=65,"Good",IF(BE4>=60,"Credit",IF(BE4>=55,"Credit",IF(BE4>=50,"Credit",IF(BE4>=45,"Pass",IF(BE4>=40,"Pass",IF(BE4>=6,"Fail",IF(BE4<5,"")))))))))) | BI4: 1 | BJ4: =Data!B2 -> ALI AHMED ASHEMI | BK4: 6 | BL4: 4 | BM4: 1 | BN4: 5 | BO4: =SUM(BK4:BN4) -> 16 | BP4: 42 | BQ4: =BO4+BP4 -> 58 | BR4: =IF(BQ4<10,"",RANK(BQ4,BQ$4:BQ$57)) -> 13 | BS4: =IF(BQ4>=75,"A1",IF(BQ4>=70,"B2",IF(BQ4>=65,"B3",IF(BQ4>=60,"C4",IF(BQ4>=55,"C5",IF(BQ4>=50,"C6",IF(BQ4>=45,"D7",IF(BQ4>=40,"E8",IF(BQ4>=6,"F",IF(BQ4<5,"")))))))))) -> C5 | BT4: =IF(BQ4>=75,"Excellent",IF(BQ4>=70,"V.Good",IF(BQ4>=65,"Good",IF(BQ4>=60,"Credit",IF(BQ4>=55,"Credit",IF(BQ4>=50,"Credit",IF(BQ4>=45,"Pass",IF(BQ4>=40,"Pass",IF(BQ4>=6,"Fail",IF(BQ4<5,"")))))))))) -> Credit | BU4: 1 | BV4: =Data!B2 -> ALI AHMED ASHEMI | BW4: 6 | BX4: 4 | BY4: 9 | BZ4: 7 | CA4: =SUM(BW4:BZ4) -> 26 | CB4: 26 | CC4: =CA4+CB4 -> 52 | CD4: =IF(CC4<10,"",RANK(CC4,CC$4:CC$57)) -> 18 | CE4: =IF(CC4>=75,"A1",IF(CC4>=70,"B2",IF(CC4>=65,"B3",IF(CC4>=60,"C4",IF(CC4>=55,"C5",IF(CC4>=50,"C6",IF(CC4>=45,"D7",IF(CC4>=40,"E8",IF(CC4>=6,"F",IF(CC4<5,"")))))))))) -> C6 | CF4: =IF(CC4>=75,"Excellent",IF(CC4>=70,"V.Good",IF(CC4>=65,"Good",IF(CC4>=60,"Credit",IF(CC4>=55,"Credit",IF(CC4>=50,"Credit",IF(CC4>=45,"Pass",IF(CC4>=40,"Pass",IF(CC4>=6,"Fail",IF(CC4<5,"")))))))))) -> Credit | CG4: 1 | CH4: =Data!B2 -> ALI AHMED ASHEMI | CM4: =SUM(CI4:CL4) -> 0 | CO4: =CM4+CN4 -> 0 | CP4: =IF(CO4<10,"",RANK(CO4,CO$4:CO$57)) | CQ4: =IF(CO4>=75,"A1",IF(CO4>=70,"B2",IF(CO4>=65,"B3",IF(CO4>=60,"C4",IF(CO4>=55,"C5",IF(CO4>=50,"C6",IF(CO4>=45,"D7",IF(CO4>=40,"E8",IF(CO4>=6,"F",IF(CO4<5,"")))))))))) | CR4: =IF(CO4>=75,"Excellent",IF(CO4>=70,"V.Good",IF(CO4>=65,"Good",IF(CO4>=60,"Credit",IF(CO4>=55,"Credit",IF(CO4>=50,"Credit",IF(CO4>=45,"Pass",IF(CO4>=40,"Pass",IF(CO4>=6,"Fail",IF(CO4<5,"")))))))))) | CS4: 1 | CT4: =Data!B2 -> ALI AHMED ASHEMI | CY4: =SUM(CU4:CX4) -> 0 | DA4: =CY4+CZ4 -> 0 | DB4: =IF(DA4<10,"",RANK(DA4,DA$4:DA$57)) | DC4: =IF(DA4>=75,"A1",IF(DA4>=70,"B2",IF(DA4>=65,"B3",IF(DA4>=60,"C4",IF(DA4>=55,"C5",IF(DA4>=50,"C6",IF(DA4>=45,"D7",IF(DA4>=40,"E8",IF(DA4>=6,"F",IF(DA4<5,"")))))))))) | DD4: =IF(DA4>=75,"Excellent",IF(DA4>=70,"V.Good",IF(DA4>=65,"Good",IF(DA4>=60,"Credit",IF(DA4>=55,"Credit",IF(DA4>=50,"Credit",IF(DA4>=45,"Pass",IF(DA4>=40,"Pass",IF(DA4>=6,"Fail",IF(DA4<5,"")))))))))) | DE4: 1 | DF4: =Data!B2 -> ALI AHMED ASHEMI | DK4: =SUM(DG4:DJ4) -> 0 | DM4: =DK4+DL4 -> 0 | DN4: =IF(DM4<10,"",RANK(DM4,DM$4:DM$57)) | DO4: =IF(DM4>=75,"A1",IF(DM4>=70,"B2",IF(DM4>=65,"B3",IF(DM4>=60,"C4",IF(DM4>=55,"C5",IF(DM4>=50,"C6",IF(DM4>=45,"D7",IF(DM4>=40,"E8",IF(DM4>=6,"F",IF(DM4<5,"")))))))))) | DP4: =IF(DM4>=75,"Excellent",IF(DM4>=70,"V.Good",IF(DM4>=65,"Good",IF(DM4>=60,"Credit",IF(DM4>=55,"Credit",IF(DM4>=50,"Credit",IF(DM4>=45,"Pass",IF(DM4>=40,"Pass",IF(DM4>=6,"Fail",IF(DM4<5,"")))))))))) | DQ4: 1 | DR4: =Data!B2 -> ALI AHMED ASHEMI | DW4: =SUM(DS4:DV4) -> 0 | DY4: =DW4+DX4 -> 0 | DZ4: =IF(DY4<10,"",RANK(DY4,DY$4:DY$57)) | EA4: =IF(DY4>=75,"A1",IF(DY4>=70,"B2",IF(DY4>=65,"B3",IF(DY4>=60,"C4",IF(DY4>=55,"C5",IF(DY4>=50,"C6",IF(DY4>=45,"D7",IF(DY4>=40,"E8",IF(DY4>=6,"F",IF(DY4<5,"")))))))))) | EB4: =IF(DY4>=75,"Excellent",IF(DY4>=70,"V.Good",IF(DY4>=65,"Good",IF(DY4>=60,"Credit",IF(DY4>=55,"Credit",IF(DY4>=50,"Credit",IF(DY4>=45,"Pass",IF(DY4>=40,"Pass",IF(DY4>=6,"Fail",IF(DY4<5,"")))))))))) | EC4: 1 | ED4: =Data!B2 -> ALI AHMED ASHEMI | EI4: =SUM(EE4:EH4) -> 0 | EK4: =EI4+EJ4 -> 0 | EL4: =IF(EK4<10,"",RANK(EK4,EK$4:EK$57)) | EM4: =IF(EK4>=75,"A1",IF(EK4>=70,"B2",IF(EK4>=65,"B3",IF(EK4>=60,"C4",IF(EK4>=55,"C5",IF(EK4>=50,"C6",IF(EK4>=45,"D7",IF(EK4>=40,"E8",IF(EK4>=6,"F",IF(EK4<5,"")))))))))) | EN4: =IF(EK4>=75,"Excellent",IF(EK4>=70,"V.Good",IF(EK4>=65,"Good",IF(EK4>=60,"Credit",IF(EK4>=55,"Credit",IF(EK4>=50,"Credit",IF(EK4>=45,"Pass",IF(EK4>=40,"Pass",IF(EK4>=6,"Fail",IF(EK4<5,"")))))))))) | EO4: 1 | EP4: =Data!B2 -> ALI AHMED ASHEMI | EU4: =SUM(EQ4:ET4) -> 0 | EW4: =EU4+EV4 -> 0 | EX4: =IF(EW4<10,"",RANK(EW4,EW$4:EW$57)) | EY4: =IF(EW4>=75,"A1",IF(EW4>=70,"B2",IF(EW4>=65,"B3",IF(EW4>=60,"C4",IF(EW4>=55,"C5",IF(EW4>=50,"C6",IF(EW4>=45,"D7",IF(EW4>=40,"E8",IF(EW4>=6,"F",IF(EW4<5,"")))))))))) | EZ4: =IF(EW4>=75,"Excellent",IF(EW4>=70,"V.Good",IF(EW4>=65,"Good",IF(EW4>=60,"Credit",IF(EW4>=55,"Credit",IF(EW4>=50,"Credit",IF(EW4>=45,"Pass",IF(EW4>=40,"Pass",IF(EW4>=6,"Fail",IF(EW4<5,"")))))))))) | FA4: 1 | FB4: =Data!B2 -> ALI AHMED ASHEMI | FG4: =SUM(FC4:FF4) -> 0 | FI4: =FG4+FH4 -> 0 | FJ4: =IF(FI4<10,"",RANK(FI4,FI$4:FI$57)) | FK4: =IF(FI4>=75,"A",IF(FI4>=70,"B2",IF(FI4>=50,"C",IF(FI4>=45,"D",IF(FI4>=40,"E",IF(FI4>=6,"F",IF(FI4<5,""))))))) | FL4: =IF(FI4>=75,"Excellent",IF(FI4>=70,"V.Good",IF(FI4>=65,"Good",IF(FI4>=60,"Credit",IF(FI4>=55,"Credit",IF(FI4>=50,"Credit",IF(FI4>=45,"Pass",IF(FI4>=40,"Pass",IF(FI4>=6,"Fail",IF(FI4<5,"")))))))))) | FM4: 1 | FN4: =Data!B2 -> ALI AHMED ASHEMI | FS4: =SUM(FO4:FR4) -> 0 | FU4: =FS4+FT4 -> 0 | FV4: =IF(FU4<10,"",RANK(FU4,FU$4:FU$57)) | FW4: =IF(FU4>=75,"A",IF(FU4>=70,"B2",IF(FU4>=50,"C",IF(FU4>=45,"D",IF(FU4>=40,"E",IF(FU4>=6,"F",IF(FU4<5,""))))))) | FX4: =IF(FU4>=75,"Excellent",IF(FU4>=70,"V.Good",IF(FU4>=65,"Good",IF(FU4>=60,"Credit",IF(FU4>=55,"Credit",IF(FU4>=50,"Credit",IF(FU4>=45,"Pass",IF(FU4>=40,"Pass",IF(FU4>=6,"Fail",IF(FU4<5,"")))))))))) | FY4: 1 | FZ4: =Data!B2 -> ALI AHMED ASHEMI | GA4: 7 | GB4: 7 | GC4: 8 | GD4: 7 | GE4: =SUM(GA4:GD4) -> 29 | GF4: 26 | GG4: =GE4+GF4 -> 55 | GH4: =IF(GG4<10,"",RANK(GG4,GG$4:GG$57)) -> 21 | GI4: =IF(GG4>=75,"A",IF(GG4>=70,"B2",IF(GG4>=50,"C",IF(GG4>=45,"D",IF(GG4>=40,"E",IF(GG4>=6,"F",IF(GG4<5,""))))))) -> C | GJ4: =IF(GG4>=75,"Excellent",IF(GG4>=70,"V.Good",IF(GG4>=65,"Good",IF(GG4>=60,"Credit",IF(GG4>=55,"Credit",IF(GG4>=50,"Credit",IF(GG4>=45,"Pass",IF(GG4>=40,"Pass",IF(GG4>=6,"Fail",IF(GG4<5,"")))))))))) -> Credit | GK4: 1 | GL4: =Data!B2 -> ALI AHMED ASHEMI | GQ4: =SUM(GM4:GP4) -> 0 | GS4: =GQ4+GR4 -> 0 | GT4: =IF(GS4<10,"",RANK(GS4,GS$4:GS$57)) | GU4: =IF(GS4>=75,"A",IF(GS4>=70,"B2",IF(GS4>=50,"C",IF(GS4>=45,"D",IF(GS4>=40,"E",IF(GS4>=6,"F",IF(GS4<5,""))))))) | GV4: =IF(GS4>=75,"Excellent",IF(GS4>=70,"V.Good",IF(GS4>=65,"Good",IF(GS4>=60,"Credit",IF(GS4>=55,"Credit",IF(GS4>=50,"Credit",IF(GS4>=45,"Pass",IF(GS4>=40,"Pass",IF(GS4>=6,"Fail",IF(GS4<5,"")))))))))) | GW4: 1 | GX4: =Data!B2 -> ALI AHMED ASHEMI | HC4: =SUM(GY4:HB4) -> 0 | HE4: =HC4+HD4 -> 0 | HF4: =IF(HE4<10,"",RANK(HE4,HE$4:HE$57)) | HG4: =IF(HE4>=75,"A",IF(HE4>=70,"B2",IF(HE4>=50,"C",IF(HE4>=45,"D",IF(HE4>=40,"E",IF(HE4>=6,"F",IF(HE4<5,""))))))) | HH4: =IF(HE4>=75,"Excellent",IF(HE4>=70,"V.Good",IF(HE4>=65,"Good",IF(HE4>=60,"Credit",IF(HE4>=55,"Credit",IF(HE4>=50,"Credit",IF(HE4>=45,"Pass",IF(HE4>=40,"Pass",IF(HE4>=6,"Fail",IF(HE4<5,"")))))))))) | HI4: 1 | HJ4: =Data!B2 -> ALI AHMED ASHEMI | HO4: =SUM(HK4:HN4) -> 0 | HQ4: =HO4+HP4 -> 0 | HR4: =IF(HQ4<10,"",RANK(HQ4,HQ$4:HQ$57)) | HS4: =IF(HQ4>=75,"A",IF(HQ4>=70,"B2",IF(HQ4>=50,"C",IF(HQ4>=45,"D",IF(HQ4>=40,"E",IF(HQ4>=6,"F",IF(HQ4<5,""))))))) | HT4: =IF(HQ4>=75,"Excellent",IF(HQ4>=70,"V.Good",IF(HQ4>=65,"Good",IF(HQ4>=60,"Credit",IF(HQ4>=55,"Credit",IF(HQ4>=50,"Credit",IF(HQ4>=45,"Pass",IF(HQ4>=40,"Pass",IF(HQ4>=6,"Fail",IF(HQ4<5,"")))))))))) | HU4: 1 | HV4: =Data!B2 -> ALI AHMED ASHEMI | IA4: =SUM(HW4:HZ4) -> 0 | IC4: =IA4+IB4 -> 0 | ID4: =IF(IC4<10,"",RANK(IC4,IC$4:IC$57)) | IE4: =IF(IC4>=75,"A",IF(IC4>=70,"B2",IF(IC4>=50,"C",IF(IC4>=45,"D",IF(IC4>=40,"E",IF(IC4>=6,"F",IF(IC4<5,""))))))) | IF4: =IF(IC4>=75,"Excellent",IF(IC4>=70,"V.Good",IF(IC4>=65,"Good",IF(IC4>=60,"Credit",IF(IC4>=55,"Credit",IF(IC4>=50,"Credit",IF(IC4>=45,"Pass",IF(IC4>=40,"Pass",IF(IC4>=6,"Fail",IF(IC4<5,"")))))))))) | IG4: 1 | IH4: =Data!B2 -> ALI AHMED ASHEMI | IM4: =SUM(II4:IL4) -> 0 | IO4: =IM4+IN4 -> 0 | IP4: =IF(IO4<10,"",RANK(IO4,IO$4:IO$57)) | IQ4: =IF(IO4>=75,"A",IF(IO4>=70,"B2",IF(IO4>=50,"C",IF(IO4>=45,"D",IF(IO4>=40,"E",IF(IO4>=6,"F",IF(IO4<5,""))))))) | IR4: =IF(IO4>=75,"Excellent",IF(IO4>=70,"V.Good",IF(IO4>=65,"Good",IF(IO4>=60,"Credit",IF(IO4>=55,"Credit",IF(IO4>=50,"Credit",IF(IO4>=45,"Pass",IF(IO4>=40,"Pass",IF(IO4>=6,"Fail",IF(IO4<5,"")))))))))) | IS4: 1 | IT4: =IH4 -> ALI AHMED ASHEMI | IU4: 6 | IV4: 4 | IW4: 1 | IX4: 5 | IY4: =SUM(IU4:IX4) -> 16 | IZ4: 42 | JA4: =IY4+IZ4 -> 58 | JB4: =IF(JA4<10,"",RANK(JA4,JA$4:JA$57)) -> 13 | JC4: =IF(JA4>=75,"A",IF(JA4>=70,"B2",IF(JA4>=50,"C",IF(JA4>=45,"D",IF(JA4>=40,"E",IF(JA4>=6,"F",IF(JA4<5,""))))))) -> C | JD4: =IF(JA4>=75,"Excellent",IF(JA4>=70,"V.Good",IF(JA4>=65,"Good",IF(JA4>=60,"Credit",IF(JA4>=55,"Credit",IF(JA4>=50,"Credit",IF(JA4>=45,"Pass",IF(JA4>=40,"Pass",IF(JA4>=6,"Fail",IF(JA4<5,"")))))))))) -> Credit | JE4: 1 | JF4: =IT4 -> ALI AHMED ASHEMI | JK4: =SUM(JG4:JJ4) -> 0 | JM4: =JK4+JL4 -> 0 | JN4: =IF(JM4<10,"",RANK(JM4,JM$4:JM$57)) | JO4: =IF(JM4>=75,"A",IF(JM4>=70,"B2",IF(JM4>=50,"C",IF(JM4>=45,"D",IF(JM4>=40,"E",IF(JM4>=6,"F",IF(JM4<5,""))))))) | JP4: =IF(JM4>=75,"Excellent",IF(JM4>=70,"V.Good",IF(JM4>=65,"Good",IF(JM4>=60,"Credit",IF(JM4>=55,"Credit",IF(JM4>=50,"Credit",IF(JM4>=45,"Pass",IF(JM4>=40,"Pass",IF(JM4>=6,"Fail",IF(JM4<5,"")))))))))) | JQ4: 1 | JR4: =JF4 -> ALI AHMED ASHEMI | JW4: =SUM(JS4:JV4) -> 0 | JY4: =JW4+JX4 -> 0 | JZ4: =IF(JY4<10,"",RANK(JY4,JY$4:JY$57)) | KA4: =IF(JY4>=75,"A",IF(JY4>=70,"B2",IF(JY4>=50,"C",IF(JY4>=45,"D",IF(JY4>=40,"E",IF(JY4>=6,"F",IF(JY4<5,""))))))) | KB4: =IF(JY4>=75,"Excellent",IF(JY4>=70,"V.Good",IF(JY4>=65,"Good",IF(JY4>=60,"Credit",IF(JY4>=55,"Credit",IF(JY4>=50,"Credit",IF(JY4>=45,"Pass",IF(JY4>=40,"Pass",IF(JY4>=6,"Fail",IF(JY4<5,""))))))))))
A5: 2 | B5: =Data!B3 -> ALHAJI MUSTAPHA ABUBAKAR | C5: 4 | D5: 2 | E5: 1 | F5: 1 | G5: =SUM(C5:F5) -> 8 | H5: 23 | I5: =G5+H5 -> 31 | J5: =IF(I5<10,"",RANK(I5,I$4:I$57)) -> 30 | K5: =IF(I5>=75,"A1",IF(I5>=70,"B2",IF(I5>=65,"B3",IF(I5>=60,"C4",IF(I5>=55,"C5",IF(I5>=50,"C6",IF(I5>=45,"D7",IF(I5>=40,"E8",IF(I5>=6,"F",IF(I5<5,"")))))))))) -> F | L5: =IF(I5>=75,"Excellent",IF(I5>=70,"V.Good",IF(I5>=65,"Good",IF(I5>=60,"Credit",IF(I5>=55,"Credit",IF(I5>=50,"Credit",IF(I5>=45,"Pass",IF(I5>=40,"Pass",IF(I5>=6,"Fail",IF(I5<5,"")))))))))) -> Fail | M5: 2 | N5: =Data!B3 -> ALHAJI MUSTAPHA ABUBAKAR | O5: 4 | P5: 2 | Q5: 1 | R5: 1 | S5: =SUM(O5:R5) -> 8 | T5: 23 | U5: =S5+T5 -> 31 | V5: =IF(U5<10,"",RANK(U5,U$4:U$57)) -> 20 | W5: =IF(U5>=75,"A1",IF(U5>=70,"B2",IF(U5>=65,"B3",IF(U5>=60,"C4",IF(U5>=55,"C5",IF(U5>=50,"C6",IF(U5>=45,"D7",IF(U5>=40,"E8",IF(U5>=6,"F",IF(U5<5,"")))))))))) -> F | X5: =IF(U5>=75,"Excellent",IF(U5>=70,"V.Good",IF(U5>=65,"Good",IF(U5>=60,"Credit",IF(U5>=55,"Credit",IF(U5>=50,"Credit",IF(U5>=45,"Pass",IF(U5>=40,"Pass",IF(U5>=6,"Fail",IF(U5<5,"")))))))))) -> Fail | Y5: 2 | Z5: =Data!B3 -> ALHAJI MUSTAPHA ABUBAKAR | AA5: 4 | AB5: 2 | AC5: 1 | AD5: 1 | AE5: =SUM(AA5:AD5) -> 8 | AF5: 42 | AG5: =AE5+AF5 -> 50 | AH5: =IF(AG5<10,"",RANK(AG5,AG$4:AG$57)) -> 36 | AI5: =IF(AG5>=75,"A1",IF(AG5>=70,"B2",IF(AG5>=65,"B3",IF(AG5>=60,"C4",IF(AG5>=55,"C5",IF(AG5>=50,"C6",IF(AG5>=45,"D7",IF(AG5>=40,"E8",IF(AG5>=6,"F",IF(AG5<5,"")))))))))) -> C6 | AJ5: =IF(AG5>=75,"Excellent",IF(AG5>=70,"V.Good",IF(AG5>=65,"Good",IF(AG5>=60,"Credit",IF(AG5>=55,"Credit",IF(AG5>=50,"Credit",IF(AG5>=45,"Pass",IF(AG5>=40,"Pass",IF(AG5>=6,"Fail",IF(AG5<5,"")))))))))) -> Credit | AK5: 2 | AL5: =Data!B3 -> ALHAJI MUSTAPHA ABUBAKAR | AQ5: =SUM(AM5:AP5) -> 0 | AS5: =AQ5+AR5 -> 0 | AT5: =IF(AS5<10,"",RANK(AS5,AS$4:AS$57)) | AU5: =IF(AS5>=75,"A1",IF(AS5>=70,"B2",IF(AS5>=65,"B3",IF(AS5>=60,"C4",IF(AS5>=55,"C5",IF(AS5>=50,"C6",IF(AS5>=45,"D7",IF(AS5>=40,"E8",IF(AS5>=6,"F",IF(AS5<5,"")))))))))) | AV5: =IF(AS5>=75,"Excellent",IF(AS5>=70,"V.Good",IF(AS5>=65,"Good",IF(AS5>=60,"Credit",IF(AS5>=55,"Credit",IF(AS5>=50,"Credit",IF(AS5>=45,"Pass",IF(AS5>=40,"Pass",IF(AS5>=6,"Fail",IF(AS5<5,"")))))))))) | AW5: 2 | AX5: =Data!B3 -> ALHAJI MUSTAPHA ABUBAKAR | BC5: =SUM(AY5:BB5) -> 0 | BE5: =BC5+BD5 -> 0 | BF5: =IF(BE5<10,"",RANK(BE5,BE$4:BE$57)) | BG5: =IF(BE5>=75,"A1",IF(BE5>=70,"B2",IF(BE5>=65,"B3",IF(BE5>=60,"C4",IF(BE5>=55,"C5",IF(BE5>=50,"C6",IF(BE5>=45,"D7",IF(BE5>=40,"E8",IF(BE5>=6,"F",IF(BE5<5,"")))))))))) | BH5: =IF(BE5>=75,"Excellent",IF(BE5>=70,"V.Good",IF(BE5>=65,"Good",IF(BE5>=60,"Credit",IF(BE5>=55,"Credit",IF(BE5>=50,"Credit",IF(BE5>=45,"Pass",IF(BE5>=40,"Pass",IF(BE5>=6,"Fail",IF(BE5<5,"")))))))))) | BI5: 2 | BJ5: =Data!B3 -> ALHAJI MUSTAPHA ABUBAKAR | BK5: 4 | BL5: 2 | BM5: 1 | BN5: 1 | BO5: =SUM(BK5:BN5) -> 8 | BP5: 42 | BQ5: =BO5+BP5 -> 50 | BR5: =IF(BQ5<10,"",RANK(BQ5,BQ$4:BQ$57)) -> 25 | BS5: =IF(BQ5>=75,"A1",IF(BQ5>=70,"B2",IF(BQ5>=65,"B3",IF(BQ5>=60,"C4",IF(BQ5>=55,"C5",IF(BQ5>=50,"C6",IF(BQ5>=45,"D7",IF(BQ5>=40,"E8",IF(BQ5>=6,"F",IF(BQ5<5,"")))))))))) -> C6 | BT5: =IF(BQ5>=75,"Excellent",IF(BQ5>=70,"V.Good",IF(BQ5>=65,"Good",IF(BQ5>=60,"Credit",IF(BQ5>=55,"Credit",IF(BQ5>=50,"Credit",IF(BQ5>=45,"Pass",IF(BQ5>=40,"Pass",IF(BQ5>=6,"Fail",IF(BQ5<5,"")))))))))) -> Credit | BU5: 2 | BV5: =Data!B3 -> ALHAJI MUSTAPHA ABUBAKAR | BW5: 7 | BX5: 2 | BY5: 8 | BZ5: 5 | CA5: =SUM(BW5:BZ5) -> 22 | CB5: 15 | CC5: =CA5+CB5 -> 37 | CD5: =IF(CC5<10,"",RANK(CC5,CC$4:CC$57)) -> 42 | CE5: =IF(CC5>=75,"A1",IF(CC5>=70,"B2",IF(CC5>=65,"B3",IF(CC5>=60,"C4",IF(CC5>=55,"C5",IF(CC5>=50,"C6",IF(CC5>=45,"D7",IF(CC5>=40,"E8",IF(CC5>=6,"F",IF(CC5<5,"")))))))))) -> F | CF5: =IF(CC5>=75,"Excellent",IF(CC5>=70,"V.Good",IF(CC5>=65,"Good",IF(CC5>=60,"Credit",IF(CC5>=55,"Credit",IF(CC5>=50,"Credit",IF(CC5>=45,"Pass",IF(CC5>=40,"Pass",IF(CC5>=6,"Fail",IF(CC5<5,"")))))))))) -> Fail | CG5: 2 | CH5: =Data!B3 -> ALHAJI MUSTAPHA ABUBAKAR | CM5: =SUM(CI5:CL5) -> 0 | CO5: =CM5+CN5 -> 0 | CP5: =IF(CO5<10,"",RANK(CO5,CO$4:CO$57)) | CQ5: =IF(CO5>=75,"A1",IF(CO5>=70,"B2",IF(CO5>=65,"B3",IF(CO5>=60,"C4",IF(CO5>=55,"C5",IF(CO5>=50,"C6",IF(CO5>=45,"D7",IF(CO5>=40,"E8",IF(CO5>=6,"F",IF(CO5<5,"")))))))))) | CR5: =IF(CO5>=75,"Excellent",IF(CO5>=70,"V.Good",IF(CO5>=65,"Good",IF(CO5>=60,"Credit",IF(CO5>=55,"Credit",IF(CO5>=50,"Credit",IF(CO5>=45,"Pass",IF(CO5>=40,"Pass",IF(CO5>=6,"Fail",IF(CO5<5,"")))))))))) | CS5: 2 | CT5: =Data!B3 -> ALHAJI MUSTAPHA ABUBAKAR | CY5: =SUM(CU5:CX5) -> 0 | DA5: =CY5+CZ5 -> 0 | DB5: =IF(DA5<10,"",RANK(DA5,DA$4:DA$57)) | DC5: =IF(DA5>=75,"A1",IF(DA5>=70,"B2",IF(DA5>=65,"B3",IF(DA5>=60,"C4",IF(DA5>=55,"C5",IF(DA5>=50,"C6",IF(DA5>=45,"D7",IF(DA5>=40,"E8",IF(DA5>=6,"F",IF(DA5<5,"")))))))))) | DD5: =IF(DA5>=75,"Excellent",IF(DA5>=70,"V.Good",IF(DA5>=65,"Good",IF(DA5>=60,"Credit",IF(DA5>=55,"Credit",IF(DA5>=50,"Credit",IF(DA5>=45,"Pass",IF(DA5>=40,"Pass",IF(DA5>=6,"Fail",IF(DA5<5,"")))))))))) | DE5: 2 | DF5: =Data!B3 -> ALHAJI MUSTAPHA ABUBAKAR | DG5: 5 | DH5: 1 | DI5: 2 | DJ5: 5 | DK5: =SUM(DG5:DJ5) -> 13 | DL5: 17 | DM5: =DK5+DL5 -> 30 | DN5: =IF(DM5<10,"",RANK(DM5,DM$4:DM$57)) -> 12 | DO5: =IF(DM5>=75,"A1",IF(DM5>=70,"B2",IF(DM5>=65,"B3",IF(DM5>=60,"C4",IF(DM5>=55,"C5",IF(DM5>=50,"C6",IF(DM5>=45,"D7",IF(DM5>=40,"E8",IF(DM5>=6,"F",IF(DM5<5,"")))))))))) -> F | DP5: =IF(DM5>=75,"Excellent",IF(DM5>=70,"V.Good",IF(DM5>=65,"Good",IF(DM5>=60,"Credit",IF(DM5>=55,"Credit",IF(DM5>=50,"Credit",IF(DM5>=45,"Pass",IF(DM5>=40,"Pass",IF(DM5>=6,"Fail",IF(DM5<5,"")))))))))) -> Fail | DQ5: 2 | DR5: =Data!B3 -> ALHAJI MUSTAPHA ABUBAKAR | DW5: =SUM(DS5:DV5) -> 0 | DY5: =DW5+DX5 -> 0 | DZ5: =IF(DY5<10,"",RANK(DY5,DY$4:DY$57)) | EA5: =IF(DY5>=75,"A1",IF(DY5>=70,"B2",IF(DY5>=65,"B3",IF(DY5>=60,"C4",IF(DY5>=55,"C5",IF(DY5>=50,"C6",IF(DY5>=45,"D7",IF(DY5>=40,"E8",IF(DY5>=6,"F",IF(DY5<5,"")))))))))) | EB5: =IF(DY5>=75,"Excellent",IF(DY5>=70,"V.Good",IF(DY5>=65,"Good",IF(DY5>=60,"Credit",IF(DY5>=55,"Credit",IF(DY5>=50,"Credit",IF(DY5>=45,"Pass",IF(DY5>=40,"Pass",IF(DY5>=6,"Fail",IF(DY5<5,"")))))))))) | EC5: 2 | ED5: =Data!B3 -> ALHAJI MUSTAPHA ABUBAKAR | EI5: =SUM(EE5:EH5) -> 0 | EK5: =EI5+EJ5 -> 0 | EL5: =IF(EK5<10,"",RANK(EK5,EK$4:EK$57)) | EM5: =IF(EK5>=75,"A1",IF(EK5>=70,"B2",IF(EK5>=65,"B3",IF(EK5>=60,"C4",IF(EK5>=55,"C5",IF(EK5>=50,"C6",IF(EK5>=45,"D7",IF(EK5>=40,"E8",IF(EK5>=6,"F",IF(EK5<5,"")))))))))) | EN5: =IF(EK5>=75,"Excellent",IF(EK5>=70,"V.Good",IF(EK5>=65,"Good",IF(EK5>=60,"Credit",IF(EK5>=55,"Credit",IF(EK5>=50,"Credit",IF(EK5>=45,"Pass",IF(EK5>=40,"Pass",IF(EK5>=6,"Fail",IF(EK5<5,"")))))))))) | EO5: 2 | EP5: =Data!B3 -> ALHAJI MUSTAPHA ABUBAKAR | EU5: =SUM(EQ5:ET5) -> 0 | EW5: =EU5+EV5 -> 0 | EX5: =IF(EW5<10,"",RANK(EW5,EW$4:EW$57)) | EY5: =IF(EW5>=75,"A1",IF(EW5>=70,"B2",IF(EW5>=65,"B3",IF(EW5>=60,"C4",IF(EW5>=55,"C5",IF(EW5>=50,"C6",IF(EW5>=45,"D7",IF(EW5>=40,"E8",IF(EW5>=6,"F",IF(EW5<5,"")))))))))) | EZ5: =IF(EW5>=75,"Excellent",IF(EW5>=70,"V.Good",IF(EW5>=65,"Good",IF(EW5>=60,"Credit",IF(EW5>=55,"Credit",IF(EW5>=50,"Credit",IF(EW5>=45,"Pass",IF(EW5>=40,"Pass",IF(EW5>=6,"Fail",IF(EW5<5,"")))))))))) | FA5: 2 | FB5: =Data!B3 -> ALHAJI MUSTAPHA ABUBAKAR | FG5: =SUM(FC5:FF5) -> 0 | FI5: =FG5+FH5 -> 0 | FJ5: =IF(FI5<10,"",RANK(FI5,FI$4:FI$57)) | FK5: =IF(FI5>=75,"A",IF(FI5>=70,"B2",IF(FI5>=50,"C",IF(FI5>=45,"D",IF(FI5>=40,"E",IF(FI5>=6,"F",IF(FI5<5,""))))))) | FL5: =IF(FI5>=75,"Excellent",IF(FI5>=70,"V.Good",IF(FI5>=65,"Good",IF(FI5>=60,"Credit",IF(FI5>=55,"Credit",IF(FI5>=50,"Credit",IF(FI5>=45,"Pass",IF(FI5>=40,"Pass",IF(FI5>=6,"Fail",IF(FI5<5,"")))))))))) | FM5: 2 | FN5: =Data!B3 -> ALHAJI MUSTAPHA ABUBAKAR | FS5: =SUM(FO5:FR5) -> 0 | FU5: =FS5+FT5 -> 0 | FV5: =IF(FU5<10,"",RANK(FU5,FU$4:FU$57)) | FW5: =IF(FU5>=75,"A",IF(FU5>=70,"B2",IF(FU5>=50,"C",IF(FU5>=45,"D",IF(FU5>=40,"E",IF(FU5>=6,"F",IF(FU5<5,""))))))) | FX5: =IF(FU5>=75,"Excellent",IF(FU5>=70,"V.Good",IF(FU5>=65,"Good",IF(FU5>=60,"Credit",IF(FU5>=55,"Credit",IF(FU5>=50,"Credit",IF(FU5>=45,"Pass",IF(FU5>=40,"Pass",IF(FU5>=6,"Fail",IF(FU5<5,"")))))))))) | FY5: 2 | FZ5: =Data!B3 -> ALHAJI MUSTAPHA ABUBAKAR | GA5: 6 | GB5: 5 | GC5: 2 | GD5: 2 | GE5: =SUM(GA5:GD5) -> 15 | GF5: 14 | GG5: =GE5+GF5 -> 29 | GH5: =IF(GG5<10,"",RANK(GG5,GG$4:GG$57)) -> 45 | GI5: =IF(GG5>=75,"A",IF(GG5>=70,"B2",IF(GG5>=50,"C",IF(GG5>=45,"D",IF(GG5>=40,"E",IF(GG5>=6,"F",IF(GG5<5,""))))))) -> F | GJ5: =IF(GG5>=75,"Excellent",IF(GG5>=70,"V.Good",IF(GG5>=65,"Good",IF(GG5>=60,"Credit",IF(GG5>=55,"Credit",IF(GG5>=50,"Credit",IF(GG5>=45,"Pass",IF(GG5>=40,"Pass",IF(GG5>=6,"Fail",IF(GG5<5,"")))))))))) -> Fail | GK5: 2 | GL5: =Data!B3 -> ALHAJI MUSTAPHA ABUBAKAR | GQ5: =SUM(GM5:GP5) -> 0 | GS5: =GQ5+GR5 -> 0 | GT5: =IF(GS5<10,"",RANK(GS5,GS$4:GS$57)) | GU5: =IF(GS5>=75,"A",IF(GS5>=70,"B2",IF(GS5>=50,"C",IF(GS5>=45,"D",IF(GS5>=40,"E",IF(GS5>=6,"F",IF(GS5<5,""))))))) | GV5: =IF(GS5>=75,"Excellent",IF(GS5>=70,"V.Good",IF(GS5>=65,"Good",IF(GS5>=60,"Credit",IF(GS5>=55,"Credit",IF(GS5>=50,"Credit",IF(GS5>=45,"Pass",IF(GS5>=40,"Pass",IF(GS5>=6,"Fail",IF(GS5<5,"")))))))))) | GW5: 2 | GX5: =Data!B3 -> ALHAJI MUSTAPHA ABUBAKAR | HC5: =SUM(GY5:HB5) -> 0 | HE5: =HC5+HD5 -> 0 | HF5: =IF(HE5<10,"",RANK(HE5,HE$4:HE$57)) | HG5: =IF(HE5>=75,"A",IF(HE5>=70,"B2",IF(HE5>=50,"C",IF(HE5>=45,"D",IF(HE5>=40,"E",IF(HE5>=6,"F",IF(HE5<5,""))))))) | HH5: =IF(HE5>=75,"Excellent",IF(HE5>=70,"V.Good",IF(HE5>=65,"Good",IF(HE5>=60,"Credit",IF(HE5>=55,"Credit",IF(HE5>=50,"Credit",IF(HE5>=45,"Pass",IF(HE5>=40,"Pass",IF(HE5>=6,"Fail",IF(HE5<5,"")))))))))) | HI5: 2 | HJ5: =Data!B3 -> ALHAJI MUSTAPHA ABUBAKAR | HO5: =SUM(HK5:HN5) -> 0 | HQ5: =HO5+HP5 -> 0 | HR5: =IF(HQ5<10,"",RANK(HQ5,HQ$4:HQ$57)) | HS5: =IF(HQ5>=75,"A",IF(HQ5>=70,"B2",IF(HQ5>=50,"C",IF(HQ5>=45,"D",IF(HQ5>=40,"E",IF(HQ5>=6,"F",IF(HQ5<5,""))))))) | HT5: =IF(HQ5>=75,"Excellent",IF(HQ5>=70,"V.Good",IF(HQ5>=65,"Good",IF(HQ5>=60,"Credit",IF(HQ5>=55,"Credit",IF(HQ5>=50,"Credit",IF(HQ5>=45,"Pass",IF(HQ5>=40,"Pass",IF(HQ5>=6,"Fail",IF(HQ5<5,"")))))))))) | HU5: 2 | HV5: =Data!B3 -> ALHAJI MUSTAPHA ABUBAKAR | IA5: =SUM(HW5:HZ5) -> 0 | IC5: =IA5+IB5 -> 0 | ID5: =IF(IC5<10,"",RANK(IC5,IC$4:IC$57)) | IE5: =IF(IC5>=75,"A",IF(IC5>=70,"B2",IF(IC5>=50,"C",IF(IC5>=45,"D",IF(IC5>=40,"E",IF(IC5>=6,"F",IF(IC5<5,""))))))) | IF5: =IF(IC5>=75,"Excellent",IF(IC5>=70,"V.Good",IF(IC5>=65,"Good",IF(IC5>=60,"Credit",IF(IC5>=55,"Credit",IF(IC5>=50,"Credit",IF(IC5>=45,"Pass",IF(IC5>=40,"Pass",IF(IC5>=6,"Fail",IF(IC5<5,"")))))))))) | IG5: 2 | IH5: =Data!B3 -> ALHAJI MUSTAPHA ABUBAKAR | IM5: =SUM(II5:IL5) -> 0 | IO5: =IM5+IN5 -> 0 | IP5: =IF(IO5<10,"",RANK(IO5,IO$4:IO$57)) | IQ5: =IF(IO5>=75,"A",IF(IO5>=70,"B2",IF(IO5>=50,"C",IF(IO5>=45,"D",IF(IO5>=40,"E",IF(IO5>=6,"F",IF(IO5<5,""))))))) | IR5: =IF(IO5>=75,"Excellent",IF(IO5>=70,"V.Good",IF(IO5>=65,"Good",IF(IO5>=60,"Credit",IF(IO5>=55,"Credit",IF(IO5>=50,"Credit",IF(IO5>=45,"Pass",IF(IO5>=40,"Pass",IF(IO5>=6,"Fail",IF(IO5<5,"")))))))))) | IS5: 2 | IT5: =IH5 -> ALHAJI MUSTAPHA ABUBAKAR | IU5: 4 | IV5: 2 | IW5: 1 | IX5: 1 | IY5: =SUM(IU5:IX5) -> 8 | IZ5: 42 | JA5: =IY5+IZ5 -> 50 | JB5: =IF(JA5<10,"",RANK(JA5,JA$4:JA$57)) -> 25 | JC5: =IF(JA5>=75,"A",IF(JA5>=70,"B2",IF(JA5>=50,"C",IF(JA5>=45,"D",IF(JA5>=40,"E",IF(JA5>=6,"F",IF(JA5<5,""))))))) -> C | JD5: =IF(JA5>=75,"Excellent",IF(JA5>=70,"V.Good",IF(JA5>=65,"Good",IF(JA5>=60,"Credit",IF(JA5>=55,"Credit",IF(JA5>=50,"Credit",IF(JA5>=45,"Pass",IF(JA5>=40,"Pass",IF(JA5>=6,"Fail",IF(JA5<5,"")))))))))) -> Credit | JE5: 2 | JF5: =IT5 -> ALHAJI MUSTAPHA ABUBAKAR | JK5: =SUM(JG5:JJ5) -> 0 | JM5: =JK5+JL5 -> 0 | JN5: =IF(JM5<10,"",RANK(JM5,JM$4:JM$57)) | JO5: =IF(JM5>=75,"A",IF(JM5>=70,"B2",IF(JM5>=50,"C",IF(JM5>=45,"D",IF(JM5>=40,"E",IF(JM5>=6,"F",IF(JM5<5,""))))))) | JP5: =IF(JM5>=75,"Excellent",IF(JM5>=70,"V.Good",IF(JM5>=65,"Good",IF(JM5>=60,"Credit",IF(JM5>=55,"Credit",IF(JM5>=50,"Credit",IF(JM5>=45,"Pass",IF(JM5>=40,"Pass",IF(JM5>=6,"Fail",IF(JM5<5,"")))))))))) | JQ5: 2 | JR5: =JF5 -> ALHAJI MUSTAPHA ABUBAKAR | JW5: =SUM(JS5:JV5) -> 0 | JY5: =JW5+JX5 -> 0 | JZ5: =IF(JY5<10,"",RANK(JY5,JY$4:JY$57)) | KA5: =IF(JY5>=75,"A",IF(JY5>=70,"B2",IF(JY5>=50,"C",IF(JY5>=45,"D",IF(JY5>=40,"E",IF(JY5>=6,"F",IF(JY5<5,""))))))) | KB5: =IF(JY5>=75,"Excellent",IF(JY5>=70,"V.Good",IF(JY5>=65,"Good",IF(JY5>=60,"Credit",IF(JY5>=55,"Credit",IF(JY5>=50,"Credit",IF(JY5>=45,"Pass",IF(JY5>=40,"Pass",IF(JY5>=6,"Fail",IF(JY5<5,""))))))))))
A6: 3 | B6: =Data!B4 -> ALI MUHAMMED UMAR | C6: 9 | D6: 2 | E6: 1 | F6: 5 | G6: =SUM(C6:F6) -> 17 | H6: 24 | I6: =G6+H6 -> 41 | J6: =IF(I6<10,"",RANK(I6,I$4:I$57)) -> 19 | K6: =IF(I6>=75,"A1",IF(I6>=70,"B2",IF(I6>=65,"B3",IF(I6>=60,"C4",IF(I6>=55,"C5",IF(I6>=50,"C6",IF(I6>=45,"D7",IF(I6>=40,"E8",IF(I6>=6,"F",IF(I6<5,"")))))))))) -> E8 | L6: =IF(I6>=75,"Excellent",IF(I6>=70,"V.Good",IF(I6>=65,"Good",IF(I6>=60,"Credit",IF(I6>=55,"Credit",IF(I6>=50,"Credit",IF(I6>=45,"Pass",IF(I6>=40,"Pass",IF(I6>=6,"Fail",IF(I6<5,"")))))))))) -> Pass | M6: 3 | N6: =Data!B4 -> ALI MUHAMMED UMAR | O6: 9 | P6: 2 | Q6: 1 | R6: 5 | S6: =SUM(O6:R6) -> 17 | T6: 24 | U6: =S6+T6 -> 41 | V6: =IF(U6<10,"",RANK(U6,U$4:U$57)) -> 13 | W6: =IF(U6>=75,"A1",IF(U6>=70,"B2",IF(U6>=65,"B3",IF(U6>=60,"C4",IF(U6>=55,"C5",IF(U6>=50,"C6",IF(U6>=45,"D7",IF(U6>=40,"E8",IF(U6>=6,"F",IF(U6<5,"")))))))))) -> E8 | X6: =IF(U6>=75,"Excellent",IF(U6>=70,"V.Good",IF(U6>=65,"Good",IF(U6>=60,"Credit",IF(U6>=55,"Credit",IF(U6>=50,"Credit",IF(U6>=45,"Pass",IF(U6>=40,"Pass",IF(U6>=6,"Fail",IF(U6<5,"")))))))))) -> Pass | Y6: 3 | Z6: =Data!B4 -> ALI MUHAMMED UMAR | AA6: 9 | AB6: 2 | AC6: 1 | AD6: 5 | AE6: =SUM(AA6:AD6) -> 17 | AF6: 42 | AG6: =AE6+AF6 -> 59 | AH6: =IF(AG6<10,"",RANK(AG6,AG$4:AG$57)) -> 17 | AI6: =IF(AG6>=75,"A1",IF(AG6>=70,"B2",IF(AG6>=65,"B3",IF(AG6>=60,"C4",IF(AG6>=55,"C5",IF(AG6>=50,"C6",IF(AG6>=45,"D7",IF(AG6>=40,"E8",IF(AG6>=6,"F",IF(AG6<5,"")))))))))) -> C5 | AJ6: =IF(AG6>=75,"Excellent",IF(AG6>=70,"V.Good",IF(AG6>=65,"Good",IF(AG6>=60,"Credit",IF(AG6>=55,"Credit",IF(AG6>=50,"Credit",IF(AG6>=45,"Pass",IF(AG6>=40,"Pass",IF(AG6>=6,"Fail",IF(AG6<5,"")))))))))) -> Credit | AK6: 3 | AL6: =Data!B4 -> ALI MUHAMMED UMAR | AQ6: =SUM(AM6:AP6) -> 0 | AS6: =AQ6+AR6 -> 0 | AT6: =IF(AS6<10,"",RANK(AS6,AS$4:AS$57)) | AU6: =IF(AS6>=75,"A1",IF(AS6>=70,"B2",IF(AS6>=65,"B3",IF(AS6>=60,"C4",IF(AS6>=55,"C5",IF(AS6>=50,"C6",IF(AS6>=45,"D7",IF(AS6>=40,"E8",IF(AS6>=6,"F",IF(AS6<5,"")))))))))) | AV6: =IF(AS6>=75,"Excellent",IF(AS6>=70,"V.Good",IF(AS6>=65,"Good",IF(AS6>=60,"Credit",IF(AS6>=55,"Credit",IF(AS6>=50,"Credit",IF(AS6>=45,"Pass",IF(AS6>=40,"Pass",IF(AS6>=6,"Fail",IF(AS6<5,"")))))))))) | AW6: 3 | AX6: =Data!B4 -> ALI MUHAMMED UMAR | BC6: =SUM(AY6:BB6) -> 0 | BE6: =BC6+BD6 -> 0 | BF6: =IF(BE6<10,"",RANK(BE6,BE$4:BE$57)) | BG6: =IF(BE6>=75,"A1",IF(BE6>=70,"B2",IF(BE6>=65,"B3",IF(BE6>=60,"C4",IF(BE6>=55,"C5",IF(BE6>=50,"C6",IF(BE6>=45,"D7",IF(BE6>=40,"E8",IF(BE6>=6,"F",IF(BE6<5,"")))))))))) | BH6: =IF(BE6>=75,"Excellent",IF(BE6>=70,"V.Good",IF(BE6>=65,"Good",IF(BE6>=60,"Credit",IF(BE6>=55,"Credit",IF(BE6>=50,"Credit",IF(BE6>=45,"Pass",IF(BE6>=40,"Pass",IF(BE6>=6,"Fail",IF(BE6<5,"")))))))))) | BI6: 3 | BJ6: =Data!B4 -> ALI MUHAMMED UMAR | BK6: 9 | BL6: 2 | BM6: 1 | BN6: 5 | BO6: =SUM(BK6:BN6) -> 17 | BP6: 42 | BQ6: =BO6+BP6 -> 59 | BR6: =IF(BQ6<10,"",RANK(BQ6,BQ$4:BQ$57)) -> 12 | BS6: =IF(BQ6>=75,"A1",IF(BQ6>=70,"B2",IF(BQ6>=65,"B3",IF(BQ6>=60,"C4",IF(BQ6>=55,"C5",IF(BQ6>=50,"C6",IF(BQ6>=45,"D7",IF(BQ6>=40,"E8",IF(BQ6>=6,"F",IF(BQ6<5,"")))))))))) -> C5 | BT6: =IF(BQ6>=75,"Excellent",IF(BQ6>=70,"V.Good",IF(BQ6>=65,"Good",IF(BQ6>=60,"Credit",IF(BQ6>=55,"Credit",IF(BQ6>=50,"Credit",IF(BQ6>=45,"Pass",IF(BQ6>=40,"Pass",IF(BQ6>=6,"Fail",IF(BQ6<5,"")))))))))) -> Credit | BU6: 3 | BV6: =Data!B4 -> ALI MUHAMMED UMAR | BW6: 6 | BX6: 4 | BY6: 8 | BZ6: 9 | CA6: =SUM(BW6:BZ6) -> 27 | CB6: 22 | CC6: =CA6+CB6 -> 49 | CD6: =IF(CC6<10,"",RANK(CC6,CC$4:CC$57)) -> 26 | CE6: =IF(CC6>=75,"A1",IF(CC6>=70,"B2",IF(CC6>=65,"B3",IF(CC6>=60,"C4",IF(CC6>=55,"C5",IF(CC6>=50,"C6",IF(CC6>=45,"D7",IF(CC6>=40,"E8",IF(CC6>=6,"F",IF(CC6<5,"")))))))))) -> D7 | CF6: =IF(CC6>=75,"Excellent",IF(CC6>=70,"V.Good",IF(CC6>=65,"Good",IF(CC6>=60,"Credit",IF(CC6>=55,"Credit",IF(CC6>=50,"Credit",IF(CC6>=45,"Pass",IF(CC6>=40,"Pass",IF(CC6>=6,"Fail",IF(CC6<5,"")))))))))) -> Pass | CG6: 3 | CH6: =Data!B4 -> ALI MUHAMMED UMAR | CM6: =SUM(CI6:CL6) -> 0 | CO6: =CM6+CN6 -> 0 | CP6: =IF(CO6<10,"",RANK(CO6,CO$4:CO$57)) | CQ6: =IF(CO6>=75,"A1",IF(CO6>=70,"B2",IF(CO6>=65,"B3",IF(CO6>=60,"C4",IF(CO6>=55,"C5",IF(CO6>=50,"C6",IF(CO6>=45,"D7",IF(CO6>=40,"E8",IF(CO6>=6,"F",IF(CO6<5,"")))))))))) | CR6: =IF(CO6>=75,"Excellent",IF(CO6>=70,"V.Good",IF(CO6>=65,"Good",IF(CO6>=60,"Credit",IF(CO6>=55,"Credit",IF(CO6>=50,"Credit",IF(CO6>=45,"Pass",IF(CO6>=40,"Pass",IF(CO6>=6,"Fail",IF(CO6<5,"")))))))))) | CS6: 3 | CT6: =Data!B4 -> ALI MUHAMMED UMAR | CY6: =SUM(CU6:CX6) -> 0 | DA6: =CY6+CZ6 -> 0 | DB6: =IF(DA6<10,"",RANK(DA6,DA$4:DA$57)) | DC6: =IF(DA6>=75,"A1",IF(DA6>=70,"B2",IF(DA6>=65,"B3",IF(DA6>=60,"C4",IF(DA6>=55,"C5",IF(DA6>=50,"C6",IF(DA6>=45,"D7",IF(DA6>=40,"E8",IF(DA6>=6,"F",IF(DA6<5,"")))))))))) | DD6: =IF(DA6>=75,"Excellent",IF(DA6>=70,"V.Good",IF(DA6>=65,"Good",IF(DA6>=60,"Credit",IF(DA6>=55,"Credit",IF(DA6>=50,"Credit",IF(DA6>=45,"Pass",IF(DA6>=40,"Pass",IF(DA6>=6,"Fail",IF(DA6<5,"")))))))))) | DE6: 3 | DF6: =Data!B4 -> ALI MUHAMMED UMAR | DG6: 2 | DH6: 1 | DI6: 2 | DJ6: 5 | DK6: =SUM(DG6:DJ6) -> 10 | DL6: 23 | DM6: =DK6+DL6 -> 33 | DN6: =IF(DM6<10,"",RANK(DM6,DM$4:DM$57)) -> 10 | DO6: =IF(DM6>=75,"A1",IF(DM6>=70,"B2",IF(DM6>=65,"B3",IF(DM6>=60,"C4",IF(DM6>=55,"C5",IF(DM6>=50,"C6",IF(DM6>=45,"D7",IF(DM6>=40,"E8",IF(DM6>=6,"F",IF(DM6<5,"")))))))))) -> F | DP6: =IF(DM6>=75,"Excellent",IF(DM6>=70,"V.Good",IF(DM6>=65,"Good",IF(DM6>=60,"Credit",IF(DM6>=55,"Credit",IF(DM6>=50,"Credit",IF(DM6>=45,"Pass",IF(DM6>=40,"Pass",IF(DM6>=6,"Fail",IF(DM6<5,"")))))))))) -> Fail | DQ6: 3 | DR6: =Data!B4 -> ALI MUHAMMED UMAR | DW6: =SUM(DS6:DV6) -> 0 | DY6: =DW6+DX6 -> 0 | DZ6: =IF(DY6<10,"",RANK(DY6,DY$4:DY$57)) | EA6: =IF(DY6>=75,"A1",IF(DY6>=70,"B2",IF(DY6>=65,"B3",IF(DY6>=60,"C4",IF(DY6>=55,"C5",IF(DY6>=50,"C6",IF(DY6>=45,"D7",IF(DY6>=40,"E8",IF(DY6>=6,"F",IF(DY6<5,"")))))))))) | EB6: =IF(DY6>=75,"Excellent",IF(DY6>=70,"V.Good",IF(DY6>=65,"Good",IF(DY6>=60,"Credit",IF(DY6>=55,"Credit",IF(DY6>=50,"Credit",IF(DY6>=45,"Pass",IF(DY6>=40,"Pass",IF(DY6>=6,"Fail",IF(DY6<5,"")))))))))) | EC6: 3 | ED6: =Data!B4 -> ALI MUHAMMED UMAR | EI6: =SUM(EE6:EH6) -> 0 | EK6: =EI6+EJ6 -> 0 | EL6: =IF(EK6<10,"",RANK(EK6,EK$4:EK$57)) | EM6: =IF(EK6>=75,"A1",IF(EK6>=70,"B2",IF(EK6>=65,"B3",IF(EK6>=60,"C4",IF(EK6>=55,"C5",IF(EK6>=50,"C6",IF(EK6>=45,"D7",IF(EK6>=40,"E8",IF(EK6>=6,"F",IF(EK6<5,"")))))))))) | EN6: =IF(EK6>=75,"Excellent",IF(EK6>=70,"V.Good",IF(EK6>=65,"Good",IF(EK6>=60,"Credit",IF(EK6>=55,"Credit",IF(EK6>=50,"Credit",IF(EK6>=45,"Pass",IF(EK6>=40,"Pass",IF(EK6>=6,"Fail",IF(EK6<5,"")))))))))) | EO6: 3 | EP6: =Data!B4 -> ALI MUHAMMED UMAR | EU6: =SUM(EQ6:ET6) -> 0 | EW6: =EU6+EV6 -> 0 | EX6: =IF(EW6<10,"",RANK(EW6,EW$4:EW$57)) | EY6: =IF(EW6>=75,"A1",IF(EW6>=70,"B2",IF(EW6>=65,"B3",IF(EW6>=60,"C4",IF(EW6>=55,"C5",IF(EW6>=50,"C6",IF(EW6>=45,"D7",IF(EW6>=40,"E8",IF(EW6>=6,"F",IF(EW6<5,"")))))))))) | EZ6: =IF(EW6>=75,"Excellent",IF(EW6>=70,"V.Good",IF(EW6>=65,"Good",IF(EW6>=60,"Credit",IF(EW6>=55,"Credit",IF(EW6>=50,"Credit",IF(EW6>=45,"Pass",IF(EW6>=40,"Pass",IF(EW6>=6,"Fail",IF(EW6<5,"")))))))))) | FA6: 3 | FB6: =Data!B4 -> ALI MUHAMMED UMAR | FG6: =SUM(FC6:FF6) -> 0 | FI6: =FG6+FH6 -> 0 | FJ6: =IF(FI6<10,"",RANK(FI6,FI$4:FI$57)) | FK6: =IF(FI6>=75,"A",IF(FI6>=70,"B2",IF(FI6>=50,"C",IF(FI6>=45,"D",IF(FI6>=40,"E",IF(FI6>=6,"F",IF(FI6<5,""))))))) | FL6: =IF(FI6>=75,"Excellent",IF(FI6>=70,"V.Good",IF(FI6>=65,"Good",IF(FI6>=60,"Credit",IF(FI6>=55,"Credit",IF(FI6>=50,"Credit",IF(FI6>=45,"Pass",IF(FI6>=40,"Pass",IF(FI6>=6,"Fail",IF(FI6<5,"")))))))))) | FM6: 3 | FN6: =Data!B4 -> ALI MUHAMMED UMAR | FS6: =SUM(FO6:FR6) -> 0 | FU6: =FS6+FT6 -> 0 | FV6: =IF(FU6<10,"",RANK(FU6,FU$4:FU$57)) | FW6: =IF(FU6>=75,"A",IF(FU6>=70,"B2",IF(FU6>=50,"C",IF(FU6>=45,"D",IF(FU6>=40,"E",IF(FU6>=6,"F",IF(FU6<5,""))))))) | FX6: =IF(FU6>=75,"Excellent",IF(FU6>=70,"V.Good",IF(FU6>=65,"Good",IF(FU6>=60,"Credit",IF(FU6>=55,"Credit",IF(FU6>=50,"Credit",IF(FU6>=45,"Pass",IF(FU6>=40,"Pass",IF(FU6>=6,"Fail",IF(FU6<5,"")))))))))) | FY6: 3 | FZ6: =Data!B4 -> ALI MUHAMMED UMAR | GA6: 7 | GB6: 7 | GC6: 8 | GD6: 8 | GE6: =SUM(GA6:GD6) -> 30 | GF6: 26 | GG6: =GE6+GF6 -> 56 | GH6: =IF(GG6<10,"",RANK(GG6,GG$4:GG$57)) -> 19 | GI6: =IF(GG6>=75,"A",IF(GG6>=70,"B2",IF(GG6>=50,"C",IF(GG6>=45,"D",IF(GG6>=40,"E",IF(GG6>=6,"F",IF(GG6<5,""))))))) -> C | GJ6: =IF(GG6>=75,"Excellent",IF(GG6>=70,"V.Good",IF(GG6>=65,"Good",IF(GG6>=60,"Credit",IF(GG6>=55,"Credit",IF(GG6>=50,"Credit",IF(GG6>=45,"Pass",IF(GG6>=40,"Pass",IF(GG6>=6,"Fail",IF(GG6<5,"")))))))))) -> Credit | GK6: 3 | GL6: =Data!B4 -> ALI MUHAMMED UMAR | GQ6: =SUM(GM6:GP6) -> 0 | GS6: =GQ6+GR6 -> 0 | GT6: =IF(GS6<10,"",RANK(GS6,GS$4:GS$57)) | GU6: =IF(GS6>=75,"A",IF(GS6>=70,"B2",IF(GS6>=50,"C",IF(GS6>=45,"D",IF(GS6>=40,"E",IF(GS6>=6,"F",IF(GS6<5,""))))))) | GV6: =IF(GS6>=75,"Excellent",IF(GS6>=70,"V.Good",IF(GS6>=65,"Good",IF(GS6>=60,"Credit",IF(GS6>=55,"Credit",IF(GS6>=50,"Credit",IF(GS6>=45,"Pass",IF(GS6>=40,"Pass",IF(GS6>=6,"Fail",IF(GS6<5,"")))))))))) | GW6: 3 | GX6: =Data!B4 -> ALI MUHAMMED UMAR | HC6: =SUM(GY6:HB6) -> 0 | HE6: =HC6+HD6 -> 0 | HF6: =IF(HE6<10,"",RANK(HE6,HE$4:HE$57)) | HG6: =IF(HE6>=75,"A",IF(HE6>=70,"B2",IF(HE6>=50,"C",IF(HE6>=45,"D",IF(HE6>=40,"E",IF(HE6>=6,"F",IF(HE6<5,""))))))) | HH6: =IF(HE6>=75,"Excellent",IF(HE6>=70,"V.Good",IF(HE6>=65,"Good",IF(HE6>=60,"Credit",IF(HE6>=55,"Credit",IF(HE6>=50,"Credit",IF(HE6>=45,"Pass",IF(HE6>=40,"Pass",IF(HE6>=6,"Fail",IF(HE6<5,"")))))))))) | HI6: 3 | HJ6: =Data!B4 -> ALI MUHAMMED UMAR | HO6: =SUM(HK6:HN6) -> 0 | HQ6: =HO6+HP6 -> 0 | HR6: =IF(HQ6<10,"",RANK(HQ6,HQ$4:HQ$57)) | HS6: =IF(HQ6>=75,"A",IF(HQ6>=70,"B2",IF(HQ6>=50,"C",IF(HQ6>=45,"D",IF(HQ6>=40,"E",IF(HQ6>=6,"F",IF(HQ6<5,""))))))) | HT6: =IF(HQ6>=75,"Excellent",IF(HQ6>=70,"V.Good",IF(HQ6>=65,"Good",IF(HQ6>=60,"Credit",IF(HQ6>=55,"Credit",IF(HQ6>=50,"Credit",IF(HQ6>=45,"Pass",IF(HQ6>=40,"Pass",IF(HQ6>=6,"Fail",IF(HQ6<5,"")))))))))) | HU6: 3 | HV6: =Data!B4 -> ALI MUHAMMED UMAR | IA6: =SUM(HW6:HZ6) -> 0 | IC6: =IA6+IB6 -> 0 | ID6: =IF(IC6<10,"",RANK(IC6,IC$4:IC$57)) | IE6: =IF(IC6>=75,"A",IF(IC6>=70,"B2",IF(IC6>=50,"C",IF(IC6>=45,"D",IF(IC6>=40,"E",IF(IC6>=6,"F",IF(IC6<5,""))))))) | IF6: =IF(IC6>=75,"Excellent",IF(IC6>=70,"V.Good",IF(IC6>=65,"Good",IF(IC6>=60,"Credit",IF(IC6>=55,"Credit",IF(IC6>=50,"Credit",IF(IC6>=45,"Pass",IF(IC6>=40,"Pass",IF(IC6>=6,"Fail",IF(IC6<5,"")))))))))) | IG6: 3 | IH6: =Data!B4 -> ALI MUHAMMED UMAR | IM6: =SUM(II6:IL6) -> 0 | IO6: =IM6+IN6 -> 0 | IP6: =IF(IO6<10,"",RANK(IO6,IO$4:IO$57)) | IQ6: =IF(IO6>=75,"A",IF(IO6>=70,"B2",IF(IO6>=50,"C",IF(IO6>=45,"D",IF(IO6>=40,"E",IF(IO6>=6,"F",IF(IO6<5,""))))))) | IR6: =IF(IO6>=75,"Excellent",IF(IO6>=70,"V.Good",IF(IO6>=65,"Good",IF(IO6>=60,"Credit",IF(IO6>=55,"Credit",IF(IO6>=50,"Credit",IF(IO6>=45,"Pass",IF(IO6>=40,"Pass",IF(IO6>=6,"Fail",IF(IO6<5,"")))))))))) | IS6: 3 | IT6: =IH6 -> ALI MUHAMMED UMAR | IU6: 9 | IV6: 2 | IW6: 1 | IX6: 5 | IY6: =SUM(IU6:IX6) -> 17 | IZ6: 42 | JA6: =IY6+IZ6 -> 59 | JB6: =IF(JA6<10,"",RANK(JA6,JA$4:JA$57)) -> 12 | JC6: =IF(JA6>=75,"A",IF(JA6>=70,"B2",IF(JA6>=50,"C",IF(JA6>=45,"D",IF(JA6>=40,"E",IF(JA6>=6,"F",IF(JA6<5,""))))))) -> C | JD6: =IF(JA6>=75,"Excellent",IF(JA6>=70,"V.Good",IF(JA6>=65,"Good",IF(JA6>=60,"Credit",IF(JA6>=55,"Credit",IF(JA6>=50,"Credit",IF(JA6>=45,"Pass",IF(JA6>=40,"Pass",IF(JA6>=6,"Fail",IF(JA6<5,"")))))))))) -> Credit | JE6: 3 | JF6: =IT6 -> ALI MUHAMMED UMAR | JK6: =SUM(JG6:JJ6) -> 0 | JM6: =JK6+JL6 -> 0 | JN6: =IF(JM6<10,"",RANK(JM6,JM$4:JM$57)) | JO6: =IF(JM6>=75,"A",IF(JM6>=70,"B2",IF(JM6>=50,"C",IF(JM6>=45,"D",IF(JM6>=40,"E",IF(JM6>=6,"F",IF(JM6<5,""))))))) | JP6: =IF(JM6>=75,"Excellent",IF(JM6>=70,"V.Good",IF(JM6>=65,"Good",IF(JM6>=60,"Credit",IF(JM6>=55,"Credit",IF(JM6>=50,"Credit",IF(JM6>=45,"Pass",IF(JM6>=40,"Pass",IF(JM6>=6,"Fail",IF(JM6<5,"")))))))))) | JQ6: 3 | JR6: =JF6 -> ALI MUHAMMED UMAR | JW6: =SUM(JS6:JV6) -> 0 | JY6: =JW6+JX6 -> 0 | JZ6: =IF(JY6<10,"",RANK(JY6,JY$4:JY$57)) | KA6: =IF(JY6>=75,"A",IF(JY6>=70,"B2",IF(JY6>=50,"C",IF(JY6>=45,"D",IF(JY6>=40,"E",IF(JY6>=6,"F",IF(JY6<5,""))))))) | KB6: =IF(JY6>=75,"Excellent",IF(JY6>=70,"V.Good",IF(JY6>=65,"Good",IF(JY6>=60,"Credit",IF(JY6>=55,"Credit",IF(JY6>=50,"Credit",IF(JY6>=45,"Pass",IF(JY6>=40,"Pass",IF(JY6>=6,"Fail",IF(JY6<5,""))))))))))
