Workbook

Sheet Data
A1: Admission_No | B1: Names | C1: Class | D1: Age | E1: State of Origin | F1: LGA | G1: Term | H1: Next Term Begins | I1: Password | J1: Email
A2: 1 | B2: AL HASSAN KHALID MUH'D | C2: JSS1 A | D2: 11 | E2: BORNO | F2: MMC | G2: 2nd | H2: 16th January, 2026 | I2: 1111 | J2: aishatuhassan233@gmail.com
A3: 2 | B3: ABATCHA MOHAMMED M. | C3: JSS1 A | D3: 13 | E3: BORNO | F3: NGALA | G3: 2nd | H3: 16th January, 2026 | I3: 1111 | J3: kuburagana@gmail.com
A4: 3 | B4: ABDULKUDUS DAUDA YUSUF | C4: JSS1 A | D4: 11 | E4: YOBE | F4: NGURU | G4: 2nd | H4: 16th January, 2026 | I4: 1111 | J4: mulikat606@gmail.com
A5: 4 | B5: DARIUS DANJUMA | C5: JSS1 A | D5: 12 | E5: BORNO | F5: BIU | G5: 2nd | H5: 16th January, 2026 | I5: 1111 | J5: danjumdanalami@gmail.com
A6: 5 | B6: EZEKIEL DAVID ABANA | C6: JSS1 A | D6: 11 | E6: BORNO | F6: CHIBOK | G6: 2nd | H6: 16th January, 2026 | I6: 1111 | J6: daudaabana645@gmail.com
A7: 6 | B7: ELIJAH EPHRAIM HAGIN | C7: JSS1 A | D7: 10 | E7: BORNO | F7: HAWUL | G7: 2nd | H7: 16th January, 2026 | I7: 1111 | J7: zeelijah277@gmail.com
A8: 7 | B8: IBRAHIM ABDULLAHI HASHIM | C8: JSS1 A | D8: 13 | E8: BORNO | F8: MMC | G8: 2nd | H8: 16th January, 2026 | I8: 1111 | J8: alhabdulkli@gmail.com
A9: 8 | B9: MOHAMMED MARTE | C9: JSS1 A | D9: 11 | E9: BORNO | F9: BADRUM | G9: 2nd | H9: 16th January, 2026 | I9: 1111 | J9: muhammadamarte54@gmail.com
A10: 9 | B10: MUHAMMAD BABAGANA M. | C10: JSS1 A | D10: 12 | E10: BORNO | F10: MMC | G10: 2nd | H10: 16th January, 2026 | I10: 1111 | J10: bgmammami10@gmail.com
A11: 10 | B11: MUHAMMED MODUYE | C11: JSS1 A | D11: 12 | E11: BORNO | F11: MMC | G11: 2nd | H11: 16th January, 2026 | I11: 1111 | J11: zaramuhammad@gmail.com
A12: 11 | B12: MUHAMMED M RABIU | C12: JSS1 A | D12: 11 | E12: BORNO | F12: BIU | G12: 2nd | H12: 16th January, 2026 | I12: 1111 | J12: rabiu3030@gmail.com
A13: 12 | B13: FATIMA ABDULRAZAK KADI | C13: JSS1 A | G13: 2nd | H13: 16th January, 2026 | I13: 1111 | J13: arikbik2010@gmail.com
A14: 13 | B14: SADIQ BUKAR ALLAU | C14: JSS1 A | D14: 11 | E14: BORNO | F14: KUNDUGA | G14: 2nd | H14: 16th January, 2026 | I14: 1111 | J14: musbuk2012@gmail.com
A15: 14 | B15: USMAN MUHAMMED USMAN | C15: JSS1 A | D15: 11 | E15: BORNO | F15: MMC | G15: 2nd | H15: 16th January, 2026 | I15: 1111 | J15: muhammadusman6969@gmail.com
A16: 15 | B16: ABUBAKAR AHMED HADIZA | C16: JSS1 A | D16: 12 | E16: BORNO | F16: JERE | G16: 2nd | H16: 16th January, 2026 | I16: 1111 | J16: ahmedabubakarglobalventures@gmail.com
A17: 16 | B17: ABDULHAMID AISHA | C17: JSS1 A | D17: 11 | E17: BORNO | F17: JERE | G17: 2nd | H17: 16th January, 2026 | I17: 1111 | J17: amaaluminium@gmail.com
A18: 17 | B18: BUKAR MUHAMMED HAUWA | C18: JSS1 A | D18: 13 | E18: BORNO | F18: NGANZAI | G18: 2nd | H18: 16th January, 2026 | I18: 1111 | J18: alargemb@gmail.com
A19: 18 | B19: BALLAMA MUH'D HALIMA | C19: JSS1 A | D19: 11 | E19: BORNO | F19: DIKWA | G19: 2nd | H19: 16th January, 2026 | I19: 1111 | J19: mbj5643@gmail.com
A20: 19 | B20: HALIM ALHAJI MAI | C20: JSS1 A | D20: 12 | E20: BORNO | F20: ASKIRA/UBA | G20: 2nd | H20: 16th January, 2026 | I20: 1111 | J20: alhajimai@gmail.com
A21: 20 | B21: JAMIMA JOHN JOSEPH | C21: JSS1 A | D21: 11 | E21: PLATEAU | F21: KANKE | G21: 2nd | H21: 16th January, 2026 | I21: 1111 | J21: helensunday135@gmail.com
A22: 21 | B22: JAFIDA MICHAEL PAPKA | C22: JSS1 A | D22: 11 | E22: BORNO | F22: ASKIRA/UBA | G22: 2nd | H22: 16th January, 2026 | I22: 1111 | J22: papkamichael2017@gmail.com
A23: 22 | B23: LUJAIN ADAMU ISAH | C23: JSS1 A | D23: 10 | E23: BORNO | F23: BIU | G23: 2nd | H23: 16th January, 2026 | I23: 1111 | J23: adamuisa2006@gmail.com
A24: 23 | B24: KABIR LUKMAN ZULAIKA | C24: JSS1 A | D24: 12 | E24: LAGOS | F24: IKORODU | G24: 2nd | H24: 16th January, 2026 | I24: 1111 | J24: lukmansholakabir@gmail.com
A25: 24 | B25: KALTUM ABBA AJIKOLO | C25: JSS1 A | D25: 11 | E25: BORNO | F25: MMC | G25: 2nd | H25: 16th January, 2026 | I25: 1111 | J25: hauwaalisadiq@gmail.com
... A40: 39 | B40: JAMES EMMANUEL | C40: JSS1 A | D40: 11 | E40: BORNO | F40: GWOZA | G40: 2nd | H40: 16th January, 2026 | I40: 1111 | J40: jtalake@gmail.com
A41: 40 | B41: FAVOUR SHANNA M. | C41: JSS1 A | D41: 11 | E41: BORNO | F41: HAWUL | G41: 2nd | H41: 16th January, 2026 | I41: 1111
A42: 41 | B42: ISHAQ MUHAMMED NUR | C42: JSS1 A | D42: 12 | E42: BORNO | F42: JERE | G42: 2nd | H42: 17th January, 2026 | I42: 1111

Sheet Comments
A1: Admission_No | B1: Comments | C1: Position of authourity
A2: 1 | B2: Calm and obedient | C2: Nil
A3: 2 | B3: Calm and obedient | C3: Board master
A4: 3 | B4: Calm and obedient | C4: Nil
A5: 4 | B5: Calm and obedient | C5: Nil
A6: 5 | B6: Calm and obedient | C6: Nil
A7: 6 | B7: Calm and obedient | C7: Nil
A8: 7 | B8: Calm and obedient | C8: Nil
A9: 8 | B9: Calm and obedient | C9: Nil
A10: 9 | B10: Calm and obedient | C10: Nil
A11: 10 | B11: Intelligent but quite playful | C11: Nil
A12: 11 | B12: Calm and obedient | C12: Nil
A13: 12 | B13: Calm and obedient | C13: Nil
... A41: 40 | B41: Calm and obedient | C41: Nil

Sheet Behaviour
A1: Admission_No | B1: Puntuality | C1: Attendance in class | D1: Neatness | E1: Politeness | F1: Honesty | G1: Attentiveness | H1: Obedience | I1: Self Control
A2: 1 | B2: 3 | C2: 5 | D2: 3 | E2: 3 | F2: 2 | G2: 3 | H2: 2 | I2: 4
A3: 2 | B3: 3 | C3: 5 | D3: 3 | E3: 3 | F3: 2 | G3: 4 | H3: 2 | I3: 4
A4: 3 | B4: 3 | C4: 5 | D4: 3 | E4: 3 | F4: 2 | G4: 3 | H4: 2 | I4: 4
A5: 4 | B5: 3 | C5: 5 | D5: 3 | E5: 3 | F5: 2 | G5: 4 | H5: 2 | I5: 4
A6: 5 | B6: 3 | C6: 5 | D6: 3 | E6: 3 | F6: 2 | G6: 4 | H6: 2 | I6: 4
A7: 6 | B7: 3 | C7: 5 | D7: 3 | E7: 3 | F7: 2 | G7: 4 | H7: 2 | I7: 4
A8: 7 | B8: 2 | C8: 5 | D8: 3 | E8: 3 | F8: 2 | G8: 3 | H8: 2 | I8: 4
A9: 8 | B9: 3 | C9: 5 | D9: 3 | E9: 3 | F9: 2 | G9: 4 | H9: 2 | I9: 4
A10: 9 | B10: 3 | C10: 5 | D10: 3 | E10: 3 | F10: 2 | G10: 3 | H10: 2 | I10: 4
A11: 10 | B11: 4 | C11: 5 | D11: 3 | E11: 3 | F11: 2 | G11: 3 | H11: 2 | I11: 4
A12: 11 | B12: 4 | C12: 3 | D12: 3 | E12: 3 | F12: 2 | G12: 4 | H12: 2 | I12: 4
A13: 12 | B13: 2 | C13: 5 | D13: 3 | E13: 3 | F13: 2 | G13: 4 | H13: 2 | I13: 4
... A41: 40 | B41: 4 | C41: 5 | D41: 3 | E41: 3 | F41: 2 | G41: 4 | H41: 2 | I41: 4
B42: 3 | C42: 5 | D42: 3 | E42: 3 | F42: 2 | G42: 4 | H42: 2 | I42: 4
B43: 4 | C43: 5 | D43: 3 | E43: 3 | F43: 2 | G43: 4 | H43: 2 | I43: 4
B44: 3 | C44: 5 | D44: 3 | E44: 3 | F44: 2 | G44: 4 | H44: 2 | I44: 4
B45: 3 | C45: 5 | D45: 3 | E45: 3 | F45: 2 | G45: 4 | H45: 2 | I45: 4
B46: 4 | C46: 5 | D46: 3 | E46: 3 | F46: 2 | G46: 4 | H46: 2 | I46: 4
B47: 4 | C47: 5 | D47: 3 | E47: 3 | F47: 2 | G47: 4 | H47: 2 | I47: 4
B48: 4 | C48: 5 | D48: 3 | E48: 3 | F48: 2 | G48: 4 | H48: 2 | I48: 4
B49: 4 | C49: 5 | D49: 3 | E49: 3 | F49: 2 | G49: 4 | H49: 2 | I49: 4
B50: 4 | C50: 5 | D50: 3 | E50: 3 | F50: 2 | G50: 4 | H50: 2 | I50: 4
B51: 4 | C51: 5 | D51: 3 | E51: 3 | F51: 2 | G51: 4 | H51: 2 | I51: 4

Sheet Skills
A1: Admission_No | B1: Handwriting | C1: Musical Skill | D1: Craft | E1: Games | F1: Fluency
A2: 1 | B2: 4 | C2: 3 | D2: 3 | E2: 5 | F2: 3
A3: 2 | B3: 3 | C3: 3 | D3: 3 | E3: 5 | F3: 3
A4: 3 | B4: 4 | C4: 3 | D4: 3 | E4: 5 | F4: 3
A5: 4 | B5: 4 | C5: 3 | D5: 3 | E5: 5 | F5: 3
A6: 5 | B6: 4 | C6: 3 | D6: 3 | E6: 5 | F6: 3
A7: 6 | B7: 4 | C7: 3 | D7: 3 | E7: 5 | F7: 3
A8: 7 | B8: 3 | C8: 3 | D8: 3 | E8: 5 | F8: 3
A9: 8 | B9: 4 | C9: 3 | D9: 3 | E9: 5 | F9: 3
A10: 9 | B10: 4 | C10: 3 | D10: 3 | E10: 5 | F10: 3
A11: 10 | B11: 4 | C11: 3 | D11: 3 | E11: 5 | F11: 3
A12: 11 | B12: 3 | C12: 3 | D12: 3 | E12: 5 | F12: 3
A13: 12 | B13: 4 | C13: 3 | D13: 3 | E13: 5 | F13: 3
... A41: 40 | B41: 4 | C41: 3 | D41: 3 | E41: 5 | F41: 3
B42: 4 | C42: 3 | D42: 3 | E42: 5 | F42: 3
B43: 4 | C43: 3 | D43: 3 | E43: 5 | F43: 3
B44: 4 | C44: 3 | D44: 3 | E44: 5 | F44: 3
B45: 4 | C45: 5 | D45: 3 | E45: 5 | F45: 3
B46: 4 | C46: 5 | D46: 3 | E46: 5 | F46: 3
B47: 4 | C47: 5 | D47: 3 | E47: 5 | F47: 3
B48: 4 | C48: 5 | D48: 3 | E48: 5 | F48: 3
B49: 4 | C49: 3 | D49: 3 | E49: 5 | F49: 3
B50: 4 | C50: 3 | D50: 3 | E50: 5 | F50: 3
B51: 4 | C51: 3 | D51: 3 | E51: 5 | F51: 3

Sheet Scoresheet
C1: English | K1: MATHEMATICS | S1: Basic Technology | AD1: C.R.K. | AL1: Social Studies | AT1: Agric Science | BB1: Basic Science | BJ1: Business Studies | BR1: Computer Science | BZ1: Home Economics | CH1: P.H.E. | CP1: Fine Art | CX1: French | DF1: Hausa | DN1: Civic Education | DV1: Literature | ED1: History | EL1: I.R.K.
A2: Admission_No | B2: Names | C2: 1st C. A. | D2: 2st C. A. | E2: 3st C. A. | F2: 4st C. A. | G2: Total C. A. | H2: Exam | I2: Total | K2: 1st C. A. | L2: 2st C. A. | M2: 3st C. A. | N2: 4st C. A. | O2: Total C. A. | P2: Exam | Q2: Total | S2: 1st C. A. | T2: 2st C. A. | U2: 3st C. A. | V2: 4st C. A. | W2: Total C. A. | X2: Exam | Y2: Total | Z2: Position | AA2: Grade | AB2: Teacher's Comment | AD2: 1st C. A. | AE2: 2st C. A. | AF2: 3st C. A. | AG2: 4st C. A. | AH2: Total C. A. | AI2: Exam | AJ2: Total | AL2: 1st C. A. | AM2: 2st C. A. | AN2: 3st C. A. | AO2: 4st C. A. | AP2: Total C. A. | AQ2: Exam | AR2: Total | AT2: 1st C. A. | AU2: 2st C. A. | AV2: 3st C. A. | AW2: 4st C. A. | AX2: Total C. A. | AY2: Exam | AZ2: Total | BB2: 1st C. A. | BC2: 2st C. A. | BD2: 3st C. A. | BE2: 4st C. A. | BF2: Total C. A. | BG2: Exam | BH2: Total | BJ2: 1st C. A. | BK2: 2st C. A. | BL2: 3st C. A. | BM2: 4st C. A. | BN2: Total C. A. | BO2: Exam | BP2: Total | BR2: 1st C. A. | BS2: 2st C. A. | BT2: 3st C. A. | BU2: 4st C. A. | BV2: Total C. A. | BW2: Exam | BX2: Total | BZ2: 1st C. A. | CA2: 2st C. A. | CB2: 3st C. A. | CC2: 4st C. A. | CD2: Total C. A. | CE2: Exam | CF2: Total | CH2: 1st C. A. | CI2: 2st C. A. | CJ2: 3st C. A. | CK2: 4st C. A. | CL2: Total C. A. | CM2: Exam | CN2: Total | CP2: 1st C. A. | CQ2: 2st C. A. | CR2: 3st C. A. | CS2: 4st C. A. | CT2: Total C. A. | CU2: Exam | CV2: Total | CX2: 1st C. A. | CY2: 2st C. A. | CZ2: 3st C. A. | DA2: 4st C. A. | DB2: Total C. A. | DC2: Exam | DD2: Total | DF2: 1st C. A. | DG2: 2st C. A. | DH2: 3st C. A. | DI2: 4st C. A. | DJ2: Total C. A. | DK2: Exam | DL2: Total | DN2: 1st C. A. | DO2: 2st C. A. | DP2: 3st C. A. | DQ2: 4st C. A. | DR2: Total C. A. | DS2: Exam | DT2: Total | DV2: 1st C. A. | DW2: 2st C. A. | DX2: 3st C. A. | DY2: 4st C. A. | DZ2: Total C. A. | EA2: Exam | EB2: Total | ED2: 1st C. A. | EE2: 2st C. A. | EF2: 3st C. A. | EG2: 4st C. A. | EH2: Total C. A. | EI2: Exam | EJ2: Total | EL2: 1st C. A. | EM2: 2st C. A. | EN2: 3st C. A. | EO2: 4st C. A. | EP2: Total C. A. | EQ2: Exam | ER2: Total
A3: 1 | B3: AL HASSAN KHALID MUH'D | C3: 5 | D3: 5 | E3: 9 | F3: 10 | G3: =SUM(C3:F3) -> 29 | H3: 26 | I3: =G3+H3 -> 55 | K3: 3 | L3: 8 | M3: 10 | N3: 10 | O3: =SUM(K3:N3) -> 31 | P3: 26 | Q3: =O3+P3 -> 57 | S3: 5 | T3: 3 | U3: 5 | V3: 6 | W3: =SUM(S3:V3) -> 19 | X3: 30 | Y3: =W3+X3 -> 49 | Z3: =IF(Y3<10,"",RANK(Y3,Y$3:Y$52)) -> 29 | AA3: =IF(Y3>=70,"A",IF(Y3>=50,"C",IF(Y3>=45,"P",IF(Y3>=6,"F",IF(Y3<5,""))))) -> P | AB3: =IF(Y3>=70,"Excellent",IF(Y3>=50,"Credit",IF(Y3>=45,"Pass",IF(Y3>=6,"Fail",IF(Y3<5,""))))) -> Pass | AH3: =SUM(AD3:AG3) -> 0 | AJ3: =AH3+AI3 -> 0 | AL3: 1 | AM3: 3 | AN3: 8 | AO3: 8 | AP3: =SUM(AL3:AO3) -> 20 | AQ3: 21 | AR3: =AP3+AQ3 -> 41 | AT3: 1 | AU3: 1 | AV3: 10 | AW3: 9 | AX3: 21 | AY3: 19 | AZ3: 40 | BB3: 4 | BC3: 0 | BD3: 7 | BE3: 4 | BF3: 15 | BG3: 38 | BH3: 53 | BJ3: 6 | BK3: 5 | BL3: 10 | BM3: 10 | BN3: 31 | BO3: 14 | BP3: 45 | BR3: 8 | BS3: 2 | BT3: 7 | BU3: 10 | BV3: 27 | BW3: 31 | BX3: 58 | BZ3: 3 | CA3: 8 | CB3: 10 | CC3: 10 | CD3: 31 | CE3: 29 | CF3: 60 | CH3: 1 | CI3: 2 | CJ3: 10 | CK3: 10 | CL3: 23 | CM3: 23 | CN3: 46 | CP3: 7 | CQ3: 2 | CR3: 10 | CS3: 8 | CT3: 27 | CU3: 29 | CV3: 56 | CX3: 3 | CY3: 3 | CZ3: 10 | DA3: 10 | DB3: 26 | DC3: 22 | DD3: 48 | DF3: 5 | DG3: 6 | DH3: 3 | DI3: 10 | DJ3: 24 | DK3: 41 | DL3: 65 | DN3: 6 | DO3: 2 | DP3: 4 | DQ3: 5 | DR3: 17 | DS3: 14 | DT3: 31 | DV3: 4 | DW3: 3 | DX3: 8 | DY3: 10 | DZ3: 25 | EA3: 22 | EB3: 47 | ED3: 4 | EE3: 4 | EF3: 9 | EG3: 10 | EH3: 27 | EI3: 31 | EJ3: 58 | EL3: 5 | EM3: 4 | EN3: 10 | EO3: 10 | EP3: 29 | EQ3: 24 | ER3: 53
A4: 2 | B4: ABATCHA MOHAMMED M. | C4: 2 | D4: 4 | E4: 8 | F4: 9 | G4: =SUM(C4:F4) -> 23 | H4: 14 | I4: =G4+H4 -> 37 | K4: 3 | L4: 5 | M4: 10 | N4: 10 | O4: =SUM(K4:N4) -> 28 | P4: 31 | Q4: =O4+P4 -> 59 | S4: 7 | T4: 4 | U4: 5 | V4: 5 | W4: =SUM(S4:V4) -> 21 | X4: 26 | Y4: =W4+X4 -> 47 | Z4: =IF(Y4<10,"",RANK(Y4,Y$3:Y$52)) -> 31 | AA4: =IF(Y4>=70,"A",IF(Y4>=50,"C",IF(Y4>=45,"P",IF(Y4>=6,"F",IF(Y4<5,""))))) -> P | AB4: =IF(Y4>=70,"Excellent",IF(Y4>=50,"Credit",IF(Y4>=45,"Pass",IF(Y4>=6,"Fail",IF(Y4<5,""))))) -> Pass | AH4: =SUM(AD4:AG4) -> 0 | AJ4: =AH4+AI4 -> 0 | AL4: 1 | AM4: 1 | AN4: 8 | AO4: 8 | AP4: =SUM(AL4:AO4) -> 18 | AQ4: 22 | AR4: =AP4+AQ4 -> 40 | AT4: 1 | AU4: 1 | AV4: 5 | AW4: 4 | AX4: 11 | AY4: 13 | AZ4: 24 | BB4: 3 | BC4: 2 | BD4: 3 | BE4: 2 | BF4: 10 | BG4: 31 | BH4: 41 | BJ4: 4 | BK4: 6 | BL4: 8 | BM4: 10 | BN4: 28 | BO4: 22 | BP4: 50 | BR4: 3 | BS4: 4 | BT4: 7 | BU4: 10 | BV4: 24 | BW4: 20 | BX4: 44 | BZ4: 3 | CA4: 3 | CB4: 8 | CC4: 6 | CD4: 20 | CE4: 27 | CF4: 47 | CH4: 2 | CI4: 2 | CJ4: 5 | CK4: 10 | CL4: 19 | CM4: 22 | CN4: 41 | CP4: 5 | CQ4: 1 | CR4: 7 | CS4: 6 | CT4: 19 | CU4: 20 | CV4: 39 | CX4: 3 | CY4: 5 | CZ4: 9 | DA4: 10 | DB4: 27 | DC4: 17 | DD4: 44 | DF4: 4 | DG4: 2 | DH4: 8 | DI4: 9 | DJ4: 23 | DK4: 31 | DL4: 54 | DN4: 1 | DO4: 1 | DP4: 4 | DQ4: 6 | DR4: 12 | DS4: 9 | DT4: 21 | DV4: 2 | DW4: 2 | DX4: 7 | DY4: 10 | DZ4: 21 | EA4: 22 | EB4: 43 | ED4: 5 | EE4: 2 | EF4: 10 | EG4: 10 | EH4: 27 | EI4: 15 | EJ4: 42 | EL4: 9 | EM4: 2 | EP4: 11 | EQ4: 23 | ER4: 34
A5: 3 | B5: ABDULKUDUS DAUDA YUSUF | C5: 3 | D5: 5 | E5: 10 | F5: 10 | G5: =SUM(C5:F5) -> 28 | H5: 26 | I5: =G5+H5 -> 54 | K5: 9 | L5: 3 | M5: 10 | N5: 10 | O5: =SUM(K5:N5) -> 32 | P5: 29 | Q5: =O5+P5 -> 61 | S5: 9 | T5: 5 | U5: 5 | V5: 9 | W5: =SUM(S5:V5) -> 28 | X5: 30 | Y5: =W5+X5 -> 58 | Z5: =IF(Y5<10,"",RANK(Y5,Y$3:Y$52)) -> 19 | AA5: =IF(Y5>=70,"A",IF(Y5>=50,"C",IF(Y5>=45,"P",IF(Y5>=6,"F",IF(Y5<5,""))))) -> C | AB5: =IF(Y5>=70,"Excellent",IF(Y5>=50,"Credit",IF(Y5>=45,"Pass",IF(Y5>=6,"Fail",IF(Y5<5,""))))) -> Credit | AH5: =SUM(AD5:AG5) -> 0 | AJ5: =AH5+AI5 -> 0 | AL5: 1 | AM5: 9 | AN5: 8 | AO5: 7 | AP5: =SUM(AL5:AO5) -> 25 | AQ5: 16 | AR5: =AP5+AQ5 -> 41 | AT5: 1 | AU5: 5 | AV5: 10 | AW5: 8 | AX5: 24 | AY5: 27 | AZ5: 51 | BB5: 6 | BC5: 7 | BD5: 7 | BE5: 8 | BF5: 28 | BG5: 40 | BH5: 68 | BJ5: 8 | BK5: 7 | BL5: 8 | BM5: 8 | BN5: 31 | BO5: 32 | BP5: 63 | BR5: 8 | BS5: 9 | BT5: 10 | BU5: 10 | BV5: 37 | BW5: 25 | BX5: 62 | BZ5: 8 | CA5: 8 | CB5: 10 | CC5: 10 | CD5: 36 | CE5: 39 | CF5: 75 | CH5: 3 | CI5: 6 | CJ5: 8 | CK5: 10 | CL5: 27 | CM5: 38 | CN5: 65 | CP5: 7 | CQ5: 3 | CR5: 10 | CS5: 8 | CT5: 28 | CU5: 27 | CV5: 55 | CX5: 4 | CY5: 2 | CZ5: 10 | DA5: 9 | DB5: 25 | DC5: 20 | DD5: 45 | DF5: 5 | DG5: 3 | DH5: 1 | DI5: 10 | DJ5: 19 | DK5: 42 | DL5: 61 | DN5: 6 | DO5: 8 | DP5: 6 | DQ5: 10 | DR5: 30 | DS5: 21 | DT5: 51 | DV5: 5 | DW5: 5 | DX5: 10 | DY5: 10 | DZ5: 30 | EA5: 28 | EB5: 58 | ED5: 5 | EE5: 7 | EF5: 10 | EG5: 10 | EH5: 32 | EI5: 45 | EJ5: 77 | EL5: 7 | EM5: 1 | EN5: 10 | EO5: 10 | EP5: 28 | EQ5: 27 | ER5: 55
A6: 4 | B6: DARIUS DANJUMA | C6: 3 | E6: 8 | F6: 8 | G6: =SUM(C6:F6) -> 19 | H6: 16 | I6: =G6+H6 -> 35 | K6: 1 | L6: 1 | M6: 10 | N6: 10 | O6: =SUM(K6:N6) -> 22 | P6: 15 | Q6: =O6+P6 -> 37 | S6: 7 | T6: 2 | U6: 5 | V6: 5 | W6: =SUM(S6:V6) -> 19 | X6: 16 | Y6: =W6+X6 -> 35 | Z6: =IF(Y6<10,"",RANK(Y6,Y$3:Y$52)) -> 37 | AA6: =IF(Y6>=70,"A",IF(Y6>=50,"C",IF(Y6>=45,"P",IF(Y6>=6,"F",IF(Y6<5,""))))) -> F | AB6: =IF(Y6>=70,"Excellent",IF(Y6>=50,"Credit",IF(Y6>=45,"Pass",IF(Y6>=6,"Fail",IF(Y6<5,""))))) -> Fail | AD6: 1 | AE6: 1 | AF6: 1 | AG6: 2 | AH6: =SUM(AD6:AG6) -> 5 | AI6: 14 | AJ6: =AH6+AI6 -> 19 | AL6: 1 | AM6: 1 | AN6: 7 | AO6: 8 | AP6: =SUM(AL6:AO6) -> 17 | AQ6: 6 | AR6: =AP6+AQ6 -> 23 | AT6: 1 | AU6: 1 | AV6: 5 | AW6: 4 | AX6: 11 | AY6: 18 | AZ6: 29 | BB6: 1 | BD6: 2 | BE6: 4 | BF6: 7 | BG6: 12 | BH6: 19 | BJ6: 3 | BL6: 8 | BM6: 9 | BN6: 20 | BO6: 14 | BP6: 34 | BR6: 2 | BT6: 8 | BU6: 9 | BV6: 19 | BW6: 15 | BX6: 34 | BZ6: 1 | CA6: 1 | CB6: 10 | CC6: 10 | CD6: 22 | CE6: 15 | CF6: 37 | CH6: 1 | CI6: 2 | CJ6: 8 | CK6: 10 | CL6: 21 | CM6: 7 | CN6: 28 | CP6: 2 | CQ6: 4 | CR6: 7 | CS6: 7 | CT6: 20 | CU6: 15 | CV6: 35 | CX6: 2 | CY6: 2 | CZ6: 9 | DA6: 10 | DB6: 23 | DC6: 16 | DD6: 39 | DF6: 1 | DH6: 6 | DI6: 9 | DJ6: 16 | DK6: 13 | DL6: 29 | DN6: 1 | DO6: 1 | DP6: 4 | DQ6: 4 | DR6: 10 | DS6: 10 | DT6: 20 | DV6: 1 | DX6: 8 | DY6: 8 | DZ6: 17 | EA6: 10 | EB6: 27 | ED6: 2 | EE6: 2 | EF6: 7 | EG6: 8 | EH6: 19 | EI6: 9 | EJ6: 28 | EP6: 0 | ER6: 0
A7: 5 | B7: EZEKIEL DAVID ABANA | C7: 7 | D7: 6 | E7: 8 | F7: 8 | G7: =SUM(C7:F7) -> 29 | H7: 32 | I7: =G7+H7 -> 61 | K7: 7 | L7: 5 | N7: 10 | O7: =SUM(K7:N7) -> 22 | P7: 29 | Q7: =O7+P7 -> 51 | S7: 8 | T7: 7 | U7: 5 | V7: 5 | W7: =SUM(S7:V7) -> 25 | X7: 38 | Y7: =W7+X7 -> 63 | Z7: =IF(Y7<10,"",RANK(Y7,Y$3:Y$52)) -> 13 | AA7: =IF(Y7>=70,"A",IF(Y7>=50,"C",IF(Y7>=45,"P",IF(Y7>=6,"F",IF(Y7<5,""))))) -> C | AB7: =IF(Y7>=70,"Excellent",IF(Y7>=50,"Credit",IF(Y7>=45,"Pass",IF(Y7>=6,"Fail",IF(Y7<5,""))))) -> Credit | AD7: 6 | AE7: 2 | AF7: 2 | AG7: 5 | AH7: =SUM(AD7:AG7) -> 15 | AI7: 45 | AJ7: =AH7+AI7 -> 60 | AL7: 3 | AM7: 3 | AN7: 8 | AO7: 7 | AP7: =SUM(AL7:AO7) -> 21 | AQ7: 21 | AR7: =AP7+AQ7 -> 42 | AT7: 2 | AU7: 2 | AV7: 5 | AW7: 7 | AX7: 16 | AY7: 19 | AZ7: 35 | BB7: 2 | BC7: 1 | BD7: 4 | BE7: 3 | BF7: 10 | BG7: 49 | BH7: 59 | BJ7: 7 | BK7: 7 | BL7: 10 | BM7: 8 | BN7: 32 | BO7: 26 | BP7: 58 | BR7: 5 | BS7: 7 | BT7: 8 | BU7: 10 | BV7: 30 | BW7: 28 | BX7: 58 | BZ7: 6 | CA7: 8 | CB7: 6 | CC7: 5 | CD7: 25 | CE7: 37 | CF7: 62 | CH7: 4 | CI7: 8 | CL7: 12 | CM7: 48 | CN7: 60 | CP7: 7 | CQ7: 4 | CR7: 7 | CS7: 7 | CT7: 25 | CU7: 25 | CV7: 50 | CX7: 3 | CY7: 4 | CZ7: 10 | DA7: 10 | DB7: 27 | DC7: 19 | DD7: 46 | DF7: 5 | DG7: 3 | DH7: 5 | DI7: 4 | DJ7: 17 | DK7: 12 | DL7: 29 | DN7: 1 | DO7: 2 | DP7: 5 | DQ7: 5 | DR7: 13 | DS7: 17 | DT7: 30 | DV7: 2 | DW7: 2 | DX7: 7 | DY7: 10 | DZ7: 21 | EA7: 17 | EB7: 38 | ED7: 8 | EE7: 2 | EF7: 8 | EG7: 10 | EH7: 28 | EI7: 26 | EJ7: 54 | EP7: 0 | ER7: 0
A8: 6 | B8: ELIJAH EPHRAIM HAGIN | C8: 10 | D8: 8 | E8: 10 | F8: 10 | G8: =SUM(C8:F8) -> 38 | H8: 50 | I8: =G8+H8 -> 88 | K8: 9 | L8: 7 | M8: 10 | N8: 10 | O8: =SUM(K8:N8) -> 36 | P8: 42 | Q8: =O8+P8 -> 78 | S8: 7 | T8: 7 | U8: 5 | V8: 5 | W8: =SUM(S8:V8) -> 24 | X8: 47 | Y8: =W8+X8 -> 71 | Z8: =IF(Y8<10,"",RANK(Y8,Y$3:Y$52)) -> 9 | AA8: =IF(Y8>=70,"A",IF(Y8>=50,"C",IF(Y8>=45,"P",IF(Y8>=6,"F",IF(Y8<5,""))))) -> A | AB8: =IF(Y8>=70,"Excellent",IF(Y8>=50,"Credit",IF(Y8>=45,"Pass",IF(Y8>=6,"Fail",IF(Y8<5,""))))) -> Excellent | AD8: 8 | AE8: 8 | AF8: 2 | AG8: 10 | AH8: =SUM(AD8:AG8) -> 28 | AI8: 53 | AJ8: =AH8+AI8 -> 81 | AL8: 4 | AM8: 8 | AN8: 9 | AO8: 8 | AP8: =SUM(AL8:AO8) -> 29 | AQ8: 43 | AR8: =AP8+AQ8 -> 72 | AT8: 8 | AU8: 5 | AV8: 10 | AW8: 4 | AX8: 27 | AY8: 49 | AZ8: 76 | BB8: 8 | BC8: 7 | BD8: 6 | BE8: 8 | BF8: 29 | BG8: 53 | BH8: 82 | BJ8: 8 | BK8: 10 | BL8: 10 | BM8: 9 | BN8: 37 | BO8: 40 | BP8: 77 | BR8: 9 | BS8: 9 | BT8: 8 | BU8: 10 | BV8: 36 | BW8: 52 | BX8: 88 | BZ8: 7 | CA8: 7 | CB8: 10 | CC8: 10 | CD8: 34 | CE8: 39 | CF8: 73 | CH8: 8 | CI8: 7 | CJ8: 5 | CK8: 8 | CL8: 28 | CM8: 41 | CN8: 69 | CP8: 7 | CQ8: 5 | CR8: 10 | CS8: 7 | CT8: 29 | CU8: 40 | CV8: 69 | CX8: 3 | CY8: 9 | CZ8: 10 | DA8: 10 | DB8: 32 | DC8: 44 | DD8: 76 | DF8: 10 | DG8: 1 | DH8: 2 | DI8: 4 | DJ8: 17 | DK8: 33 | DL8: 50 | DN8: 2 | DO8: 6 | DP8: 5 | DQ8: 9 | DR8: 22 | DS8: 42 | DT8: 64 | DV8: 10 | DW8: 5 | DX8: 10 | DY8: 10 | DZ8: 35 | EA8: 47 | EB8: 82 | ED8: 8 | EE8: 4 | EF8: 6 | EG8: 10 | EH8: 28 | EI8: 40 | EJ8: 68 | EP8: 0 | ER8: 0
A9: 7 | B9: IBRAHIM ABDULLAHI HASHIM | C9: 8 | D9: 10 | E9: 9 | F9: 10 | G9: =SUM(C9:F9) -> 37 | H9: 48 | I9: =G9+H9 -> 85 | K9: 10 | L9: 8 | M9: 10 | N9: 10 | O9: =SUM(K9:N9) -> 38 | P9: 57 | Q9: =O9+P9 -> 95 | S9: 9 | T9: 8 | U9: 5 | V9: 10 | W9: =SUM(S9:V9) -> 32 | X9: 51 | Y9: =W9+X9 -> 83 | Z9: =IF(Y9<10,"",RANK(Y9,Y$3:Y$52)) -> 2 | AA9: =IF(Y9>=70,"A",IF(Y9>=50,"C",IF(Y9>=45,"P",IF(Y9>=6,"F",IF(Y9<5,""))))) -> A | AB9: =IF(Y9>=70,"Excellent",IF(Y9>=50,"Credit",IF(Y9>=45,"Pass",IF(Y9>=6,"Fail",IF(Y9<5,""))))) -> Excellent | AH9: =SUM(AD9:AG9) -> 0 | AJ9: =AH9+AI9 -> 0 | AL9: 10 | AM9: 8 | AN9: 10 | AO9: 9 | AP9: =SUM(AL9:AO9) -> 37 | AQ9: 39 | AR9: =AP9+AQ9 -> 76 | AT9: 9 | AU9: 6 | AV9: 10 | AW9: 10 | AX9: 35 | AY9: 49 | AZ9: 84 | BB9: 10 | BC9: 7 | BD9: 10 | BE9: 10 | BF9: 37 | BG9: 55 | BH9: 92 | BJ9: 8 | BK9: 10 | BL9: 10 | BM9: 8 | BN9: 36 | BO9: 54 | BP9: 90 | BR9: 10 | BS9: 10 | BT9: 10 | BU9: 10 | BV9: 40 | BW9: 51 | BX9: 91 | BZ9: 5 | CA9: 8 | CB9: 10 | CC9: 10 | CD9: 33 | CE9: 47 | CF9: 80 | CH9: 7 | CI9: 10 | CJ9: 10 | CK9: 10 | CL9: 37 | CM9: 53 | CN9: 90 | CP9: 7 | CR9: 9 | CS9: 7 | CT9: 23 | CU9: 45 | CV9: 68 | CX9: 5 | CY9: 9 | CZ9: 10 | DA9: 10 | DB9: 34 | DC9: 28 | DD9: 62 | DF9: 10 | DG9: 7 | DH9: 3 | DI9: 10 | DJ9: 30 | DK9: 49 | DL9: 79 | DN9: 9 | DO9: 4 | DP9: 7 | DQ9: 9 | DR9: 29 | DS9: 50 | DT9: 79 | DV9: 8 | DW9: 8 | DX9: 8 | DY9: 10 | DZ9: 34 | EA9: 50 | EB9: 84 | ED9: 9 | EE9: 7 | EF9: 10 | EG9: 10 | EH9: 36 | EI9: 48 | EJ9: 84 | EL9: 10 | EM9: 6 | EN9: 5 | EO9: 5 | EP9: 26 | EQ9: 45 | ER9: 71
A10: 8 | B10: MOHAMMED MARTE | C10: 2 | D10: 2 | E10: 8 | F10: 8 | G10: =SUM(C10:F10) -> 20 | H10: 7 | I10: =G10+H10 -> 27 | K10: 1 | L10: 1 | M10: 10 | N10: 10 | O10: =SUM(K10:N10) -> 22 | P10: 16 | Q10: =O10+P10 -> 38 | S10: 1 | T10: 2 | U10: 5 | V10: 5 | W10: =SUM(S10:V10) -> 13 | X10: 12 | Y10: =W10+X10 -> 25 | Z10: =IF(Y10<10,"",RANK(Y10,Y$3:Y$52)) -> 39 | AA10: =IF(Y10>=70,"A",IF(Y10>=50,"C",IF(Y10>=45,"P",IF(Y10>=6,"F",IF(Y10<5,""))))) -> F | AB10: =IF(Y10>=70,"Excellent",IF(Y10>=50,"Credit",IF(Y10>=45,"Pass",IF(Y10>=6,"Fail",IF(Y10<5,""))))) -> Fail | AH10: =SUM(AD10:AG10) -> 0 | AJ10: =AH10+AI10 -> 0 | AL10: 1 | AM10: 2 | AN10: 8 | AO10: 7 | AP10: =SUM(AL10:AO10) -> 18 | AQ10: 11 | AR10: =AP10+AQ10 -> 29 | AT10: 1 | AU10: 1 | AV10: 5 | AW10: 4 | AX10: 11 | AY10: 15 | AZ10: 26 | BB10: 1 | BC10: 1 | BD10: 2 | BE10: 3 | BF10: 7 | BG10: 11 | BH10: 18 | BJ10: 7 | BK10: 3 | BL10: 9 | BM10: 10 | BN10: 29 | BO10: 15 | BP10: 44 | BR10: 1 | BS10: 2 | BT10: 10 | BU10: 10 | BV10: 23 | BW10: 7 | BX10: 30 | BZ10: 1 | CA10: 1 | CB10: 10 | CC10: 5 | CD10: 17 | CE10: 8 | CF10: 25 | CH10: 1 | CI10: 2 | CL10: 3 | CM10: 13 | CN10: 16 | CP10: 1 | CQ10: 1 | CR10: 9 | CS10: 7 | CT10: 18 | CU10: 15 | CV10: 33 | CX10: 2 | CY10: 2 | CZ10: 8 | DA10: 8 | DB10: 20 | DC10: 17 | DD10: 37 | DF10: 1 | DG10: 1 | DJ10: 2 | DK10: 19 | DL10: 21 | DN10: 1 | DO10: 1 | DP10: 4 | DQ10: 5 | DR10: 11 | DS10: 9 | DT10: 20 | DV10: 1 | DW10: 2 | DX10: 8 | DY10: 10 | DZ10: 21 | EA10: 14 | EB10: 35 | ED10: 2 | EE10: 2 | EF10: 8 | EG10: 7 | EH10: 19 | EI10: 17 | EJ10: 36 | EL10: 1 | EM10: 1 | EN10: 5 | EO10: 5 | EP10: 12 | EQ10: 17 | ER10: 29
A11: 9 | B11: MUHAMMAD BABAGANA M. | C11: 2 | D11: 6 | E11: 9 | F11: 9 | G11: =SUM(C11:F11) -> 26 | H11: 20 | I11: =G11+H11 -> 46 | K11: 1 | L11: 3 | N11: 10 | O11: =SUM(K11:N11) -> 14 | P11: 29 | Q11: =O11+P11 -> 43 | S11: 7 | T11: 4 | U11: 5 | V11: 7 | W11: =SUM(S11:V11) -> 23 | X11: 21 | Y11: =W11+X11 -> 44 | Z11: =IF(Y11<10,"",RANK(Y11,Y$3:Y$52)) -> 33 | AA11: =IF(Y11>=70,"A",IF(Y11>=50,"C",IF(Y11>=45,"P",IF(Y11>=6,"F",IF(Y11<5,""))))) -> F | AB11: =IF(Y11>=70,"Excellent",IF(Y11>=50,"Credit",IF(Y11>=45,"Pass",IF(Y11>=6,"Fail",IF(Y11<5,""))))) -> Fail | AH11: =SUM(AD11:AG11) -> 0 | AJ11: =AH11+AI11 -> 0 | AL11: 1 | AM11: 8 | AN11: 10 | AO11: 9 | AP11: =SUM(AL11:AO11) -> 28 | AQ11: 20 | AR11: =AP11+AQ11 -> 48 | AT11: 1 | AU11: 1 | AV11: 5 | AW11: 9 | AX11: 16 | AY11: 20 | AZ11: 36 | BB11: 2 | BC11: 1 | BD11: 9 | BE11: 5 | BF11: 17 | BG11: 30 | BH11: 47 | BJ11: 3 | BK11: 5 | BL11: 8 | BM11: 10 | BN11: 26 | BO11: 12 | BP11: 38 | BR11: 5 | BS11: 5 | BT11: 7 | BU11: 10 | BV11: 27 | BW11: 27 | BX11: 54 | BZ11: 5 | CA11: 7 | CB11: 8 | CC11: 5 | CD11: 25 | CE11: 29 | CF11: 54 | CH11: 1 | CI11: 5 | CJ11: 10 | CK11: 10 | CL11: 26 | CM11: 16 | CN11: 42 | CP11: 9 | CQ11: 4 | CR11: 7 | CS11: 7 | CT11: 27 | CU11: 20 | CV11: 47 | CX11: 4 | CY11: 5 | CZ11: 10 | DA11: 10 | DB11: 29 | DC11: 19 | DD11: 48 | DF11: 2 | DG11: 1 | DH11: 2 | DI11: 10 | DJ11: 15 | DK11: 29 | DL11: 44 | DN11: 1 | DO11: 1 | DP11: 4 | DQ11: 5 | DR11: 11 | DS11: 10 | DT11: 21 | DV11: 2 | DW11: 4 | DX11: 8 | DY11: 10 | DZ11: 24 | EA11: 16 | EB11: 40 | ED11: 3 | EE11: 3 | EF11: 8 | EG11: 8 | EH11: 22 | EI11: 24 | EJ11: 46 | EL11: 2 | EM11: 4 | EN11: 10 | EO11: 10 | EP11: 26 | EQ11: 19 | ER11: 45
A12: 10 | B12: MUHAMMED MODUYE | C12: 4 | D12: 3 | E12: 8 | F12: 8 | G12: =SUM(C12:F12) -> 23 | H12: 26 | I12: =G12+H12 -> 49 | K12: 1 | L12: 1 | M12: 10 | N12: 10 | O12: =SUM(K12:N12) -> 22 | P12: 29 | Q12: =O12+P12 -> 51 | S12: 10 | T12: 5 | U12: 5 | V12: 7 | W12: =SUM(S12:V12) -> 27 | X12: 27 | Y12: =W12+X12 -> 54 | Z12: =IF(Y12<10,"",RANK(Y12,Y$3:Y$52)) -> 27 | AA12: =IF(Y12>=70,"A",IF(Y12>=50,"C",IF(Y12>=45,"P",IF(Y12>=6,"F",IF(Y12<5,""))))) -> C | AB12: =IF(Y12>=70,"Excellent",IF(Y12>=50,"Credit",IF(Y12>=45,"Pass",IF(Y12>=6,"Fail",IF(Y12<5,""))))) -> Credit | AH12: =SUM(AD12:AG12) -> 0 | AJ12: =AH12+AI12 -> 0 | AL12: 1 | AM12: 4 | AN12: 8 | AO12: 9 | AP12: =SUM(AL12:AO12) -> 22 | AQ12: 15 | AR12: =AP12+AQ12 -> 37 | AT12: 1 | AU12: 1 | AV12: 5 | AW12: 6 | AX12: 13 | AY12: 15 | AZ12: 28 | BB12: 6 | BC12: 1 | BD12: 4 | BE12: 10 | BF12: 21 | BG12: 30 | BH12: 51 | BJ12: 5 | BK12: 4 | BL12: 8 | BM12: 8 | BN12: 25 | BO12: 17 | BP12: 42 | BR12: 4 | BS12: 5 | BT12: 10 | BU12: 10 | BV12: 29 | BW12: 25 | BX12: 54 | BZ12: 6 | CA12: 2 | CB12: 10 | CC12: 10 | CD12: 28 | CE12: 21 | CF12: 49 | CH12: 3 | CI12: 6 | CJ12: 8 | CK12: 10 | CL12: 27 | CM12: 19 | CN12: 46 | CP12: 7 | CQ12: 2 | CR12: 10 | CS12: 8 | CT12: 27 | CU12: 25 | CV12: 52 | CX12: 1 | CY12: 4 | CZ12: 10 | DA12: 10 | DB12: 25 | DC12: 16 | DD12: 41 | DF12: 4 | DG12: 1 | DH12: 10 | DI12: 9 | DJ12: 24 | DK12: 26 | DL12: 50 | DN12: 1 | DO12: 3 | DP12: 4 | DQ12: 8 | DR12: 16 | DS12: 11 | DT12: 27 | DV12: 1 | DW12: 2 | DX12: 8 | DY12: 10 | DZ12: 21 | EA12: 6 | EB12: 27 | ED12: 7 | EE12: 2 | EF12: 7 | EG12: 8 | EH12: 24 | EI12: 10 | EJ12: 34 | EL12: 8 | EM12: 1 | EN12: 10 | EO12: 10 | EP12: 29 | EQ12: 25 | ER12: 54
A13: 11 | B13: MUHAMMED M RABIU | C13: 9 | D13: 6 | E13: 9 | F13: 10 | G13: =SUM(C13:F13) -> 34 | H13: 35 | I13: =G13+H13 -> 69 | K13: 8 | L13: 8 | M13: 10 | N13: 10 | O13: =SUM(K13:N13) -> 36 | P13: 32 | Q13: =O13+P13 -> 68 | S13: 10 | T13: 6 | U13: 5 | V13: 10 | W13: =SUM(S13:V13) -> 31 | X13: 41 | Y13: =W13+X13 -> 72 | Z13: =IF(Y13<10,"",RANK(Y13,Y$3:Y$52)) -> 6 | AA13: =IF(Y13>=70,"A",IF(Y13>=50,"C",IF(Y13>=45,"P",IF(Y13>=6,"F",IF(Y13<5,""))))) -> A | AB13: =IF(Y13>=70,"Excellent",IF(Y13>=50,"Credit",IF(Y13>=45,"Pass",IF(Y13>=6,"Fail",IF(Y13<5,""))))) -> Excellent | AH13: =SUM(AD13:AG13) -> 0 | AJ13: =AH13+AI13 -> 0 | AL13: 8 | AM13: 10 | AN13: 10 | AO13: 8 | AP13: =SUM(AL13:AO13) -> 36 | AQ13: 35 | AR13: =AP13+AQ13 -> 71 | AT13: 4 | AU13: 6 | AV13: 5 | AW13: 10 | AX13: 25 | AY13: 27 | AZ13: 52 | BB13: 10 | BC13: 8 | BD13: 9 | BE13: 8 | BF13: 35 | BG13: 53 | BH13: 88 | BJ13: 9 | BK13: 10 | BL13: 10 | BM13: 10 | BN13: 39 | BO13: 35 | BP13: 74 | BR13: 9 | BS13: 8 | BT13: 10 | BU13: 10 | BV13: 37 | BW13: 42 | BX13: 79 | BZ13: 7 | CA13: 8 | CB13: 10 | CC13: 10 | CD13: 35 | CE13: 42 | CF13: 77 | CH13: 4 | CI13: 8 | CJ13: 10 | CK13: 10 | CL13: 32 | CM13: 48 | CN13: 80 | CP13: 7 | CQ13: 3 | CR13: 9 | CS13: 8 | CT13: 27 | CU13: 40 | CV13: 67 | CX13: 4 | CY13: 4 | CZ13: 8 | DA13: 10 | DB13: 26 | DC13: 20 | DD13: 46 | DF13: 9 | DG13: 6 | DH13: 9 | DI13: 10 | DJ13: 34 | DK13: 44 | DL13: 78 | DN13: 2 | DO13: 10 | DQ13: 5 | DR13: 17 | DS13: 30 | DT13: 47 | DV13: 5 | DW13: 8 | DX13: 8 | DY13: 10 | DZ13: 31 | EA13: 29 | EB13: 60 | ED13: 9 | EE13: 9 | EF13: 8 | EG13: 10 | EH13: 36 | EI13: 40 | EJ13: 76 | EL13: 9 | EM13: 8 | EN13: 10 | EO13: 10 | EP13: 37 | EQ13: 42 | ER13: 79
A14: 12 | C14: 10 | D14: 7 | E14: 10 | F14: 9 | G14: =SUM(C14:F14) -> 36 | H14: 50 | I14: =G14+H14 -> 86 | K14: 9 | L14: 10 | M14: 10 | N14: 10 | O14: =SUM(K14:N14) -> 39 | P14: 30 | Q14: =O14+P14 -> 69 | S14: 10 | T14: 7 | U14: 5 | V14: 9 | W14: =SUM(S14:V14) -> 31 | X14: 35 | Y14: =W14+X14 -> 66 | Z14: =IF(Y14<10,"",RANK(Y14,Y$3:Y$52)) -> 12 | AA14: =IF(Y14>=70,"A",IF(Y14>=50,"C",IF(Y14>=45,"P",IF(Y14>=6,"F",IF(Y14<5,""))))) -> C | AB14: =IF(Y14>=70,"Excellent",IF(Y14>=50,"Credit",IF(Y14>=45,"Pass",IF(Y14>=6,"Fail",IF(Y14<5,""))))) -> Credit | AH14: =SUM(AD14:AG14) -> 0 | AJ14: =AH14+AI14 -> 0 | AL14: 10 | AM14: 7 | AN14: 10 | AO14: 10 | AP14: =SUM(AL14:AO14) -> 37 | AQ14: 26 | AR14: =AP14+AQ14 -> 63 | AT14: 3 | AU14: 5 | AV14: 5 | AW14: 10 | AX14: 23 | AY14: 31 | AZ14: 54 | BB14: 10 | BC14: 10 | BD14: 6 | BE14: 10 | BF14: 36 | BG14: 44 | BH14: 80 | BJ14: 8 | BK14: 8 | BL14: 10 | BM14: 8 | BN14: 34 | BO14: 46 | BP14: 80 | BR14: 10 | BS14: 10 | BT14: 10 | BU14: 10 | BV14: 40 | BW14: 34 | BX14: 74 | BZ14: 9 | CA14: 8 | CB14: 8 | CC14: 10 | CD14: 35 | CE14: 43 | CF14: 78 | CH14: 5 | CI14: 10 | CJ14: 10 | CK14: 10 | CL14: 35 | CM14: 51 | CN14: 86 | CP14: 8 | CQ14: 5 | CR14: 7 | CS14: 7 | CT14: 27 | CU14: 35 | CV14: 62 | CX14: 4 | CY14: 7 | CZ14: 10 | DA14: 10 | DB14: 31 | DC14: 32 | DD14: 63 | DF14: 10 | DG14: 7 | DH14: 5 | DI14: 10 | DJ14: 32 | DK14: 44 | DL14: 76 | DN14: 4 | DO14: 7 | DP14: 4 | DQ14: 5 | DR14: 20 | DS14: 36 | DT14: 56 | DV14: 5 | DW14: 9 | DX14: 10 | DY14: 8 | DZ14: 32 | EA14: 27 | EB14: 59 | ED14: 10 | EE14: 8 | EF14: 10 | EG14: 10 | EH14: 38 | EI14: 44 | EJ14: 82 | EL14: 10 | EM14: 8 | EN14: 10 | EO14: 10 | EP14: 38 | EQ14: 52 | ER14: 90
A15: 13 | B15: SADIQ BUKAR ALLAU | C15: 5 | D15: 4 | E15: 7 | F15: 8 | G15: =SUM(C15:F15) -> 24 | H15: 21 | I15: =G15+H15 -> 45 | K15: 3 | L15: 7 | M15: 10 | N15: 10 | O15: =SUM(K15:N15) -> 30 | P15: 22 | Q15: =O15+P15 -> 52 | S15: 6 | T15: 2 | U15: 5 | V15: 5 | W15: =SUM(S15:V15) -> 18 | X15: 26 | Y15: =W15+X15 -> 44 | Z15: =IF(Y15<10,"",RANK(Y15,Y$3:Y$52)) -> 33 | AA15: =IF(Y15>=70,"A",IF(Y15>=50,"C",IF(Y15>=45,"P",IF(Y15>=6,"F",IF(Y15<5,""))))) -> F | AB15: =IF(Y15>=70,"Excellent",IF(Y15>=50,"Credit",IF(Y15>=45,"Pass",IF(Y15>=6,"Fail",IF(Y15<5,""))))) -> Fail | AH15: =SUM(AD15:AG15) -> 0 | AJ15: =AH15+AI15 -> 0 | AL15: 3 | AM15: 2 | AN15: 10 | AO15: 10 | AP15: =SUM(AL15:AO15) -> 25 | AQ15: 19 | AR15: =AP15+AQ15 -> 44 | AT15: 2 | AV15: 5 | AW15: 4 | AX15: 11 | AY15: 15 | AZ15: 26 | BB15: 2 | BC15: 1 | BD15: 3 | BE15: 5 | BF15: 11 | BG15: 33 | BH15: 44 | BJ15: 5 | BK15: 5 | BL15: 10 | BM15: 10 | BN15: 30 | BO15: 17 | BP15: 47 | BR15: 3 | BS15: 5 | BT15: 10 | BU15: 10 | BV15: 28 | BW15: 21 | BX15: 49 | BZ15: 3 | CA15: 9 | CB15: 10 | CC15: 9 | CD15: 31 | CE15: 23 | CF15: 54 | CH15: 3 | CI15: 3 | CJ15: 8 | CK15: 10 | CL15: 24 | CM15: 23 | CN15: 47 | CP15: 2 | CQ15: 1 | CR15: 8 | CS15: 7 | CT15: 18 | CU15: 10 | CV15: 28 | CX15: 7 | CY15: 7 | CZ15: 8 | DA15: 9 | DB15: 31 | DC15: 16 | DD15: 47 | DF15: 5 | DG15: 1 | DJ15: 6 | DL15: 6 | DN15: 1 | DO15: 1 | DP15: 4 | DQ15: 5 | DR15: 11 | DS15: 11 | DT15: 22 | DV15: 1 | DW15: 6 | DX15: 8 | DY15: 10 | DZ15: 25 | EB15: 25 | ED15: 3 | EE15: 5 | EF15: 8 | EG15: 8 | EH15: 24 | EI15: 12 | EJ15: 36 | EL15: 8 | EM15: 1 | EN15: 5 | EO15: 5 | EP15: 19 | EQ15: 14 | ER15: 33
A16: 14 | B16: USMAN MUHAMMED USMAN | C16: 5 | D16: 4 | E16: 9 | F16: 8 | G16: =SUM(C16:F16) -> 26 | H16: 14 | I16: =G16+H16 -> 40 | K16: 1 | L16: 3 | M16: 10 | N16: 10 | O16: =SUM(K16:N16) -> 24 | P16: 20 | Q16: =O16+P16 -> 44 | S16: 9 | T16: 6 | U16: 5 | V16: 5 | W16: =SUM(S16:V16) -> 25 | X16: 30 | Y16: =W16+X16 -> 55 | Z16: =IF(Y16<10,"",RANK(Y16,Y$3:Y$52)) -> 26 | AA16: =IF(Y16>=70,"A",IF(Y16>=50,"C",IF(Y16>=45,"P",IF(Y16>=6,"F",IF(Y16<5,""))))) -> C | AB16: =IF(Y16>=70,"Excellent",IF(Y16>=50,"Credit",IF(Y16>=45,"Pass",IF(Y16>=6,"Fail",IF(Y16<5,""))))) -> Credit | AH16: =SUM(AD16:AG16) -> 0 | AJ16: =AH16+AI16 -> 0 | AL16: 2 | AM16: 4 | AN16: 8 | AO16: 9 | AP16: =SUM(AL16:AO16) -> 23 | AQ16: 17 | AR16: =AP16+AQ16 -> 40 | AT16: 1 | AU16: 1 | AV16: 5 | AW16: 6 | AX16: 13 | AY16: 13 | AZ16: 26 | BB16: 4 | BC16: 1 | BD16: 3 | BE16: 5 | BF16: 13 | BG16: 29 | BH16: 42 | BJ16: 4 | BK16: 6 | BL16: 10 | BM16: 8 | BN16: 28 | BO16: 17 | BP16: 45 | BR16: 7 | BS16: 3 | BT16: 7 | BU16: 10 | BV16: 27 | BW16: 14 | BX16: 41 | BZ16: 3 | CA16: 2 | CB16: 9 | CC16: 6 | CD16: 20 | CE16: 22 | CF16: 42 | CH16: 5 | CI16: 6 | CJ16: 2 | CK16: 5 | CL16: 18 | CM16: 26 | CN16: 44 | CP16: 6 | CQ16: 3 | CR16: 8 | CS16: 6 | CT16: 23 | CU16: 25 | CV16: 48 | CX16: 5 | CY16: 5 | CZ16: 9 | DA16: 10 | DB16: 29 | DC16: 12 | DD16: 41 | DF16: 5 | DG16: 1 | DH16: 4 | DI16: 5 | DJ16: 15 | DK16: 25 | DL16: 40 | DN16: 4 | DO16: 2 | DP16: 5 | DQ16: 5 | DR16: 16 | DS16: 11 | DT16: 27 | DV16: 6 | DW16: 3 | DX16: 7 | DY16: 10 | DZ16: 26 | EA16: 22 | EB16: 48 | ED16: 7 | EE16: 5 | EF16: 8 | EG16: 8 | EH16: 28 | EI16: 28 | EJ16: 56 | EL16: 10 | EM16: 5 | EN16: 5 | EO16: 5 | EP16: 25 | EQ16: 29 | ER16: 54
A17: 15 | B17: ABUBAKAR AHMED HADIZA | C17: 9 | D17: 10 | E17: 10 | F17: 10 | G17: =SUM(C17:F17) -> 39 | H17: 50 | I17: =G17+H17 -> 89 | K17: 9 | L17: 5 | M17: 10 | N17: 10 | O17: =SUM(K17:N17) -> 34 | P17: 35 | Q17: =O17+P17 -> 69 | S17: 10 | T17: 6 | U17: 5 | V17: 5 | W17: =SUM(S17:V17) -> 26 | X17: 45 | Y17: =W17+X17 -> 71 | Z17: =IF(Y17<10,"",RANK(Y17,Y$3:Y$52)) -> 9 | AA17: =IF(Y17>=70,"A",IF(Y17>=50,"C",IF(Y17>=45,"P",IF(Y17>=6,"F",IF(Y17<5,""))))) -> A | AB17: =IF(Y17>=70,"Excellent",IF(Y17>=50,"Credit",IF(Y17>=45,"Pass",IF(Y17>=6,"Fail",IF(Y17<5,""))))) -> Excellent | AH17: =SUM(AD17:AG17) -> 0 | AJ17: =AH17+AI17 -> 0 | AL17: 8 | AM17: 8 | AN17: 9 | AO17: 9 | AP17: =SUM(AL17:AO17) -> 34 | AQ17: 27 | AR17: =AP17+AQ17 -> 61 | AT17: 3 | AU17: 1 | AV17: 5 | AW17: 4 | AX17: 13 | AY17: 38 | AZ17: 51 | BB17: 10 | BC17: 8 | BD17: 9 | BE17: 5 | BF17: 32 | BG17: 53 | BH17: 85 | BJ17: 8 | BK17: 8 | BL17: 10 | BM17: 10 | BN17: 36 | BO17: 47 | BP17: 83 | BR17: 10 | BS17: 10 | BT17: 10 | BU17: 10 | BV17: 40 | BW17: 44 | BX17: 84 | BZ17: 8 | CA17: 3 | CB17: 10 | CC17: 5 | CD17: 26 | CE17: 39 | CF17: 65 | CH17: 7 | CI17: 5 | CJ17: 10 | CK17: 10 | CL17: 32 | CM17: 50 | CN17: 82 | CP17: 9 | CQ17: 6 | CR17: 7 | CS17: 7 | CT17: 29 | CU17: 35 | CV17: 64 | CX17: 8 | CY17: 8 | CZ17: 7 | DA17: 9 | DB17: 32 | DC17: 20 | DD17: 52 | DF17: 10 | DG17: 4 | DH17: 10 | DI17: 10 | DJ17: 34 | DK17: 53 | DL17: 87 | DN17: 5 | DO17: 8 | DP17: 4 | DQ17: 5 | DR17: 22 | DS17: 34 | DT17: 56 | DV17: 10 | DW17: 6 | DX17: 8 | DY17: 10 | DZ17: 34 | EA17: 41 | EB17: 75 | ED17: 9 | EE17: 9 | EF17: 10 | EG17: 10 | EH17: 38 | EI17: 36 | EJ17: 74 | EL17: 8 | EM17: 7 | EN17: 5 | EO17: 5 | EP17: 25 | EQ17: 47 | ER17: 72
A18: 16 | B18: ABDULHAMID AISHA | C18: 1 | D18: 5 | E18: 10 | F18: 9 | G18: =SUM(C18:F18) -> 25 | H18: 20 | I18: =G18+H18 -> 45 | K18: 1 | L18: 5 | N18: 10 | O18: =SUM(K18:N18) -> 16 | P18: 19 | Q18: =O18+P18 -> 35 | S18: 4 | T18: 4 | U18: 5 | V18: 5 | W18: =SUM(S18:V18) -> 18 | X18: 30 | Y18: =W18+X18 -> 48 | Z18: =IF(Y18<10,"",RANK(Y18,Y$3:Y$52)) -> 30 | AA18: =IF(Y18>=70,"A",IF(Y18>=50,"C",IF(Y18>=45,"P",IF(Y18>=6,"F",IF(Y18<5,""))))) -> P | AB18: =IF(Y18>=70,"Excellent",IF(Y18>=50,"Credit",IF(Y18>=45,"Pass",IF(Y18>=6,"Fail",IF(Y18<5,""))))) -> Pass | AH18: =SUM(AD18:AG18) -> 0 | AJ18: =AH18+AI18 -> 0 | AL18: 1 | AM18: 2 | AN18: 8 | AO18: 8 | AP18: =SUM(AL18:AO18) -> 19 | AQ18: 21 | AR18: =AP18+AQ18 -> 40 | AT18: 1 | AU18: 4 | AV18: 5 | AW18: 4 | AX18: 14 | AY18: 22 | AZ18: 36 | BB18: 2 | BC18: 1 | BD18: 4 | BE18: 6 | BF18: 13 | BG18: 15 | BH18: 28 | BJ18: 2 | BK18: 6 | BL18: 10 | BM18: 10 | BN18: 28 | BO18: 14 | BP18: 42 | BR18: 5 | BS18: 2 | BT18: 10 | BU18: 10 | BV18: 27 | BW18: 22 | BX18: 49 | BZ18: 1 | CA18: 2 | CB18: 10 | CC18: 5 | CD18: 18 | CE18: 18 | CF18: 36 | CH18: 1 | CI18: 2 | CJ18: 8 | CK18: 10 | CL18: 21 | CM18: 17 | CN18: 38 | CP18: 2 | CQ18: 1 | CR18: 10 | CS18: 7 | CT18: 20 | CU18: 16 | CV18: 36 | CX18: 3 | CY18: 3 | CZ18: 10 | DA18: 10 | DB18: 26 | DC18: 15 | DD18: 41 | DF18: 2 | DG18: 2 | DH18: 9 | DI18: 10 | DJ18: 23 | DK18: 15 | DL18: 38 | DN18: 1 | DO18: 1 | DP18: 5 | DQ18: 5 | DR18: 12 | DS18: 12 | DT18: 24 | DV18: 1 | DW18: 3 | DX18: 8 | DY18: 10 | DZ18: 22 | EA18: 12 | EB18: 34 | ED18: 4 | EE18: 5 | EF18: 8 | EG18: 9 | EH18: 26 | EI18: 21 | EJ18: 47 | EL18: 2 | EM18: 1 | EN18: 10 | EO18: 10 | EP18: 23 | EQ18: 18 | ER18: 41
A19: 17 | B19: BUKAR MUHAMMED HAUWA | C19: 6 | E19: 10 | F19: 10 | G19: =SUM(C19:F19) -> 26 | H19: 23 | I19: =G19+H19 -> 49 | K19: 3 | L19: 1 | M19: 10 | N19: 10 | O19: =SUM(K19:N19) -> 24 | P19: 18 | Q19: =O19+P19 -> 42 | S19: 1 | T19: 4 | U19: 5 | V19: 5 | W19: =SUM(S19:V19) -> 15 | X19: 18 | Y19: =W19+X19 -> 33 | Z19: =IF(Y19<10,"",RANK(Y19,Y$3:Y$52)) -> 38 | AA19: =IF(Y19>=70,"A",IF(Y19>=50,"C",IF(Y19>=45,"P",IF(Y19>=6,"F",IF(Y19<5,""))))) -> F | AB19: =IF(Y19>=70,"Excellent",IF(Y19>=50,"Credit",IF(Y19>=45,"Pass",IF(Y19>=6,"Fail",IF(Y19<5,""))))) -> Fail | AH19: =SUM(AD19:AG19) -> 0 | AJ19: =AH19+AI19 -> 0 | AL19: 2 | AM19: 3 | AN19: 10 | AO19: 9 | AP19: =SUM(AL19:AO19) -> 24 | AQ19: 17 | AR19: =AP19+AQ19 -> 41 | AT19: 1 | AU19: 3 | AV19: 10 | AW19: 4 | AX19: 18 | AY19: 13 | AZ19: 31 | BB19: 2 | BC19: 1 | BD19: 2 | BE19: 5 | BF19: 10 | BG19: 16 | BH19: 26 | BJ19: 1 | BK19: 4 | BL19: 10 | BM19: 9 | BN19: 24 | BO19: 14 | BP19: 38 | BR19: 2 | BS19: 1 | BT19: 5 | BU19: 10 | BV19: 18 | BW19: 18 | BX19: 36 | BZ19: 1 | CA19: 5 | CB19: 8 | CC19: 5 | CD19: 19 | CE19: 27 | CF19: 46 | CH19: 1 | CI19: 6 | CJ19: 8 | CK19: 10 | CL19: 25 | CM19: 18 | CN19: 43 | CP19: 2 | CQ19: 4 | CR19: 10 | CS19: 8 | CT19: 24 | CU19: 16 | CV19: 40 | CX19: 3 | CY19: 4 | CZ19: 10 | DA19: 10 | DB19: 27 | DC19: 21 | DD19: 48 | DF19: 1 | DG19: 1 | DH19: 10 | DI19: 10 | DJ19: 22 | DK19: 16 | DL19: 38 | DN19: 1 | DO19: 4 | DP19: 5 | DQ19: 5 | DR19: 15 | DS19: 23 | DT19: 38 | DV19: 1 | DX19: 8 | DY19: 10 | DZ19: 19 | EA19: 13 | EB19: 32 | ED19: 2 | EE19: 5 | EF19: 10 | EG19: 10 | EH19: 27 | EI19: 17 | EJ19: 44 | EL19: 1 | EM19: 1 | EN19: 5 | EO19: 5 | EP19: 12 | ER19: 12
A20: 18 | B20: BALLAMA MUH'D HALIMA | C20: 7 | D20: 7 | E20: 9 | F20: 10 | G20: =SUM(C20:F20) -> 33 | H20: 26 | I20: =G20+H20 -> 59 | K20: 5 | L20: 3 | M20: 10 | N20: 10 | O20: =SUM(K20:N20) -> 28 | P20: 11 | Q20: =O20+P20 -> 39 | S20: 9 | T20: 6 | U20: 5 | V20: 5 | W20: =SUM(S20:V20) -> 25 | X20: 31 | Y20: =W20+X20 -> 56 | Z20: =IF(Y20<10,"",RANK(Y20,Y$3:Y$52)) -> 25 | AA20: =IF(Y20>=70,"A",IF(Y20>=50,"C",IF(Y20>=45,"P",IF(Y20>=6,"F",IF(Y20<5,""))))) -> C | AB20: =IF(Y20>=70,"Excellent",IF(Y20>=50,"Credit",IF(Y20>=45,"Pass",IF(Y20>=6,"Fail",IF(Y20<5,""))))) -> Credit | AH20: =SUM(AD20:AG20) -> 0 | AJ20: =AH20+AI20 -> 0 | AL20: 2 | AM20: 3 | AN20: 10 | AO20: 9 | AP20: =SUM(AL20:AO20) -> 24 | AQ20: 23 | AR20: =AP20+AQ20 -> 47 | AT20: 4 | AU20: 1 | AV20: 5 | AW20: 10 | AX20: 20 | AY20: 23 | AZ20: 43 | BB20: 8 | BC20: 4 | BD20: 4 | BE20: 8 | BF20: 24 | BG20: 36 | BH20: 60 | BJ20: 5 | BK20: 8 | BL20: 8 | BM20: 10 | BN20: 31 | BO20: 28 | BP20: 59 | BR20: 7 | BS20: 7 | BT20: 10 | BU20: 10 | BV20: 34 | BW20: 32 | BX20: 66 | BZ20: 3 | CA20: 4 | CB20: 8 | CC20: 5 | CD20: 20 | CE20: 31 | CF20: 51 | CH20: 9 | CI20: 6 | CJ20: 10 | CK20: 10 | CL20: 35 | CM20: 35 | CN20: 70 | CP20: 8 | CQ20: 2 | CR20: 10 | CS20: 8 | CT20: 28 | CU20: 26 | CV20: 54 | CX20: 7 | CY20: 6 | CZ20: 10 | DA20: 10 | DB20: 33 | DC20: 21 | DD20: 54 | DF20: 10 | DG20: 2 | DH20: 5 | DI20: 10 | DJ20: 27 | DK20: 40 | DL20: 67 | DN20: 3 | DO20: 9 | DP20: 7 | DQ20: 9 | DR20: 28 | DS20: 30 | DT20: 58 | DV20: 4 | DW20: 2 | DX20: 8 | DY20: 10 | DZ20: 24 | EA20: 29 | EB20: 53 | ED20: 9 | EE20: 2 | EF20: 8 | EG20: 10 | EH20: 29 | EI20: 28 | EJ20: 57 | EL20: 5 | EM20: 7 | EN20: 5 | EO20: 5 | EP20: 22 | EQ20: 34 | ER20: 56
A21: 19 | B21: HALIM ALHAJI MAI | C21: 10 | D21: 8 | E21: 10 | F21: 9 | G21: =SUM(C21:F21) -> 37 | H21: 45 | I21: =G21+H21 -> 82 | K21: 7 | L21: 9 | M21: 10 | N21: 10 | O21: =SUM(K21:N21) -> 36 | P21: 26 | Q21: =O21+P21 -> 62 | S21: 10 | T21: 8 | U21: 5 | V21: 5 | W21: =SUM(S21:V21) -> 28 | X21: 45 | Y21: =W21+X21 -> 73 | Z21: =IF(Y21<10,"",RANK(Y21,Y$3:Y$52)) -> 5 | AA21: =IF(Y21>=70,"A",IF(Y21>=50,"C",IF(Y21>=45,"P",IF(Y21>=6,"F",IF(Y21<5,""))))) -> A | AB21: =IF(Y21>=70,"Excellent",IF(Y21>=50,"Credit",IF(Y21>=45,"Pass",IF(Y21>=6,"Fail",IF(Y21<5,""))))) -> Excellent | AH21: =SUM(AD21:AG21) -> 0 | AJ21: =AH21+AI21 -> 0 | AL21: 10 | AM21: 10 | AN21: 8 | AO21: 10 | AP21: =SUM(AL21:AO21) -> 38 | AQ21: 40 | AR21: =AP21+AQ21 -> 78 | AT21: 6 | AU21: 6 | AV21: 10 | AW21: 4 | AX21: 26 | AY21: 39 | AZ21: 65 | BB21: 8 | BC21: 9 | BD21: 10 | BE21: 10 | BF21: 37 | BG21: 48 | BH21: 85 | BJ21: 10 | BK21: 7 | BL21: 9 | BM21: 10 | BN21: 36 | BO21: 48 | BP21: 84 | BR21: 7 | BS21: 10 | BT21: 10 | BU21: 10 | BV21: 37 | BW21: 43 | BX21: 80 | BZ21: 10 | CA21: 8 | CB21: 7 | CC21: 10 | CD21: 35 | CE21: 45 | CF21: 80 | CH21: 10 | CI21: 10 | CJ21: 10 | CK21: 10 | CL21: 40 | CM21: 57 | CN21: 97 | CP21: 9 | CQ21: 7 | CR21: 10 | CS21: 7 | CT21: 33 | CU21: 40 | CV21: 73 | CX21: 8 | CY21: 5 | CZ21: 10 | DA21: 10 | DB21: 33 | DC21: 31 | DD21: 64 | DF21: 10 | DG21: 10 | DH21: 5 | DI21: 10 | DJ21: 35 | DK21: 51 | DL21: 86 | DN21: 3 | DO21: 10 | DP21: 6 | DQ21: 9 | DR21: 28 | DS21: 43 | DT21: 71 | DV21: 9 | DW21: 8 | DX21: 10 | DY21: 10 | DZ21: 37 | EA21: 44 | EB21: 81 | ED21: 10 | EE21: 10 | EF21: 7 | EG21: 10 | EH21: 37 | EI21: 53 | EJ21: 90 | EL21: 6 | EM21: 6 | EN21: 10 | EO21: 10 | EP21: 32 | EQ21: 45 | ER21: 77
A22: 20 | B22: JAMIMA JOHN JOSEPH | C22: 8 | D22: 5 | E22: 9 | F22: 10 | G22: =SUM(C22:F22) -> 32 | H22: 47 | I22: =G22+H22 -> 79 | K22: 3 | L22: 3 | M22: 10 | N22: 10 | O22: =SUM(K22:N22) -> 26 | P22: 21 | Q22: =O22+P22 -> 47 | S22: 10 | T22: 7 | U22: 5 | V22: 5 | W22: =SUM(S22:V22) -> 27 | X22: 36 | Y22: =W22+X22 -> 63 | Z22: =IF(Y22<10,"",RANK(Y22,Y$3:Y$52)) -> 13 | AA22: =IF(Y22>=70,"A",IF(Y22>=50,"C",IF(Y22>=45,"P",IF(Y22>=6,"F",IF(Y22<5,""))))) -> C | AB22: =IF(Y22>=70,"Excellent",IF(Y22>=50,"Credit",IF(Y22>=45,"Pass",IF(Y22>=6,"Fail",IF(Y22<5,""))))) -> Credit | AD22: 5 | AE22: 8 | AF22: 2 | AG22: 10 | AH22: =SUM(AD22:AG22) -> 25 | AI22: 54 | AJ22: =AH22+AI22 -> 79 | AL22: 6 | AM22: 5 | AN22: 10 | AO22: 10 | AP22: =SUM(AL22:AO22) -> 31 | AQ22: 28 | AR22: =AP22+AQ22 -> 59 | AT22: 6 | AU22: 4 | AV22: 5 | AW22: 9 | AX22: 24 | AY22: 26 | AZ22: 50 | BB22: 9 | BC22: 7 | BD22: 4 | BE22: 9 | BF22: 29 | BG22: 49 | BH22: 78 | BJ22: 7 | BK22: 9 | BL22: 10 | BM22: 8 | BN22: 34 | BO22: 39 | BP22: 73 | BR22: 6 | BS22: 9 | BT22: 10 | BU22: 10 | BV22: 35 | BW22: 38 | BX22: 73 | BZ22: 5 | CA22: 8 | CB22: 9 | CC22: 10 | CD22: 32 | CE22: 41 | CF22: 73 | CH22: 7 | CI22: 7 | CJ22: 10 | CK22: 10 | CL22: 34 | CM22: 46 | CN22: 80 | CP22: 7 | CQ22: 2 | CR22: 7 | CS22: 8 | CT22: 24 | CU22: 25 | CV22: 49 | CX22: 4 | CY22: 8 | CZ22: 10 | DA22: 10 | DB22: 32 | DC22: 19 | DD22: 51 | DF22: 7 | DG22: 7 | DH22: 5 | DI22: 10 | DJ22: 29 | DK22: 51 | DL22: 80 | DN22: 3 | DO22: 10 | DP22: 2 | DQ22: 7 | DR22: 22 | DS22: 34 | DT22: 56 | DV22: 2 | DW22: 5 | DX22: 8 | DY22: 10 | DZ22: 25 | EA22: 37 | EB22: 62 | ED22: 9 | EE22: 4 | EF22: 10 | EG22: 10 | EH22: 33 | EI22: 41 | EJ22: 74 | EP22: 0 | ER22: 0
A23: 21 | B23: JAFIDA MICHAEL PAPKA | C23: 4 | D23: 6 | E23: 10 | F23: 10 | G23: =SUM(C23:F23) -> 30 | H23: 40 | I23: =G23+H23 -> 70 | K23: 1 | L23: 3 | M23: 10 | N23: 10 | O23: =SUM(K23:N23) -> 24 | P23: 26 | Q23: =O23+P23 -> 50 | S23: 9 | T23: 5 | U23: 5 | V23: 5 | W23: =SUM(S23:V23) -> 24 | X23: 39 | Y23: =W23+X23 -> 63 | Z23: =IF(Y23<10,"",RANK(Y23,Y$3:Y$52)) -> 13 | AA23: =IF(Y23>=70,"A",IF(Y23>=50,"C",IF(Y23>=45,"P",IF(Y23>=6,"F",IF(Y23<5,""))))) -> C | AB23: =IF(Y23>=70,"Excellent",IF(Y23>=50,"Credit",IF(Y23>=45,"Pass",IF(Y23>=6,"Fail",IF(Y23<5,""))))) -> Credit | AD23: 10 | AE23: 7 | AF23: 2 | AG23: 10 | AH23: =SUM(AD23:AG23) -> 29 | AI23: 48 | AJ23: =AH23+AI23 -> 77 | AL23: 5 | AM23: 10 | AN23: 10 | AO23: 10 | AP23: =SUM(AL23:AO23) -> 35 | AQ23: 21 | AR23: =AP23+AQ23 -> 56 | AT23: 1 | AU23: 6 | AV23: 10 | AW23: 7 | AX23: 24 | AY23: 26 | AZ23: 50 | BB23: 4 | BC23: 2 | BD23: 4 | BE23: 9 | BF23: 19 | BG23: 49 | BH23: 68 | BJ23: 6 | BK23: 6 | BL23: 8 | BM23: 9 | BN23: 29 | BO23: 33 | BP23: 62 | BR23: 8 | BS23: 9 | BT23: 10 | BU23: 10 | BV23: 37 | BW23: 28 | BX23: 65 | BZ23: 7 | CA23: 8 | CB23: 10 | CC23: 6 | CD23: 31 | CE23: 30 | CF23: 61 | CH23: 7 | CI23: 10 | CJ23: 10 | CK23: 10 | CL23: 37 | CM23: 43 | CN23: 80 | CP23: 6 | CQ23: 6 | CR23: 7 | CS23: 7 | CT23: 26 | CU23: 30 | CV23: 56 | CX23: 7 | CY23: 7 | CZ23: 8 | DA23: 10 | DB23: 32 | DC23: 22 | DD23: 54 | DF23: 4 | DG23: 2 | DH23: 5 | DI23: 5 | DJ23: 16 | DK23: 35 | DL23: 51 | DN23: 1 | DO23: 3 | DP23: 4 | DQ23: 6 | DR23: 14 | DS23: 30 | DT23: 44 | DV23: 1 | DW23: 6 | DX23: 7 | DY23: 10 | DZ23: 24 | EA23: 32 | EB23: 56 | ED23: 6 | EE23: 7 | EF23: 10 | EG23: 10 | EH23: 33 | EI23: 36 | EJ23: 69 | EP23: 0 | ER23: 0
A24: 22 | B24: LUJAIN ADAMU ISAH | C24: 8 | D24: 6 | E24: 10 | F24: 10 | G24: =SUM(C24:F24) -> 34 | H24: 33 | I24: =G24+H24 -> 67 | K24: 10 | L24: 5 | M24: 10 | N24: 10 | O24: =SUM(K24:N24) -> 35 | P24: 37 | Q24: =O24+P24 -> 72 | S24: 9 | T24: 7 | U24: 5 | V24: 8 | W24: =SUM(S24:V24) -> 29 | X24: 46 | Y24: =W24+X24 -> 75 | Z24: =IF(Y24<10,"",RANK(Y24,Y$3:Y$52)) -> 4 | AA24: =IF(Y24>=70,"A",IF(Y24>=50,"C",IF(Y24>=45,"P",IF(Y24>=6,"F",IF(Y24<5,""))))) -> A | AB24: =IF(Y24>=70,"Excellent",IF(Y24>=50,"Credit",IF(Y24>=45,"Pass",IF(Y24>=6,"Fail",IF(Y24<5,""))))) -> Excellent | AH24: =SUM(AD24:AG24) -> 0 | AJ24: =AH24+AI24 -> 0 | AL24: 8 | AM24: 9 | AN24: 10 | AO24: 8 | AP24: =SUM(AL24:AO24) -> 35 | AQ24: 39 | AR24: =AP24+AQ24 -> 74 | AT24: 7 | AU24: 2 | AV24: 10 | AW24: 9 | AX24: 28 | AY24: 28 | AZ24: 56 | BB24: 10 | BC24: 6 | BD24: 9 | BE24: 9 | BF24: 34 | BG24: 47 | BH24: 81 | BJ24: 7 | BK24: 7 | BL24: 10 | BM24: 10 | BN24: 34 | BO24: 43 | BP24: 77 | BR24: 9 | BS24: 10 | BT24: 10 | BU24: 10 | BV24: 39 | BW24: 51 | BX24: 90 | BZ24: 10 | CA24: 7 | CB24: 10 | CC24: 10 | CD24: 37 | CE24: 32 | CF24: 69 | CH24: 10 | CI24: 7 | CJ24: 10 | CK24: 10 | CL24: 37 | CM24: 41 | CN24: 78 | CP24: 9 | CQ24: 6 | CR24: 10 | CS24: 8 | CT24: 33 | CU24: 40 | CV24: 73 | CX24: 6 | CY24: 6 | CZ24: 10 | DA24: 10 | DB24: 32 | DC24: 32 | DD24: 64 | DF24: 10 | DG24: 8 | DH24: 5 | DI24: 10 | DJ24: 33 | DK24: 51 | DL24: 84 | DN24: 4 | DO24: 4 | DP24: 4 | DQ24: 8 | DR24: 20 | DS24: 27 | DT24: 47 | DV24: 8 | DW24: 10 | DX24: 8 | DY24: 10 | DZ24: 36 | EA24: 36 | EB24: 72 | ED24: 10 | EE24: 7 | EF24: 10 | EG24: 10 | EH24: 37 | EI24: 42 | EJ24: 79 | EL24: 10 | EM24: 4 | EN24: 10 | EO24: 10 | EP24: 34 | EQ24: 46 | ER24: 80
A25: 23 | B25: KABIR LUKMAN ZULAIKA | C25: 8 | D25: 7 | E25: 10 | F25: 10 | G25: =SUM(C25:F25) -> 35 | H25: 24 | I25: =G25+H25 -> 59 | K25: 7 | L25: 5 | M25: 10 | N25: 10 | O25: =SUM(K25:N25) -> 32 | P25: 25 | Q25: =O25+P25 -> 57 | S25: 10 | T25: 6 | U25: 5 | V25: 9 | W25: =SUM(S25:V25) -> 30 | X25: 39 | Y25: =W25+X25 -> 69 | Z25: =IF(Y25<10,"",RANK(Y25,Y$3:Y$52)) -> 11 | AA25: =IF(Y25>=70,"A",IF(Y25>=50,"C",IF(Y25>=45,"P",IF(Y25>=6,"F",IF(Y25<5,""))))) -> C | AB25: =IF(Y25>=70,"Excellent",IF(Y25>=50,"Credit",IF(Y25>=45,"Pass",IF(Y25>=6,"Fail",IF(Y25<5,""))))) -> Credit | AH25: =SUM(AD25:AG25) -> 0 | AJ25: =AH25+AI25 -> 0 | AL25: 8 | AM25: 7 | AN25: 10 | AO25: 8 | AP25: =SUM(AL25:AO25) -> 33 | AQ25: 27 | AR25: =AP25+AQ25 -> 60 | AT25: 2 | AU25: 2 | AV25: 10 | AW25: 10 | AX25: 24 | AY25: 25 | AZ25: 49 | BB25: 8 | BC25: 8 | BD25: 9 | BE25: 5 | BF25: 30 | BG25: 44 | BH25: 74 | BJ25: 9 | BK25: 5 | BL25: 10 | BM25: 9 | BN25: 33 | BO25: 33 | BP25: 66 | BR25: 10 | BS25: 8 | BT25: 9 | BU25: 10 | BV25: 37 | BW25: 27 | BX25: 64 | BZ25: 8 | CA25: 6 | CB25: 7 | CC25: 10 | CD25: 31 | CE25: 40 | CF25: 71 | CH25: 7 | CI25: 5 | CJ25: 10 | CK25: 10 | CL25: 32 | CM25: 34 | CN25: 66 | CP25: 9 | CQ25: 6 | CR25: 10 | CS25: 8 | CT25: 33 | CU25: 40 | CV25: 73 | CX25: 4 | CY25: 4 | CZ25: 9 | DA25: 10 | DB25: 27 | DC25: 25 | DD25: 52 | DF25: 10 | DG25: 4 | DH25: 10 | DI25: 10 | DJ25: 34 | DK25: 45 | DL25: 79 | DN25: 6 | DO25: 9 | DP25: 6 | DQ25: 9 | DR25: 30 | DS25: 24 | DT25: 54 | DV25: 10 | DW25: 8 | DX25: 8 | DY25: 10 | DZ25: 36 | EA25: 28 | EB25: 64 | ED25: 7 | EE25: 9 | EF25: 7 | EG25: 10 | EH25: 33 | EI25: 34 | EJ25: 67 | EL25: 8 | EM25: 10 | EN25: 10 | EO25: 10 | EP25: 38 | EQ25: 30 | ER25: 68
A26: 24 | B26: KALTUM ABBA AJIKOLO | C26: 7 | D26: 8 | E26: 8 | F26: 8 | G26: =SUM(C26:F26) -> 31 | H26: 32 | I26: =G26+H26 -> 63 | K26: 7 | L26: 5 | M26: 10 | N26: 10 | O26: =SUM(K26:N26) -> 32 | P26: 28 | Q26: =O26+P26 -> 60 | S26: 10 | T26: 5 | U26: 5 | V26: 9 | W26: =SUM(S26:V26) -> 29 | X26: 34 | Y26: =W26+X26 -> 63 | Z26: =IF(Y26<10,"",RANK(Y26,Y$3:Y$52)) -> 13 | AA26: =IF(Y26>=70,"A",IF(Y26>=50,"C",IF(Y26>=45,"P",IF(Y26>=6,"F",IF(Y26<5,""))))) -> C | AB26: =IF(Y26>=70,"Excellent",IF(Y26>=50,"Credit",IF(Y26>=45,"Pass",IF(Y26>=6,"Fail",IF(Y26<5,""))))) -> Credit | AH26: =SUM(AD26:AG26) -> 0 | AJ26: =AH26+AI26 -> 0 | AL26: 4 | AM26: 8 | AN26: 10 | AO26: 9 | AP26: =SUM(AL26:AO26) -> 31 | AQ26: 23 | AR26: =AP26+AQ26 -> 54 | AT26: 1 | AU26: 5 | AV26: 5 | AW26: 4 | AX26: 15 | AY26: 21 | AZ26: 36 | BB26: 6 | BC26: 9 | BD26: 3 | BE26: 9 | BF26: 27 | BG26: 44 | BH26: 71 | BJ26: 7 | BK26: 8 | BL26: 10 | BM26: 9 | BN26: 34 | BO26: 47 | BP26: 81 | BR26: 8 | BS26: 9 | BT26: 8 | BU26: 10 | BV26: 35 | BW26: 31 | BX26: 66 | BZ26: 8 | CA26: 7 | CB26: 6 | CC26: 10 | CD26: 31 | CE26: 40 | CF26: 71 | CH26: 5 | CI26: 10 | CJ26: 10 | CK26: 10 | CL26: 35 | CM26: 45 | CN26: 80 | CP26: 3 | CQ26: 5 | CR26: 10 | CS26: 8 | CT26: 26 | CU26: 35 | CV26: 61 | CX26: 4 | CY26: 3 | CZ26: 10 | DA26: 10 | DB26: 27 | DC26: 20 | DD26: 47 | DF26: 9 | DG26: 7 | DH26: 3 | DI26: 9 | DJ26: 28 | DK26: 40 | DL26: 68 | DN26: 6 | DO26: 5 | DP26: 6 | DQ26: 7 | DR26: 24 | DS26: 28 | DT26: 52 | DV26: 6 | DW26: 10 | DX26: 8 | DY26: 10 | DZ26: 34 | EA26: 26 | EB26: 60 | ED26: 10 | EE26: 8 | EF26: 8 | EG26: 10 | EH26: 36 | EI26: 30 | EJ26: 66 | EL26: 9 | EM26: 2 | EN26: 10 | EO26: 10 | EP26: 31 | EQ26: 43 | ER26: 74
A27: 25 | B27: MARYAM IBRAHIM ADAMU | C27: 7 | D27: 3 | E27: 9 | F27: 9 | G27: =SUM(C27:F27) -> 28 | H27: 14 | I27: =G27+H27 -> 42 | K27: 3 | L27: 1 | M27: 10 | N27: 10 | O27: =SUM(K27:N27) -> 24 | P27: 19 | Q27: =O27+P27 -> 43 | S27: 2 | T27: 2 | U27: 5 | V27: 5 | W27: =SUM(S27:V27) -> 14 | X27: 25 | Y27: =W27+X27 -> 39 | Z27: =IF(Y27<10,"",RANK(Y27,Y$3:Y$52)) -> 35 | AA27: =IF(Y27>=70,"A",IF(Y27>=50,"C",IF(Y27>=45,"P",IF(Y27>=6,"F",IF(Y27<5,""))))) -> F | AB27: =IF(Y27>=70,"Excellent",IF(Y27>=50,"Credit",IF(Y27>=45,"Pass",IF(Y27>=6,"Fail",IF(Y27<5,""))))) -> Fail | AH27: =SUM(AD27:AG27) -> 0 | AJ27: =AH27+AI27 -> 0 | AL27: 1 | AM27: 1 | AN27: 7 | AO27: 8 | AP27: =SUM(AL27:AO27) -> 17 | AQ27: 16 | AR27: =AP27+AQ27 -> 33 | AT27: 1 | AU27: 4 | AV27: 10 | AW27: 4 | AX27: 19 | AY27: 13 | AZ27: 32 | BB27: 2 | BC27: 1 | BD27: 2 | BE27: 2 | BF27: 7 | BG27: 17 | BH27: 24 | BJ27: 2 | BK27: 5 | BL27: 8 | BM27: 10 | BN27: 25 | BO27: 8 | BP27: 33 | BR27: 2 | BS27: 2 | BT27: 7 | BU27: 8 | BV27: 19 | BW27: 10 | BX27: 29 | BZ27: 2 | CA27: 1 | CB27: 10 | CC27: 5 | CD27: 18 | CE27: 12 | CF27: 30 | CH27: 1 | CI27: 4 | CJ27: 10 | CK27: 10 | CL27: 25 | CM27: 12 | CN27: 37 | CP27: 2 | CQ27: 1 | CR27: 5 | CS27: 8 | CT27: 16 | CU27: 20 | CV27: 36 | CX27: 2 | CY27: 2 | CZ27: 9 | DA27: 9 | DB27: 22 | DC27: 18 | DD27: 40 | DF27: 1 | DG27: 1 | DH27: 1 | DI27: 5 | DJ27: 8 | DK27: 11 | DL27: 19 | DN27: 1 | DO27: 1 | DP27: 4 | DQ27: 5 | DR27: 11 | DS27: 14 | DT27: 25 | DV27: 1 | DW27: 2 | DX27: 8 | DY27: 10 | DZ27: 21 | EA27: 8 | EB27: 29 | ED27: 2 | EE27: 3 | EF27: 10 | EG27: 7 | EH27: 22 | EI27: 18 | EJ27: 40 | EL27: 1 | EM27: 2 | EN27: 5 | EO27: 5 | EP27: 13 | EQ27: 12 | ER27: 25
A28: 26 | B28: MARYAM LAWAN YAUMI | C28: 3 | D28: 5 | E28: 10 | F28: 10 | G28: =SUM(C28:F28) -> 28 | H28: 31 | I28: =G28+H28 -> 59 | K28: 2 | L28: 3 | M28: 10 | N28: 10 | O28: =SUM(K28:N28) -> 25 | P28: 20 | Q28: =O28+P28 -> 45 | S28: 6 | T28: 6 | U28: 5 | V28: 5 | W28: =SUM(S28:V28) -> 22 | X28: 36 | Y28: =W28+X28 -> 58 | Z28: =IF(Y28<10,"",RANK(Y28,Y$3:Y$52)) -> 19 | AA28: =IF(Y28>=70,"A",IF(Y28>=50,"C",IF(Y28>=45,"P",IF(Y28>=6,"F",IF(Y28<5,""))))) -> C | AB28: =IF(Y28>=70,"Excellent",IF(Y28>=50,"Credit",IF(Y28>=45,"Pass",IF(Y28>=6,"Fail",IF(Y28<5,""))))) -> Credit | AH28: =SUM(AD28:AG28) -> 0 | AJ28: =AH28+AI28 -> 0 | AL28: 3 | AM28: 4 | AN28: 7 | AO28: 7 | AP28: =SUM(AL28:AO28) -> 21 | AQ28: 17 | AR28: =AP28+AQ28 -> 38 | AT28: 3 | AU28: 1 | AV28: 5 | AW28: 4 | AX28: 13 | AY28: 21 | AZ28: 34 | BB28: 8 | BC28: 6 | BD28: 8 | BE28: 8 | BF28: 30 | BG28: 39 | BH28: 69 | BJ28: 6 | BK28: 9 | BL28: 8 | BM28: 9 | BN28: 32 | BO28: 26 | BP28: 58 | BR28: 7 | BS28: 8 | BT28: 7 | BU28: 10 | BV28: 32 | BW28: 19 | BX28: 51 | BZ28: 4 | CA28: 6 | CB28: 9 | CC28: 10 | CD28: 29 | CE28: 34 | CF28: 63 | CH28: 6 | CI28: 7 | CJ28: 10 | CK28: 10 | CL28: 33 | CM28: 42 | CN28: 75 | CP28: 7 | CQ28: 2 | CR28: 10 | CS28: 8 | CT28: 27 | CU28: 25 | CV28: 52 | CX28: 6 | CY28: 6 | CZ28: 8 | DA28: 9 | DB28: 29 | DC28: 20 | DD28: 49 | DF28: 5 | DG28: 7 | DH28: 4 | DI28: 9 | DJ28: 25 | DK28: 43 | DL28: 68 | DN28: 3 | DO28: 4 | DP28: 4 | DQ28: 9 | DR28: 20 | DS28: 22 | DT28: 42 | DV28: 4 | DW28: 6 | DX28: 8 | DY28: 10 | DZ28: 28 | EA28: 19 | EB28: 47 | ED28: 7 | EE28: 5 | EF28: 10 | EG28: 7 | EH28: 29 | EI28: 34 | EJ28: 63 | EL28: 7 | EM28: 4 | EN28: 5 | EO28: 5 | EP28: 21 | EQ28: 32 | ER28: 53
A29: 27 | B29: REJOICE YUSUF MAMZA | C29: 7 | D29: 6 | E29: 10 | F29: 10 | G29: =SUM(C29:F29) -> 33 | H29: 41 | I29: =G29+H29 -> 74 | K29: 9 | L29: 7 | M29: 10 | N29: 10 | O29: =SUM(K29:N29) -> 36 | P29: 28 | Q29: =O29+P29 -> 64 | S29: 10 | T29: 7 | U29: 5 | V29: 10 | W29: =SUM(S29:V29) -> 32 | X29: 52 | Y29: =W29+X29 -> 84 | Z29: =IF(Y29<10,"",RANK(Y29,Y$3:Y$52)) -> 1 | AA29: =IF(Y29>=70,"A",IF(Y29>=50,"C",IF(Y29>=45,"P",IF(Y29>=6,"F",IF(Y29<5,""))))) -> A | AB29: =IF(Y29>=70,"Excellent",IF(Y29>=50,"Credit",IF(Y29>=45,"Pass",IF(Y29>=6,"Fail",IF(Y29<5,""))))) -> Excellent | AD29: 10 | AE29: 10 | AF29: 10 | AG29: 10 | AH29: =SUM(AD29:AG29) -> 40 | AI29: 57 | AJ29: =AH29+AI29 -> 97 | AL29: 8 | AM29: 10 | AN29: 8 | AO29: 9 | AP29: =SUM(AL29:AO29) -> 35 | AQ29: 44 | AR29: =AP29+AQ29 -> 79 | AT29: 8 | AU29: 4 | AV29: 10 | AW29: 10 | AX29: 32 | AY29: 42 | AZ29: 74 | BB29: 10 | BC29: 7 | BD29: 9 | BE29: 10 | BF29: 36 | BG29: 53 | BH29: 89 | BJ29: 10 | BK29: 10 | BL29: 8 | BM29: 10 | BN29: 38 | BO29: 47 | BP29: 85 | BR29: 10 | BS29: 8 | BT29: 10 | BU29: 10 | BV29: 38 | BW29: 42 | BX29: 80 | BZ29: 8 | CA29: 8 | CB29: 10 | CC29: 10 | CD29: 36 | CE29: 47 | CF29: 83 | CH29: 10 | CI29: 10 | CJ29: 10 | CK29: 10 | CL29: 40 | CM29: 55 | CN29: 95 | CP29: 8 | CQ29: 7 | CR29: 10 | CS29: 8 | CT29: 33 | CU29: 40 | CV29: 73 | CX29: 6 | CY29: 4 | CZ29: 10 | DA29: 10 | DB29: 30 | DC29: 25 | DD29: 55 | DF29: 9 | DG29: 3 | DH29: 3 | DI29: 10 | DJ29: 25 | DK29: 47 | DL29: 72 | DN29: 7 | DO29: 9 | DP29: 6 | DQ29: 10 | DR29: 32 | DS29: 41 | DT29: 73 | DV29: 10 | DW29: 7 | DX29: 9 | DY29: 10 | DZ29: 36 | EA29: 50 | EB29: 86 | ED29: 10 | EE29: 8 | EF29: 8 | EG29: 10 | EH29: 36 | EI29: 40 | EJ29: 76 | EP29: 0 | ER29: 0
A30: 28 | B30: TIJJANI MUHAMMED FATIMA | C30: 10 | D30: 7 | E30: 10 | F30: 10 | G30: =SUM(C30:F30) -> 37 | H30: 44 | I30: =G30+H30 -> 81 | K30: 9 | L30: 7 | N30: 10 | O30: =SUM(K30:N30) -> 26 | P30: 36 | Q30: =O30+P30 -> 62 | S30: 10 | T30: 7 | U30: 5 | V30: 10 | W30: =SUM(S30:V30) -> 32 | X30: 40 | Y30: =W30+X30 -> 72 | Z30: =IF(Y30<10,"",RANK(Y30,Y$3:Y$52)) -> 6 | AA30: =IF(Y30>=70,"A",IF(Y30>=50,"C",IF(Y30>=45,"P",IF(Y30>=6,"F",IF(Y30<5,""))))) -> A | AB30: =IF(Y30>=70,"Excellent",IF(Y30>=50,"Credit",IF(Y30>=45,"Pass",IF(Y30>=6,"Fail",IF(Y30<5,""))))) -> Excellent | AH30: =SUM(AD30:AG30) -> 0 | AJ30: =AH30+AI30 -> 0 | AL30: 10 | AM30: 10 | AN30: 10 | AO30: 10 | AP30: =SUM(AL30:AO30) -> 40 | AQ30: 26 | AR30: =AP30+AQ30 -> 66 | AT30: 2 | AU30: 6 | AV30: 10 | AW30: 10 | AX30: 28 | AY30: 34 | AZ30: 62 | BB30: 8 | BC30: 7 | BD30: 9 | BE30: 10 | BF30: 34 | BG30: 48 | BH30: 82 | BJ30: 10 | BK30: 10 | BL30: 9 | BM30: 10 | BN30: 39 | BO30: 42 | BP30: 81 | BR30: 9 | BS30: 10 | BT30: 10 | BU30: 10 | BV30: 39 | BW30: 31 | BX30: 70 | BZ30: 9 | CA30: 6 | CB30: 10 | CC30: 10 | CD30: 35 | CE30: 42 | CF30: 77 | CH30: 8 | CI30: 7 | CJ30: 10 | CK30: 10 | CL30: 35 | CM30: 52 | CN30: 87 | CP30: 9 | CQ30: 6 | CR30: 10 | CS30: 8 | CT30: 33 | CU30: 45 | CV30: 78 | CX30: 6 | CY30: 7 | CZ30: 10 | DA30: 10 | DB30: 33 | DC30: 21 | DD30: 54 | DF30: 8 | DG30: 10 | DH30: 10 | DI30: 10 | DJ30: 38 | DK30: 50 | DL30: 88 | DN30: 6 | DO30: 8 | DP30: 7 | DQ30: 10 | DR30: 31 | DS30: 34 | DT30: 65 | DV30: 5 | DW30: 8 | DX30: 8 | DY30: 10 | DZ30: 31 | EA30: 45 | EB30: 76 | ED30: 10 | EE30: 10 | EF30: 10 | EG30: 10 | EH30: 40 | EI30: 36 | EJ30: 76 | EM30: 10 | EN30: 10 | EO30: 10 | EP30: 30 | EQ30: 39 | ER30: 69
A31: 29 | B31: SHETTIMA KALLI MARYAM | C31: 7 | D31: 7 | E31: 9 | F31: 10 | G31: =SUM(C31:F31) -> 33 | H31: 41 | I31: =G31+H31 -> 74 | K31: 4 | L31: 2 | M31: 10 | N31: 10 | O31: =SUM(K31:N31) -> 26 | P31: 24 | Q31: =O31+P31 -> 50 | S31: 9 | T31: 7 | U31: 5 | V31: 6 | W31: =SUM(S31:V31) -> 27 | X31: 32 | Y31: =W31+X31 -> 59 | Z31: =IF(Y31<10,"",RANK(Y31,Y$3:Y$52)) -> 18 | AA31: =IF(Y31>=70,"A",IF(Y31>=50,"C",IF(Y31>=45,"P",IF(Y31>=6,"F",IF(Y31<5,""))))) -> C | AB31: =IF(Y31>=70,"Excellent",IF(Y31>=50,"Credit",IF(Y31>=45,"Pass",IF(Y31>=6,"Fail",IF(Y31<5,""))))) -> Credit | AH31: =SUM(AD31:AG31) -> 0 | AJ31: =AH31+AI31 -> 0 | AL31: 4 | AM31: 10 | AN31: 8 | AO31: 8 | AP31: =SUM(AL31:AO31) -> 30 | AQ31: 25 | AR31: =AP31+AQ31 -> 55 | AT31: 2 | AU31: 5 | AV31: 10 | AW31: 4 | AX31: 21 | AY31: 25 | AZ31: 46 | BB31: 10 | BC31: 7 | BD31: 9 | BE31: 5 | BF31: 31 | BG31: 40 | BH31: 71 | BJ31: 7 | BK31: 8 | BL31: 10 | BM31: 10 | BN31: 35 | BO31: 35 | BP31: 70 | BR31: 4 | BS31: 9 | BT31: 10 | BU31: 10 | BV31: 33 | BW31: 30 | BX31: 63 | BZ31: 4 | CA31: 9 | CB31: 6 | CC31: 6 | CD31: 25 | CE31: 24 | CF31: 49 | CH31: 8 | CI31: 10 | CJ31: 10 | CK31: 10 | CL31: 38 | CM31: 26 | CN31: 64 | CP31: 7 | CQ31: 6 | CR31: 7 | CS31: 7 | CT31: 27 | CU31: 30 | CV31: 57 | CX31: 4 | CY31: 4 | CZ31: 9 | DA31: 9 | DB31: 26 | DC31: 26 | DD31: 52 | DF31: 10 | DG31: 7 | DH31: 10 | DI31: 10 | DJ31: 37 | DK31: 43 | DL31: 80 | DN31: 3 | DO31: 5 | DP31: 8 | DQ31: 10 | DR31: 26 | DS31: 33 | DT31: 59 | DV31: 5 | DW31: 10 | DX31: 9 | DY31: 10 | DZ31: 34 | EA31: 27 | EB31: 61 | ED31: 8 | EE31: 6 | EF31: 8 | EG31: 10 | EH31: 32 | EI31: 37 | EJ31: 69 | EL31: 8 | EM31: 8 | EN31: 10 | EO31: 10 | EP31: 36 | EQ31: 39 | ER31: 75
A32: 30 | B32: UMMI QUTHUM ALKON | C32: 4 | D32: 7 | E32: 9 | F32: 10 | G32: =SUM(C32:F32) -> 30 | H32: 27 | I32: =G32+H32 -> 57 | K32: 5 | L32: 3 | M32: 10 | N32: 10 | O32: =SUM(K32:N32) -> 28 | P32: 15 | Q32: =O32+P32 -> 43 | S32: 8 | T32: 6 | U32: 5 | V32: 8 | W32: =SUM(S32:V32) -> 27 | X32: 31 | Y32: =W32+X32 -> 58 | Z32: =IF(Y32<10,"",RANK(Y32,Y$3:Y$52)) -> 19 | AA32: =IF(Y32>=70,"A",IF(Y32>=50,"C",IF(Y32>=45,"P",IF(Y32>=6,"F",IF(Y32<5,""))))) -> C | AB32: =IF(Y32>=70,"Excellent",IF(Y32>=50,"Credit",IF(Y32>=45,"Pass",IF(Y32>=6,"Fail",IF(Y32<5,""))))) -> Credit | AH32: =SUM(AD32:AG32) -> 0 | AJ32: =AH32+AI32 -> 0 | AL32: 1 | AM32: 9 | AN32: 10 | AO32: 10 | AP32: =SUM(AL32:AO32) -> 30 | AQ32: 11 | AR32: =AP32+AQ32 -> 41 | AT32: 1 | AU32: 5 | AV32: 5 | AW32: 10 | AX32: 21 | AY32: 13 | AZ32: 34 | BB32: 2 | BC32: 8 | BD32: 4 | BE32: 10 | BF32: 24 | BG32: 24 | BH32: 48 | BJ32: 7 | BK32: 4 | BL32: 10 | BM32: 8 | BN32: 29 | BO32: 21 | BP32: 50 | BR32: 7 | BS32: 9 | BT32: 10 | BU32: 10 | BV32: 36 | BW32: 31 | BX32: 67 | BZ32: 6 | CA32: 5 | CB32: 8 | CC32: 10 | CD32: 29 | CE32: 28 | CF32: 57 | CH32: 7 | CI32: 5 | CJ32: 10 | CK32: 10 | CL32: 32 | CM32: 28 | CN32: 60 | CP32: 7 | CQ32: 5 | CR32: 10 | CS32: 8 | CT32: 30 | CU32: 35 | CV32: 65 | CX32: 6 | CY32: 6 | CZ32: 9 | DA32: 9 | DB32: 30 | DC32: 16 | DD32: 46 | DF32: 6 | DG32: 2 | DH32: 10 | DI32: 10 | DJ32: 28 | DK32: 32 | DL32: 60 | DN32: 5 | DO32: 8 | DP32: 5 | DQ32: 9 | DR32: 27 | DS32: 18 | DT32: 45 | DV32: 4 | DW32: 4 | DX32: 10 | DY32: 10 | DZ32: 28 | EA32: 15 | EB32: 43 | ED32: 7 | EE32: 4 | EF32: 8 | EG32: 10 | EH32: 29 | EI32: 35 | EJ32: 64 | EL32: 5 | EM32: 8 | EN32: 10 | EO32: 10 | EP32: 33 | EQ32: 37 | ER32: 70
